[2023-01-25T18:52:11.421+0000] {taskinstance.py:1083} INFO - Dependencies all met for <TaskInstance: twitter_dag.complete_twitter_etl scheduled__2021-01-28T00:00:00+00:00 [queued]>
[2023-01-25T18:52:11.533+0000] {taskinstance.py:1083} INFO - Dependencies all met for <TaskInstance: twitter_dag.complete_twitter_etl scheduled__2021-01-28T00:00:00+00:00 [queued]>
[2023-01-25T18:52:11.547+0000] {taskinstance.py:1279} INFO - 
--------------------------------------------------------------------------------
[2023-01-25T18:52:11.580+0000] {taskinstance.py:1280} INFO - Starting attempt 1 of 2
[2023-01-25T18:52:11.582+0000] {taskinstance.py:1281} INFO - 
--------------------------------------------------------------------------------
[2023-01-25T18:52:11.696+0000] {taskinstance.py:1300} INFO - Executing <Task(PythonOperator): complete_twitter_etl> on 2021-01-28 00:00:00+00:00
[2023-01-25T18:52:11.731+0000] {standard_task_runner.py:55} INFO - Started process 1651 to run task
[2023-01-25T18:52:11.744+0000] {standard_task_runner.py:82} INFO - Running: ['***', 'tasks', 'run', 'twitter_dag', 'complete_twitter_etl', 'scheduled__2021-01-28T00:00:00+00:00', '--job-id', '156', '--raw', '--subdir', 'DAGS_FOLDER/twitter_dag.py', '--cfg-path', '/tmp/tmpqbsd56sk']
[2023-01-25T18:52:11.759+0000] {standard_task_runner.py:83} INFO - Job 156: Subtask complete_twitter_etl
[2023-01-25T18:52:11.971+0000] {task_command.py:388} INFO - Running <TaskInstance: twitter_dag.complete_twitter_etl scheduled__2021-01-28T00:00:00+00:00 [running]> on host 512d0ff0785b
[2023-01-25T18:52:13.495+0000] {taskinstance.py:1509} INFO - Exporting the following env vars:
AIRFLOW_CTX_DAG_EMAIL=***@example.com
AIRFLOW_CTX_DAG_OWNER=***
AIRFLOW_CTX_DAG_ID=twitter_dag
AIRFLOW_CTX_TASK_ID=complete_twitter_etl
AIRFLOW_CTX_EXECUTION_DATE=2021-01-28T00:00:00+00:00
AIRFLOW_CTX_TRY_NUMBER=1
AIRFLOW_CTX_DAG_RUN_ID=scheduled__2021-01-28T00:00:00+00:00
[2023-01-25T18:52:19.092+0000] {taskinstance.py:1768} ERROR - Task failed with exception
Traceback (most recent call last):
  File "/home/airflow/.local/lib/python3.7/site-packages/s3fs/core.py", line 112, in _error_wrapper
    return await func(*args, **kwargs)
  File "/home/airflow/.local/lib/python3.7/site-packages/aiobotocore/client.py", line 358, in _make_api_call
    raise error_class(parsed_response, operation_name)
botocore.exceptions.ClientError: An error occurred (AccessDenied) when calling the CreateBucket operation: Anonymous access is forbidden for this operation

The above exception was the direct cause of the following exception:

Traceback (most recent call last):
  File "/home/airflow/.local/lib/python3.7/site-packages/airflow/operators/python.py", line 175, in execute
    return_value = self.execute_callable()
  File "/home/airflow/.local/lib/python3.7/site-packages/airflow/operators/python.py", line 192, in execute_callable
    return self.python_callable(*self.op_args, **self.op_kwargs)
  File "/opt/airflow/dags/twitter_etl.py", line 46, in run_twitter_etl
    df.to_csv("s3://jinchoi-airflow-bucket/data/elonmusk_tweets.csv")
  File "/home/airflow/.local/lib/python3.7/site-packages/pandas/core/generic.py", line 3482, in to_csv
    storage_options=storage_options,
  File "/home/airflow/.local/lib/python3.7/site-packages/pandas/io/formats/format.py", line 1105, in to_csv
    csv_formatter.save()
  File "/home/airflow/.local/lib/python3.7/site-packages/pandas/io/formats/csvs.py", line 243, in save
    storage_options=self.storage_options,
  File "/home/airflow/.local/lib/python3.7/site-packages/pandas/io/common.py", line 614, in get_handle
    storage_options=storage_options,
  File "/home/airflow/.local/lib/python3.7/site-packages/pandas/io/common.py", line 370, in _get_filepath_or_buffer
    filepath_or_buffer, mode=fsspec_mode, **(storage_options or {})
  File "/home/airflow/.local/lib/python3.7/site-packages/fsspec/core.py", line 428, in open
    **kwargs,
  File "/home/airflow/.local/lib/python3.7/site-packages/fsspec/core.py", line 283, in open_files
    [fs.makedirs(parent, exist_ok=True) for parent in parents]
  File "/home/airflow/.local/lib/python3.7/site-packages/fsspec/core.py", line 283, in <listcomp>
    [fs.makedirs(parent, exist_ok=True) for parent in parents]
  File "/home/airflow/.local/lib/python3.7/site-packages/fsspec/asyn.py", line 114, in wrapper
    return sync(self.loop, func, *args, **kwargs)
  File "/home/airflow/.local/lib/python3.7/site-packages/fsspec/asyn.py", line 99, in sync
    raise return_result
  File "/home/airflow/.local/lib/python3.7/site-packages/fsspec/asyn.py", line 54, in _runner
    result[0] = await coro
  File "/home/airflow/.local/lib/python3.7/site-packages/s3fs/core.py", line 883, in _makedirs
    await self._mkdir(path, create_parents=True)
  File "/home/airflow/.local/lib/python3.7/site-packages/s3fs/core.py", line 868, in _mkdir
    await self._call_s3("create_bucket", **params)
  File "/home/airflow/.local/lib/python3.7/site-packages/s3fs/core.py", line 340, in _call_s3
    method, kwargs=additional_kwargs, retries=self.retries
  File "/home/airflow/.local/lib/python3.7/site-packages/s3fs/core.py", line 139, in _error_wrapper
    raise err
PermissionError: Anonymous access is forbidden for this operation
[2023-01-25T18:52:19.133+0000] {taskinstance.py:1323} INFO - Marking task as UP_FOR_RETRY. dag_id=twitter_dag, task_id=complete_twitter_etl, execution_date=20210128T000000, start_date=20230125T185211, end_date=20230125T185219
[2023-01-25T18:52:19.166+0000] {standard_task_runner.py:105} ERROR - Failed to execute job 156 for task complete_twitter_etl (Anonymous access is forbidden for this operation; 1651)
[2023-01-25T18:52:19.233+0000] {local_task_job.py:208} INFO - Task exited with return code 1
[2023-01-25T18:52:19.272+0000] {taskinstance.py:2578} INFO - 0 downstream tasks scheduled from follow-on schedule check
[2023-01-26T06:26:43.762+0000] {taskinstance.py:1083} INFO - Dependencies all met for <TaskInstance: twitter_dag.complete_twitter_etl scheduled__2021-01-28T00:00:00+00:00 [queued]>
[2023-01-26T06:26:43.786+0000] {taskinstance.py:1083} INFO - Dependencies all met for <TaskInstance: twitter_dag.complete_twitter_etl scheduled__2021-01-28T00:00:00+00:00 [queued]>
[2023-01-26T06:26:43.787+0000] {taskinstance.py:1279} INFO - 
--------------------------------------------------------------------------------
[2023-01-26T06:26:43.788+0000] {taskinstance.py:1280} INFO - Starting attempt 1 of 2
[2023-01-26T06:26:43.790+0000] {taskinstance.py:1281} INFO - 
--------------------------------------------------------------------------------
[2023-01-26T06:26:43.839+0000] {taskinstance.py:1300} INFO - Executing <Task(PythonOperator): complete_twitter_etl> on 2021-01-28 00:00:00+00:00
[2023-01-26T06:26:43.849+0000] {standard_task_runner.py:55} INFO - Started process 2767 to run task
[2023-01-26T06:26:43.878+0000] {standard_task_runner.py:82} INFO - Running: ['***', 'tasks', 'run', 'twitter_dag', 'complete_twitter_etl', 'scheduled__2021-01-28T00:00:00+00:00', '--job-id', '157', '--raw', '--subdir', 'DAGS_FOLDER/twitter_dag.py', '--cfg-path', '/tmp/tmp8psyrxw6']
[2023-01-26T06:26:43.883+0000] {standard_task_runner.py:83} INFO - Job 157: Subtask complete_twitter_etl
[2023-01-26T06:26:44.901+0000] {task_command.py:388} INFO - Running <TaskInstance: twitter_dag.complete_twitter_etl scheduled__2021-01-28T00:00:00+00:00 [running]> on host 864c120ca3c2
[2023-01-26T06:26:45.274+0000] {taskinstance.py:1509} INFO - Exporting the following env vars:
AIRFLOW_CTX_DAG_EMAIL=***@example.com
AIRFLOW_CTX_DAG_OWNER=***
AIRFLOW_CTX_DAG_ID=twitter_dag
AIRFLOW_CTX_TASK_ID=complete_twitter_etl
AIRFLOW_CTX_EXECUTION_DATE=2021-01-28T00:00:00+00:00
AIRFLOW_CTX_TRY_NUMBER=1
AIRFLOW_CTX_DAG_RUN_ID=scheduled__2021-01-28T00:00:00+00:00
[2023-01-26T06:26:46.088+0000] {taskinstance.py:1768} ERROR - Task failed with exception
Traceback (most recent call last):
  File "/home/airflow/.local/lib/python3.7/site-packages/airflow/operators/python.py", line 175, in execute
    return_value = self.execute_callable()
  File "/home/airflow/.local/lib/python3.7/site-packages/airflow/operators/python.py", line 192, in execute_callable
    return self.python_callable(*self.op_args, **self.op_kwargs)
  File "/opt/airflow/dags/twitter_etl.py", line 51, in run_twitter_etl
    aws_access_key_id=os.environ['aws_access_key_id'],
  File "/usr/local/lib/python3.7/os.py", line 681, in __getitem__
    raise KeyError(key) from None
KeyError: 'aws_access_key_id'
[2023-01-26T06:26:46.130+0000] {taskinstance.py:1323} INFO - Marking task as UP_FOR_RETRY. dag_id=twitter_dag, task_id=complete_twitter_etl, execution_date=20210128T000000, start_date=20230126T062643, end_date=20230126T062646
[2023-01-26T06:26:46.222+0000] {standard_task_runner.py:105} ERROR - Failed to execute job 157 for task complete_twitter_etl ('aws_access_key_id'; 2767)
[2023-01-26T06:26:46.462+0000] {local_task_job.py:208} INFO - Task exited with return code 1
[2023-01-26T06:26:46.620+0000] {taskinstance.py:2578} INFO - 0 downstream tasks scheduled from follow-on schedule check
[2023-01-26T07:12:44.067+0000] {taskinstance.py:1083} INFO - Dependencies all met for <TaskInstance: twitter_dag.complete_twitter_etl scheduled__2021-01-28T00:00:00+00:00 [queued]>
[2023-01-26T07:12:44.172+0000] {taskinstance.py:1083} INFO - Dependencies all met for <TaskInstance: twitter_dag.complete_twitter_etl scheduled__2021-01-28T00:00:00+00:00 [queued]>
[2023-01-26T07:12:44.174+0000] {taskinstance.py:1279} INFO - 
--------------------------------------------------------------------------------
[2023-01-26T07:12:44.176+0000] {taskinstance.py:1280} INFO - Starting attempt 1 of 2
[2023-01-26T07:12:44.180+0000] {taskinstance.py:1281} INFO - 
--------------------------------------------------------------------------------
[2023-01-26T07:12:44.460+0000] {taskinstance.py:1300} INFO - Executing <Task(PythonOperator): complete_twitter_etl> on 2021-01-28 00:00:00+00:00
[2023-01-26T07:12:44.507+0000] {standard_task_runner.py:55} INFO - Started process 1140 to run task
[2023-01-26T07:12:44.520+0000] {standard_task_runner.py:82} INFO - Running: ['***', 'tasks', 'run', 'twitter_dag', 'complete_twitter_etl', 'scheduled__2021-01-28T00:00:00+00:00', '--job-id', '120', '--raw', '--subdir', 'DAGS_FOLDER/twitter_dag.py', '--cfg-path', '/tmp/tmpt4lanwi2']
[2023-01-26T07:12:44.531+0000] {standard_task_runner.py:83} INFO - Job 120: Subtask complete_twitter_etl
[2023-01-26T07:12:46.487+0000] {task_command.py:388} INFO - Running <TaskInstance: twitter_dag.complete_twitter_etl scheduled__2021-01-28T00:00:00+00:00 [running]> on host 2221c1ebf970
[2023-01-26T07:12:46.663+0000] {taskinstance.py:1509} INFO - Exporting the following env vars:
AIRFLOW_CTX_DAG_EMAIL=***@example.com
AIRFLOW_CTX_DAG_OWNER=***
AIRFLOW_CTX_DAG_ID=twitter_dag
AIRFLOW_CTX_TASK_ID=complete_twitter_etl
AIRFLOW_CTX_EXECUTION_DATE=2021-01-28T00:00:00+00:00
AIRFLOW_CTX_TRY_NUMBER=1
AIRFLOW_CTX_DAG_RUN_ID=scheduled__2021-01-28T00:00:00+00:00
[2023-01-26T07:12:50.244+0000] {python.py:177} INFO - Done. Returned value was: None
[2023-01-26T07:12:50.276+0000] {taskinstance.py:1323} INFO - Marking task as SUCCESS. dag_id=twitter_dag, task_id=complete_twitter_etl, execution_date=20210128T000000, start_date=20230126T071244, end_date=20230126T071250
[2023-01-26T07:12:50.567+0000] {local_task_job.py:208} INFO - Task exited with return code 0
[2023-01-26T07:12:52.056+0000] {taskinstance.py:2578} INFO - 0 downstream tasks scheduled from follow-on schedule check
[2023-01-26T08:29:54.119+0000] {taskinstance.py:1083} INFO - Dependencies all met for <TaskInstance: twitter_dag.complete_twitter_etl scheduled__2021-01-28T00:00:00+00:00 [queued]>
[2023-01-26T08:29:54.164+0000] {taskinstance.py:1083} INFO - Dependencies all met for <TaskInstance: twitter_dag.complete_twitter_etl scheduled__2021-01-28T00:00:00+00:00 [queued]>
[2023-01-26T08:29:54.166+0000] {taskinstance.py:1279} INFO - 
--------------------------------------------------------------------------------
[2023-01-26T08:29:54.170+0000] {taskinstance.py:1280} INFO - Starting attempt 1 of 2
[2023-01-26T08:29:54.171+0000] {taskinstance.py:1281} INFO - 
--------------------------------------------------------------------------------
[2023-01-26T08:29:54.357+0000] {taskinstance.py:1300} INFO - Executing <Task(PythonOperator): complete_twitter_etl> on 2021-01-28 00:00:00+00:00
[2023-01-26T08:29:54.365+0000] {standard_task_runner.py:55} INFO - Started process 2398 to run task
[2023-01-26T08:29:54.411+0000] {standard_task_runner.py:82} INFO - Running: ['***', 'tasks', 'run', 'twitter_dag', 'complete_twitter_etl', 'scheduled__2021-01-28T00:00:00+00:00', '--job-id', '169', '--raw', '--subdir', 'DAGS_FOLDER/twitter_dag.py', '--cfg-path', '/tmp/tmp1it5nhu4']
[2023-01-26T08:29:54.426+0000] {standard_task_runner.py:83} INFO - Job 169: Subtask complete_twitter_etl
[2023-01-26T08:29:55.761+0000] {task_command.py:388} INFO - Running <TaskInstance: twitter_dag.complete_twitter_etl scheduled__2021-01-28T00:00:00+00:00 [running]> on host 3143b9e5b257
[2023-01-26T08:29:56.138+0000] {taskinstance.py:1509} INFO - Exporting the following env vars:
AIRFLOW_CTX_DAG_EMAIL=***@example.com
AIRFLOW_CTX_DAG_OWNER=***
AIRFLOW_CTX_DAG_ID=twitter_dag
AIRFLOW_CTX_TASK_ID=complete_twitter_etl
AIRFLOW_CTX_EXECUTION_DATE=2021-01-28T00:00:00+00:00
AIRFLOW_CTX_TRY_NUMBER=1
AIRFLOW_CTX_DAG_RUN_ID=scheduled__2021-01-28T00:00:00+00:00
[2023-01-26T08:29:58.910+0000] {taskinstance.py:1768} ERROR - Task failed with exception
Traceback (most recent call last):
  File "/home/airflow/.local/lib/python3.7/site-packages/airflow/operators/python.py", line 175, in execute
    return_value = self.execute_callable()
  File "/home/airflow/.local/lib/python3.7/site-packages/airflow/operators/python.py", line 192, in execute_callable
    return self.python_callable(*self.op_args, **self.op_kwargs)
  File "/opt/airflow/dags/twitter_etl.py", line 64, in run_twitter_etl
    s3.Object(BUCKET_NAME, KEY).put(Body=csv_buffer.getvalue())
  File "/home/airflow/.local/lib/python3.7/site-packages/boto3/resources/factory.py", line 580, in do_action
    response = action(self, *args, **kwargs)
  File "/home/airflow/.local/lib/python3.7/site-packages/boto3/resources/action.py", line 88, in __call__
    response = getattr(parent.meta.client, operation_name)(*args, **params)
  File "/home/airflow/.local/lib/python3.7/site-packages/botocore/client.py", line 508, in _api_call
    return self._make_api_call(operation_name, kwargs)
  File "/home/airflow/.local/lib/python3.7/site-packages/botocore/client.py", line 915, in _make_api_call
    raise error_class(parsed_response, operation_name)
botocore.exceptions.ClientError: An error occurred (InvalidAccessKeyId) when calling the PutObject operation: The AWS Access Key Id you provided does not exist in our records.
[2023-01-26T08:29:59.116+0000] {taskinstance.py:1323} INFO - Marking task as UP_FOR_RETRY. dag_id=twitter_dag, task_id=complete_twitter_etl, execution_date=20210128T000000, start_date=20230126T082954, end_date=20230126T082959
[2023-01-26T08:29:59.790+0000] {standard_task_runner.py:105} ERROR - Failed to execute job 169 for task complete_twitter_etl (An error occurred (InvalidAccessKeyId) when calling the PutObject operation: The AWS Access Key Id you provided does not exist in our records.; 2398)
[2023-01-26T08:30:00.249+0000] {local_task_job.py:208} INFO - Task exited with return code 1
[2023-01-26T08:30:02.305+0000] {taskinstance.py:2578} INFO - 0 downstream tasks scheduled from follow-on schedule check
[2023-01-26T09:10:08.670+0000] {taskinstance.py:1083} INFO - Dependencies all met for <TaskInstance: twitter_dag.complete_twitter_etl scheduled__2021-01-28T00:00:00+00:00 [queued]>
[2023-01-26T09:10:08.794+0000] {taskinstance.py:1083} INFO - Dependencies all met for <TaskInstance: twitter_dag.complete_twitter_etl scheduled__2021-01-28T00:00:00+00:00 [queued]>
[2023-01-26T09:10:08.795+0000] {taskinstance.py:1279} INFO - 
--------------------------------------------------------------------------------
[2023-01-26T09:10:08.799+0000] {taskinstance.py:1280} INFO - Starting attempt 1 of 2
[2023-01-26T09:10:08.810+0000] {taskinstance.py:1281} INFO - 
--------------------------------------------------------------------------------
[2023-01-26T09:10:08.932+0000] {taskinstance.py:1300} INFO - Executing <Task(PythonOperator): complete_twitter_etl> on 2021-01-28 00:00:00+00:00
[2023-01-26T09:10:08.991+0000] {standard_task_runner.py:55} INFO - Started process 437 to run task
[2023-01-26T09:10:09.062+0000] {standard_task_runner.py:82} INFO - Running: ['***', 'tasks', 'run', 'twitter_dag', 'complete_twitter_etl', 'scheduled__2021-01-28T00:00:00+00:00', '--job-id', '84', '--raw', '--subdir', 'DAGS_FOLDER/twitter_dag.py', '--cfg-path', '/tmp/tmpkm3diacn']
[2023-01-26T09:10:09.076+0000] {standard_task_runner.py:83} INFO - Job 84: Subtask complete_twitter_etl
[2023-01-26T09:10:10.928+0000] {task_command.py:388} INFO - Running <TaskInstance: twitter_dag.complete_twitter_etl scheduled__2021-01-28T00:00:00+00:00 [running]> on host d0fc3b00c15c
[2023-01-26T09:10:11.384+0000] {taskinstance.py:1509} INFO - Exporting the following env vars:
AIRFLOW_CTX_DAG_EMAIL=***@example.com
AIRFLOW_CTX_DAG_OWNER=***
AIRFLOW_CTX_DAG_ID=twitter_dag
AIRFLOW_CTX_TASK_ID=complete_twitter_etl
AIRFLOW_CTX_EXECUTION_DATE=2021-01-28T00:00:00+00:00
AIRFLOW_CTX_TRY_NUMBER=1
AIRFLOW_CTX_DAG_RUN_ID=scheduled__2021-01-28T00:00:00+00:00
[2023-01-26T09:10:16.063+0000] {python.py:177} INFO - Done. Returned value was: None
[2023-01-26T09:10:16.175+0000] {taskinstance.py:1323} INFO - Marking task as SUCCESS. dag_id=twitter_dag, task_id=complete_twitter_etl, execution_date=20210128T000000, start_date=20230126T091008, end_date=20230126T091016
[2023-01-26T09:10:16.668+0000] {local_task_job.py:208} INFO - Task exited with return code 0
[2023-01-26T09:10:17.435+0000] {taskinstance.py:2578} INFO - 0 downstream tasks scheduled from follow-on schedule check
