[2023-01-26T08:07:53.813+0000] {taskinstance.py:1083} INFO - Dependencies all met for <TaskInstance: twitter_dag.complete_twitter_etl manual__2023-01-26T08:07:46.638764+00:00 [queued]>
[2023-01-26T08:07:53.855+0000] {taskinstance.py:1083} INFO - Dependencies all met for <TaskInstance: twitter_dag.complete_twitter_etl manual__2023-01-26T08:07:46.638764+00:00 [queued]>
[2023-01-26T08:07:53.860+0000] {taskinstance.py:1279} INFO - 
--------------------------------------------------------------------------------
[2023-01-26T08:07:53.863+0000] {taskinstance.py:1280} INFO - Starting attempt 1 of 2
[2023-01-26T08:07:53.864+0000] {taskinstance.py:1281} INFO - 
--------------------------------------------------------------------------------
[2023-01-26T08:07:53.934+0000] {taskinstance.py:1300} INFO - Executing <Task(PythonOperator): complete_twitter_etl> on 2023-01-26 08:07:46.638764+00:00
[2023-01-26T08:07:53.956+0000] {standard_task_runner.py:55} INFO - Started process 803 to run task
[2023-01-26T08:07:53.974+0000] {standard_task_runner.py:82} INFO - Running: ['***', 'tasks', 'run', 'twitter_dag', 'complete_twitter_etl', 'manual__2023-01-26T08:07:46.638764+00:00', '--job-id', '38', '--raw', '--subdir', 'DAGS_FOLDER/twitter_dag.py', '--cfg-path', '/tmp/tmpc9wfe8vg']
[2023-01-26T08:07:53.977+0000] {standard_task_runner.py:83} INFO - Job 38: Subtask complete_twitter_etl
[2023-01-26T08:07:54.453+0000] {task_command.py:388} INFO - Running <TaskInstance: twitter_dag.complete_twitter_etl manual__2023-01-26T08:07:46.638764+00:00 [running]> on host 3143b9e5b257
[2023-01-26T08:07:54.568+0000] {taskinstance.py:1509} INFO - Exporting the following env vars:
AIRFLOW_CTX_DAG_EMAIL=***@example.com
AIRFLOW_CTX_DAG_OWNER=***
AIRFLOW_CTX_DAG_ID=twitter_dag
AIRFLOW_CTX_TASK_ID=complete_twitter_etl
AIRFLOW_CTX_EXECUTION_DATE=2023-01-26T08:07:46.638764+00:00
AIRFLOW_CTX_TRY_NUMBER=1
AIRFLOW_CTX_DAG_RUN_ID=manual__2023-01-26T08:07:46.638764+00:00
[2023-01-26T08:07:55.714+0000] {taskinstance.py:1768} ERROR - Task failed with exception
Traceback (most recent call last):
  File "/home/airflow/.local/lib/python3.7/site-packages/airflow/operators/python.py", line 175, in execute
    return_value = self.execute_callable()
  File "/home/airflow/.local/lib/python3.7/site-packages/airflow/operators/python.py", line 192, in execute_callable
    return self.python_callable(*self.op_args, **self.op_kwargs)
  File "/opt/airflow/dags/twitter_etl.py", line 64, in run_twitter_etl
    s3.Object(BUCKET_NAME, KEY).put(Body=csv_buffer.getvalue())
  File "/home/airflow/.local/lib/python3.7/site-packages/boto3/resources/factory.py", line 580, in do_action
    response = action(self, *args, **kwargs)
  File "/home/airflow/.local/lib/python3.7/site-packages/boto3/resources/action.py", line 88, in __call__
    response = getattr(parent.meta.client, operation_name)(*args, **params)
  File "/home/airflow/.local/lib/python3.7/site-packages/botocore/client.py", line 508, in _api_call
    return self._make_api_call(operation_name, kwargs)
  File "/home/airflow/.local/lib/python3.7/site-packages/botocore/client.py", line 915, in _make_api_call
    raise error_class(parsed_response, operation_name)
botocore.exceptions.ClientError: An error occurred (InvalidAccessKeyId) when calling the PutObject operation: The AWS Access Key Id you provided does not exist in our records.
[2023-01-26T08:07:55.734+0000] {taskinstance.py:1323} INFO - Marking task as UP_FOR_RETRY. dag_id=twitter_dag, task_id=complete_twitter_etl, execution_date=20230126T080746, start_date=20230126T080753, end_date=20230126T080755
[2023-01-26T08:07:55.761+0000] {standard_task_runner.py:105} ERROR - Failed to execute job 38 for task complete_twitter_etl (An error occurred (InvalidAccessKeyId) when calling the PutObject operation: The AWS Access Key Id you provided does not exist in our records.; 803)
[2023-01-26T08:07:55.828+0000] {local_task_job.py:208} INFO - Task exited with return code 1
[2023-01-26T08:07:55.864+0000] {taskinstance.py:2578} INFO - 0 downstream tasks scheduled from follow-on schedule check
