[2023-01-25T18:58:50.208+0000] {taskinstance.py:1083} INFO - Dependencies all met for <TaskInstance: twitter_dag.complete_twitter_etl scheduled__2021-03-17T00:00:00+00:00 [queued]>
[2023-01-25T18:58:50.484+0000] {taskinstance.py:1083} INFO - Dependencies all met for <TaskInstance: twitter_dag.complete_twitter_etl scheduled__2021-03-17T00:00:00+00:00 [queued]>
[2023-01-25T18:58:50.494+0000] {taskinstance.py:1279} INFO - 
--------------------------------------------------------------------------------
[2023-01-25T18:58:50.496+0000] {taskinstance.py:1280} INFO - Starting attempt 1 of 2
[2023-01-25T18:58:50.500+0000] {taskinstance.py:1281} INFO - 
--------------------------------------------------------------------------------
[2023-01-25T18:58:51.298+0000] {taskinstance.py:1300} INFO - Executing <Task(PythonOperator): complete_twitter_etl> on 2021-03-17 00:00:00+00:00
[2023-01-25T18:58:51.448+0000] {standard_task_runner.py:82} INFO - Running: ['***', 'tasks', 'run', 'twitter_dag', 'complete_twitter_etl', 'scheduled__2021-03-17T00:00:00+00:00', '--job-id', '253', '--raw', '--subdir', 'DAGS_FOLDER/twitter_dag.py', '--cfg-path', '/tmp/tmp5qaragsm']
[2023-01-25T18:58:51.457+0000] {standard_task_runner.py:83} INFO - Job 253: Subtask complete_twitter_etl
[2023-01-25T18:58:51.422+0000] {standard_task_runner.py:55} INFO - Started process 2501 to run task
[2023-01-25T18:58:54.771+0000] {task_command.py:388} INFO - Running <TaskInstance: twitter_dag.complete_twitter_etl scheduled__2021-03-17T00:00:00+00:00 [running]> on host 512d0ff0785b
[2023-01-25T18:58:56.964+0000] {taskinstance.py:1509} INFO - Exporting the following env vars:
AIRFLOW_CTX_DAG_EMAIL=***@example.com
AIRFLOW_CTX_DAG_OWNER=***
AIRFLOW_CTX_DAG_ID=twitter_dag
AIRFLOW_CTX_TASK_ID=complete_twitter_etl
AIRFLOW_CTX_EXECUTION_DATE=2021-03-17T00:00:00+00:00
AIRFLOW_CTX_TRY_NUMBER=1
AIRFLOW_CTX_DAG_RUN_ID=scheduled__2021-03-17T00:00:00+00:00
[2023-01-25T18:59:03.391+0000] {taskinstance.py:1768} ERROR - Task failed with exception
Traceback (most recent call last):
  File "/home/airflow/.local/lib/python3.7/site-packages/s3fs/core.py", line 112, in _error_wrapper
    return await func(*args, **kwargs)
  File "/home/airflow/.local/lib/python3.7/site-packages/aiobotocore/client.py", line 358, in _make_api_call
    raise error_class(parsed_response, operation_name)
botocore.exceptions.ClientError: An error occurred (AccessDenied) when calling the CreateBucket operation: Anonymous access is forbidden for this operation

The above exception was the direct cause of the following exception:

Traceback (most recent call last):
  File "/home/airflow/.local/lib/python3.7/site-packages/airflow/operators/python.py", line 175, in execute
    return_value = self.execute_callable()
  File "/home/airflow/.local/lib/python3.7/site-packages/airflow/operators/python.py", line 192, in execute_callable
    return self.python_callable(*self.op_args, **self.op_kwargs)
  File "/opt/airflow/dags/twitter_etl.py", line 46, in run_twitter_etl
    df.to_csv("s3://jinchoi-airflow-bucket/data/elonmusk_tweets.csv")
  File "/home/airflow/.local/lib/python3.7/site-packages/pandas/core/generic.py", line 3482, in to_csv
    storage_options=storage_options,
  File "/home/airflow/.local/lib/python3.7/site-packages/pandas/io/formats/format.py", line 1105, in to_csv
    csv_formatter.save()
  File "/home/airflow/.local/lib/python3.7/site-packages/pandas/io/formats/csvs.py", line 243, in save
    storage_options=self.storage_options,
  File "/home/airflow/.local/lib/python3.7/site-packages/pandas/io/common.py", line 614, in get_handle
    storage_options=storage_options,
  File "/home/airflow/.local/lib/python3.7/site-packages/pandas/io/common.py", line 370, in _get_filepath_or_buffer
    filepath_or_buffer, mode=fsspec_mode, **(storage_options or {})
  File "/home/airflow/.local/lib/python3.7/site-packages/fsspec/core.py", line 428, in open
    **kwargs,
  File "/home/airflow/.local/lib/python3.7/site-packages/fsspec/core.py", line 283, in open_files
    [fs.makedirs(parent, exist_ok=True) for parent in parents]
  File "/home/airflow/.local/lib/python3.7/site-packages/fsspec/core.py", line 283, in <listcomp>
    [fs.makedirs(parent, exist_ok=True) for parent in parents]
  File "/home/airflow/.local/lib/python3.7/site-packages/fsspec/asyn.py", line 114, in wrapper
    return sync(self.loop, func, *args, **kwargs)
  File "/home/airflow/.local/lib/python3.7/site-packages/fsspec/asyn.py", line 99, in sync
    raise return_result
  File "/home/airflow/.local/lib/python3.7/site-packages/fsspec/asyn.py", line 54, in _runner
    result[0] = await coro
  File "/home/airflow/.local/lib/python3.7/site-packages/s3fs/core.py", line 883, in _makedirs
    await self._mkdir(path, create_parents=True)
  File "/home/airflow/.local/lib/python3.7/site-packages/s3fs/core.py", line 868, in _mkdir
    await self._call_s3("create_bucket", **params)
  File "/home/airflow/.local/lib/python3.7/site-packages/s3fs/core.py", line 340, in _call_s3
    method, kwargs=additional_kwargs, retries=self.retries
  File "/home/airflow/.local/lib/python3.7/site-packages/s3fs/core.py", line 139, in _error_wrapper
    raise err
PermissionError: Anonymous access is forbidden for this operation
[2023-01-25T18:59:03.464+0000] {taskinstance.py:1323} INFO - Marking task as UP_FOR_RETRY. dag_id=twitter_dag, task_id=complete_twitter_etl, execution_date=20210317T000000, start_date=20230125T185850, end_date=20230125T185903
[2023-01-25T18:59:03.564+0000] {standard_task_runner.py:105} ERROR - Failed to execute job 253 for task complete_twitter_etl (Anonymous access is forbidden for this operation; 2501)
[2023-01-25T18:59:03.730+0000] {local_task_job.py:208} INFO - Task exited with return code 1
[2023-01-25T18:59:05.053+0000] {taskinstance.py:2578} INFO - 0 downstream tasks scheduled from follow-on schedule check
[2023-01-26T06:54:00.483+0000] {taskinstance.py:1083} INFO - Dependencies all met for <TaskInstance: twitter_dag.complete_twitter_etl scheduled__2021-03-17T00:00:00+00:00 [queued]>
[2023-01-26T06:54:00.536+0000] {taskinstance.py:1083} INFO - Dependencies all met for <TaskInstance: twitter_dag.complete_twitter_etl scheduled__2021-03-17T00:00:00+00:00 [queued]>
[2023-01-26T06:54:00.538+0000] {taskinstance.py:1279} INFO - 
--------------------------------------------------------------------------------
[2023-01-26T06:54:00.539+0000] {taskinstance.py:1280} INFO - Starting attempt 1 of 2
[2023-01-26T06:54:00.540+0000] {taskinstance.py:1281} INFO - 
--------------------------------------------------------------------------------
[2023-01-26T06:54:00.604+0000] {taskinstance.py:1300} INFO - Executing <Task(PythonOperator): complete_twitter_etl> on 2021-03-17 00:00:00+00:00
[2023-01-26T06:54:00.621+0000] {standard_task_runner.py:55} INFO - Started process 347 to run task
[2023-01-26T06:54:00.644+0000] {standard_task_runner.py:82} INFO - Running: ['***', 'tasks', 'run', 'twitter_dag', 'complete_twitter_etl', 'scheduled__2021-03-17T00:00:00+00:00', '--job-id', '251', '--raw', '--subdir', 'DAGS_FOLDER/twitter_dag.py', '--cfg-path', '/tmp/tmp0g8lgn8s']
[2023-01-26T06:54:00.646+0000] {standard_task_runner.py:83} INFO - Job 251: Subtask complete_twitter_etl
[2023-01-26T06:54:01.362+0000] {task_command.py:388} INFO - Running <TaskInstance: twitter_dag.complete_twitter_etl scheduled__2021-03-17T00:00:00+00:00 [running]> on host 47843127de93
[2023-01-26T06:54:01.588+0000] {taskinstance.py:1509} INFO - Exporting the following env vars:
AIRFLOW_CTX_DAG_EMAIL=***@example.com
AIRFLOW_CTX_DAG_OWNER=***
AIRFLOW_CTX_DAG_ID=twitter_dag
AIRFLOW_CTX_TASK_ID=complete_twitter_etl
AIRFLOW_CTX_EXECUTION_DATE=2021-03-17T00:00:00+00:00
AIRFLOW_CTX_TRY_NUMBER=1
AIRFLOW_CTX_DAG_RUN_ID=scheduled__2021-03-17T00:00:00+00:00
[2023-01-26T06:54:02.160+0000] {taskinstance.py:1768} ERROR - Task failed with exception
Traceback (most recent call last):
  File "/home/airflow/.local/lib/python3.7/site-packages/airflow/operators/python.py", line 175, in execute
    return_value = self.execute_callable()
  File "/home/airflow/.local/lib/python3.7/site-packages/airflow/operators/python.py", line 192, in execute_callable
    return self.python_callable(*self.op_args, **self.op_kwargs)
  File "/opt/airflow/dags/twitter_etl.py", line 51, in run_twitter_etl
    aws_access_key_id=os.environ['aws_access_key_id'],
  File "/usr/local/lib/python3.7/os.py", line 681, in __getitem__
    raise KeyError(key) from None
KeyError: 'aws_access_key_id'
[2023-01-26T06:54:02.176+0000] {taskinstance.py:1323} INFO - Marking task as UP_FOR_RETRY. dag_id=twitter_dag, task_id=complete_twitter_etl, execution_date=20210317T000000, start_date=20230126T065400, end_date=20230126T065402
[2023-01-26T06:54:02.222+0000] {standard_task_runner.py:105} ERROR - Failed to execute job 251 for task complete_twitter_etl ('aws_access_key_id'; 347)
[2023-01-26T06:54:02.275+0000] {local_task_job.py:208} INFO - Task exited with return code 1
[2023-01-26T06:54:02.354+0000] {taskinstance.py:2578} INFO - 0 downstream tasks scheduled from follow-on schedule check
[2023-01-26T07:13:56.124+0000] {taskinstance.py:1083} INFO - Dependencies all met for <TaskInstance: twitter_dag.complete_twitter_etl scheduled__2021-03-17T00:00:00+00:00 [queued]>
[2023-01-26T07:13:56.157+0000] {taskinstance.py:1083} INFO - Dependencies all met for <TaskInstance: twitter_dag.complete_twitter_etl scheduled__2021-03-17T00:00:00+00:00 [queued]>
[2023-01-26T07:13:56.166+0000] {taskinstance.py:1279} INFO - 
--------------------------------------------------------------------------------
[2023-01-26T07:13:56.168+0000] {taskinstance.py:1280} INFO - Starting attempt 1 of 2
[2023-01-26T07:13:56.170+0000] {taskinstance.py:1281} INFO - 
--------------------------------------------------------------------------------
[2023-01-26T07:13:56.347+0000] {taskinstance.py:1300} INFO - Executing <Task(PythonOperator): complete_twitter_etl> on 2021-03-17 00:00:00+00:00
[2023-01-26T07:13:56.366+0000] {standard_task_runner.py:55} INFO - Started process 1323 to run task
[2023-01-26T07:13:56.427+0000] {standard_task_runner.py:82} INFO - Running: ['***', 'tasks', 'run', 'twitter_dag', 'complete_twitter_etl', 'scheduled__2021-03-17T00:00:00+00:00', '--job-id', '168', '--raw', '--subdir', 'DAGS_FOLDER/twitter_dag.py', '--cfg-path', '/tmp/tmpd8xqntvy']
[2023-01-26T07:13:56.433+0000] {standard_task_runner.py:83} INFO - Job 168: Subtask complete_twitter_etl
[2023-01-26T07:13:59.718+0000] {task_command.py:388} INFO - Running <TaskInstance: twitter_dag.complete_twitter_etl scheduled__2021-03-17T00:00:00+00:00 [running]> on host 2221c1ebf970
[2023-01-26T07:14:00.393+0000] {taskinstance.py:1509} INFO - Exporting the following env vars:
AIRFLOW_CTX_DAG_EMAIL=***@example.com
AIRFLOW_CTX_DAG_OWNER=***
AIRFLOW_CTX_DAG_ID=twitter_dag
AIRFLOW_CTX_TASK_ID=complete_twitter_etl
AIRFLOW_CTX_EXECUTION_DATE=2021-03-17T00:00:00+00:00
AIRFLOW_CTX_TRY_NUMBER=1
AIRFLOW_CTX_DAG_RUN_ID=scheduled__2021-03-17T00:00:00+00:00
[2023-01-26T07:14:02.850+0000] {python.py:177} INFO - Done. Returned value was: None
[2023-01-26T07:14:02.888+0000] {taskinstance.py:1323} INFO - Marking task as SUCCESS. dag_id=twitter_dag, task_id=complete_twitter_etl, execution_date=20210317T000000, start_date=20230126T071356, end_date=20230126T071402
[2023-01-26T07:14:03.531+0000] {local_task_job.py:208} INFO - Task exited with return code 0
[2023-01-26T07:14:05.398+0000] {taskinstance.py:2578} INFO - 0 downstream tasks scheduled from follow-on schedule check
[2023-01-26T09:11:38.595+0000] {taskinstance.py:1083} INFO - Dependencies all met for <TaskInstance: twitter_dag.complete_twitter_etl scheduled__2021-03-17T00:00:00+00:00 [queued]>
[2023-01-26T09:11:38.689+0000] {taskinstance.py:1083} INFO - Dependencies all met for <TaskInstance: twitter_dag.complete_twitter_etl scheduled__2021-03-17T00:00:00+00:00 [queued]>
[2023-01-26T09:11:38.691+0000] {taskinstance.py:1279} INFO - 
--------------------------------------------------------------------------------
[2023-01-26T09:11:38.693+0000] {taskinstance.py:1280} INFO - Starting attempt 1 of 2
[2023-01-26T09:11:38.699+0000] {taskinstance.py:1281} INFO - 
--------------------------------------------------------------------------------
[2023-01-26T09:11:38.824+0000] {taskinstance.py:1300} INFO - Executing <Task(PythonOperator): complete_twitter_etl> on 2021-03-17 00:00:00+00:00
[2023-01-26T09:11:38.886+0000] {standard_task_runner.py:55} INFO - Started process 645 to run task
[2023-01-26T09:11:38.950+0000] {standard_task_runner.py:82} INFO - Running: ['***', 'tasks', 'run', 'twitter_dag', 'complete_twitter_etl', 'scheduled__2021-03-17T00:00:00+00:00', '--job-id', '131', '--raw', '--subdir', 'DAGS_FOLDER/twitter_dag.py', '--cfg-path', '/tmp/tmp9_9jnrps']
[2023-01-26T09:11:38.957+0000] {standard_task_runner.py:83} INFO - Job 131: Subtask complete_twitter_etl
[2023-01-26T09:11:41.033+0000] {task_command.py:388} INFO - Running <TaskInstance: twitter_dag.complete_twitter_etl scheduled__2021-03-17T00:00:00+00:00 [running]> on host d0fc3b00c15c
[2023-01-26T09:11:41.722+0000] {taskinstance.py:1509} INFO - Exporting the following env vars:
AIRFLOW_CTX_DAG_EMAIL=***@example.com
AIRFLOW_CTX_DAG_OWNER=***
AIRFLOW_CTX_DAG_ID=twitter_dag
AIRFLOW_CTX_TASK_ID=complete_twitter_etl
AIRFLOW_CTX_EXECUTION_DATE=2021-03-17T00:00:00+00:00
AIRFLOW_CTX_TRY_NUMBER=1
AIRFLOW_CTX_DAG_RUN_ID=scheduled__2021-03-17T00:00:00+00:00
[2023-01-26T09:11:43.706+0000] {python.py:177} INFO - Done. Returned value was: None
[2023-01-26T09:11:43.739+0000] {taskinstance.py:1323} INFO - Marking task as SUCCESS. dag_id=twitter_dag, task_id=complete_twitter_etl, execution_date=20210317T000000, start_date=20230126T091138, end_date=20230126T091143
[2023-01-26T09:11:43.871+0000] {local_task_job.py:208} INFO - Task exited with return code 0
[2023-01-26T09:11:43.952+0000] {taskinstance.py:2578} INFO - 0 downstream tasks scheduled from follow-on schedule check
