[2023-01-25T18:40:15.603+0000] {taskinstance.py:1083} INFO - Dependencies all met for <TaskInstance: twitter_dag.complete_twitter_etl scheduled__2020-11-12T00:00:00+00:00 [queued]>
[2023-01-25T18:40:17.458+0000] {taskinstance.py:1083} INFO - Dependencies all met for <TaskInstance: twitter_dag.complete_twitter_etl scheduled__2020-11-12T00:00:00+00:00 [queued]>
[2023-01-25T18:40:17.477+0000] {taskinstance.py:1279} INFO - 
--------------------------------------------------------------------------------
[2023-01-25T18:40:17.519+0000] {taskinstance.py:1280} INFO - Starting attempt 1 of 2
[2023-01-25T18:40:17.549+0000] {taskinstance.py:1281} INFO - 
--------------------------------------------------------------------------------
[2023-01-25T18:40:20.976+0000] {taskinstance.py:1300} INFO - Executing <Task(PythonOperator): complete_twitter_etl> on 2020-11-12 00:00:00+00:00
[2023-01-25T18:40:21.270+0000] {standard_task_runner.py:55} INFO - Started process 319 to run task
[2023-01-25T18:40:21.528+0000] {standard_task_runner.py:82} INFO - Running: ['***', 'tasks', 'run', 'twitter_dag', 'complete_twitter_etl', 'scheduled__2020-11-12T00:00:00+00:00', '--job-id', '7', '--raw', '--subdir', 'DAGS_FOLDER/twitter_dag.py', '--cfg-path', '/tmp/tmpg3ulh428']
[2023-01-25T18:40:21.569+0000] {standard_task_runner.py:83} INFO - Job 7: Subtask complete_twitter_etl
[2023-01-25T18:40:31.371+0000] {task_command.py:388} INFO - Running <TaskInstance: twitter_dag.complete_twitter_etl scheduled__2020-11-12T00:00:00+00:00 [running]> on host 512d0ff0785b
[2023-01-25T18:40:34.549+0000] {taskinstance.py:1509} INFO - Exporting the following env vars:
AIRFLOW_CTX_DAG_EMAIL=***@example.com
AIRFLOW_CTX_DAG_OWNER=***
AIRFLOW_CTX_DAG_ID=twitter_dag
AIRFLOW_CTX_TASK_ID=complete_twitter_etl
AIRFLOW_CTX_EXECUTION_DATE=2020-11-12T00:00:00+00:00
AIRFLOW_CTX_TRY_NUMBER=1
AIRFLOW_CTX_DAG_RUN_ID=scheduled__2020-11-12T00:00:00+00:00
[2023-01-25T18:40:55.360+0000] {taskinstance.py:1768} ERROR - Task failed with exception
Traceback (most recent call last):
  File "/home/airflow/.local/lib/python3.7/site-packages/s3fs/core.py", line 112, in _error_wrapper
    return await func(*args, **kwargs)
  File "/home/airflow/.local/lib/python3.7/site-packages/aiobotocore/client.py", line 358, in _make_api_call
    raise error_class(parsed_response, operation_name)
botocore.exceptions.ClientError: An error occurred (AccessDenied) when calling the CreateBucket operation: Anonymous access is forbidden for this operation

The above exception was the direct cause of the following exception:

Traceback (most recent call last):
  File "/home/airflow/.local/lib/python3.7/site-packages/airflow/operators/python.py", line 175, in execute
    return_value = self.execute_callable()
  File "/home/airflow/.local/lib/python3.7/site-packages/airflow/operators/python.py", line 192, in execute_callable
    return self.python_callable(*self.op_args, **self.op_kwargs)
  File "/opt/airflow/dags/twitter_etl.py", line 46, in run_twitter_etl
    df.to_csv("s3://jinchoi-airflow-bucket/data/elonmusk_tweets.csv")
  File "/home/airflow/.local/lib/python3.7/site-packages/pandas/core/generic.py", line 3482, in to_csv
    storage_options=storage_options,
  File "/home/airflow/.local/lib/python3.7/site-packages/pandas/io/formats/format.py", line 1105, in to_csv
    csv_formatter.save()
  File "/home/airflow/.local/lib/python3.7/site-packages/pandas/io/formats/csvs.py", line 243, in save
    storage_options=self.storage_options,
  File "/home/airflow/.local/lib/python3.7/site-packages/pandas/io/common.py", line 614, in get_handle
    storage_options=storage_options,
  File "/home/airflow/.local/lib/python3.7/site-packages/pandas/io/common.py", line 370, in _get_filepath_or_buffer
    filepath_or_buffer, mode=fsspec_mode, **(storage_options or {})
  File "/home/airflow/.local/lib/python3.7/site-packages/fsspec/core.py", line 428, in open
    **kwargs,
  File "/home/airflow/.local/lib/python3.7/site-packages/fsspec/core.py", line 283, in open_files
    [fs.makedirs(parent, exist_ok=True) for parent in parents]
  File "/home/airflow/.local/lib/python3.7/site-packages/fsspec/core.py", line 283, in <listcomp>
    [fs.makedirs(parent, exist_ok=True) for parent in parents]
  File "/home/airflow/.local/lib/python3.7/site-packages/fsspec/asyn.py", line 114, in wrapper
    return sync(self.loop, func, *args, **kwargs)
  File "/home/airflow/.local/lib/python3.7/site-packages/fsspec/asyn.py", line 99, in sync
    raise return_result
  File "/home/airflow/.local/lib/python3.7/site-packages/fsspec/asyn.py", line 54, in _runner
    result[0] = await coro
  File "/home/airflow/.local/lib/python3.7/site-packages/s3fs/core.py", line 883, in _makedirs
    await self._mkdir(path, create_parents=True)
  File "/home/airflow/.local/lib/python3.7/site-packages/s3fs/core.py", line 868, in _mkdir
    await self._call_s3("create_bucket", **params)
  File "/home/airflow/.local/lib/python3.7/site-packages/s3fs/core.py", line 340, in _call_s3
    method, kwargs=additional_kwargs, retries=self.retries
  File "/home/airflow/.local/lib/python3.7/site-packages/s3fs/core.py", line 139, in _error_wrapper
    raise err
PermissionError: Anonymous access is forbidden for this operation
[2023-01-25T18:40:55.595+0000] {taskinstance.py:1323} INFO - Marking task as UP_FOR_RETRY. dag_id=twitter_dag, task_id=complete_twitter_etl, execution_date=20201112T000000, start_date=20230125T184015, end_date=20230125T184055
[2023-01-25T18:40:55.766+0000] {standard_task_runner.py:105} ERROR - Failed to execute job 7 for task complete_twitter_etl (Anonymous access is forbidden for this operation; 319)
[2023-01-25T18:40:59.278+0000] {local_task_job.py:208} INFO - Task exited with return code 1
[2023-01-25T18:41:11.322+0000] {taskinstance.py:2578} INFO - 0 downstream tasks scheduled from follow-on schedule check
[2023-01-26T03:22:26.701+0000] {taskinstance.py:1083} INFO - Dependencies all met for <TaskInstance: twitter_dag.complete_twitter_etl scheduled__2020-11-12T00:00:00+00:00 [queued]>
[2023-01-26T03:22:26.824+0000] {taskinstance.py:1083} INFO - Dependencies all met for <TaskInstance: twitter_dag.complete_twitter_etl scheduled__2020-11-12T00:00:00+00:00 [queued]>
[2023-01-26T03:22:26.828+0000] {taskinstance.py:1279} INFO - 
--------------------------------------------------------------------------------
[2023-01-26T03:22:26.829+0000] {taskinstance.py:1280} INFO - Starting attempt 1 of 2
[2023-01-26T03:22:26.831+0000] {taskinstance.py:1281} INFO - 
--------------------------------------------------------------------------------
[2023-01-26T03:22:27.004+0000] {taskinstance.py:1300} INFO - Executing <Task(PythonOperator): complete_twitter_etl> on 2020-11-12 00:00:00+00:00
[2023-01-26T03:22:27.070+0000] {standard_task_runner.py:55} INFO - Started process 132 to run task
[2023-01-26T03:22:27.099+0000] {standard_task_runner.py:82} INFO - Running: ['***', 'tasks', 'run', 'twitter_dag', 'complete_twitter_etl', 'scheduled__2020-11-12T00:00:00+00:00', '--job-id', '5', '--raw', '--subdir', 'DAGS_FOLDER/twitter_dag.py', '--cfg-path', '/tmp/tmpxe4x9mrq']
[2023-01-26T03:22:27.122+0000] {standard_task_runner.py:83} INFO - Job 5: Subtask complete_twitter_etl
[2023-01-26T03:22:28.076+0000] {task_command.py:388} INFO - Running <TaskInstance: twitter_dag.complete_twitter_etl scheduled__2020-11-12T00:00:00+00:00 [running]> on host 3db080823b1b
[2023-01-26T03:22:31.971+0000] {taskinstance.py:1509} INFO - Exporting the following env vars:
AIRFLOW_CTX_DAG_EMAIL=***@example.com
AIRFLOW_CTX_DAG_OWNER=***
AIRFLOW_CTX_DAG_ID=twitter_dag
AIRFLOW_CTX_TASK_ID=complete_twitter_etl
AIRFLOW_CTX_EXECUTION_DATE=2020-11-12T00:00:00+00:00
AIRFLOW_CTX_TRY_NUMBER=1
AIRFLOW_CTX_DAG_RUN_ID=scheduled__2020-11-12T00:00:00+00:00
[2023-01-26T03:22:34.526+0000] {taskinstance.py:1768} ERROR - Task failed with exception
Traceback (most recent call last):
  File "/home/airflow/.local/lib/python3.7/site-packages/airflow/operators/python.py", line 175, in execute
    return_value = self.execute_callable()
  File "/home/airflow/.local/lib/python3.7/site-packages/airflow/operators/python.py", line 192, in execute_callable
    return self.python_callable(*self.op_args, **self.op_kwargs)
  File "/opt/airflow/dags/twitter_etl.py", line 53, in run_twitter_etl
    df.to_csv('s3://{BUCKET_NAME}/data/{KEY}', index=False, header=False,sep=',', engine='python', filesystem=s3)
TypeError: to_csv() got an unexpected keyword argument 'engine'
[2023-01-26T03:22:34.588+0000] {taskinstance.py:1323} INFO - Marking task as UP_FOR_RETRY. dag_id=twitter_dag, task_id=complete_twitter_etl, execution_date=20201112T000000, start_date=20230126T032226, end_date=20230126T032234
[2023-01-26T03:22:34.658+0000] {standard_task_runner.py:105} ERROR - Failed to execute job 5 for task complete_twitter_etl (to_csv() got an unexpected keyword argument 'engine'; 132)
[2023-01-26T03:22:34.968+0000] {local_task_job.py:208} INFO - Task exited with return code 1
[2023-01-26T03:22:35.083+0000] {taskinstance.py:2578} INFO - 0 downstream tasks scheduled from follow-on schedule check
[2023-01-26T03:34:09.254+0000] {taskinstance.py:1083} INFO - Dependencies all met for <TaskInstance: twitter_dag.complete_twitter_etl scheduled__2020-11-12T00:00:00+00:00 [queued]>
[2023-01-26T03:34:09.488+0000] {taskinstance.py:1083} INFO - Dependencies all met for <TaskInstance: twitter_dag.complete_twitter_etl scheduled__2020-11-12T00:00:00+00:00 [queued]>
[2023-01-26T03:34:09.489+0000] {taskinstance.py:1279} INFO - 
--------------------------------------------------------------------------------
[2023-01-26T03:34:09.490+0000] {taskinstance.py:1280} INFO - Starting attempt 1 of 2
[2023-01-26T03:34:09.491+0000] {taskinstance.py:1281} INFO - 
--------------------------------------------------------------------------------
[2023-01-26T03:34:09.560+0000] {taskinstance.py:1300} INFO - Executing <Task(PythonOperator): complete_twitter_etl> on 2020-11-12 00:00:00+00:00
[2023-01-26T03:34:09.657+0000] {standard_task_runner.py:55} INFO - Started process 126 to run task
[2023-01-26T03:34:09.719+0000] {standard_task_runner.py:82} INFO - Running: ['***', 'tasks', 'run', 'twitter_dag', 'complete_twitter_etl', 'scheduled__2020-11-12T00:00:00+00:00', '--job-id', '3', '--raw', '--subdir', 'DAGS_FOLDER/twitter_dag.py', '--cfg-path', '/tmp/tmpbf592a7f']
[2023-01-26T03:34:09.738+0000] {standard_task_runner.py:83} INFO - Job 3: Subtask complete_twitter_etl
[2023-01-26T03:34:10.203+0000] {task_command.py:388} INFO - Running <TaskInstance: twitter_dag.complete_twitter_etl scheduled__2020-11-12T00:00:00+00:00 [running]> on host 9c4f31e2db2b
[2023-01-26T03:34:12.568+0000] {taskinstance.py:1509} INFO - Exporting the following env vars:
AIRFLOW_CTX_DAG_EMAIL=***@example.com
AIRFLOW_CTX_DAG_OWNER=***
AIRFLOW_CTX_DAG_ID=twitter_dag
AIRFLOW_CTX_TASK_ID=complete_twitter_etl
AIRFLOW_CTX_EXECUTION_DATE=2020-11-12T00:00:00+00:00
AIRFLOW_CTX_TRY_NUMBER=1
AIRFLOW_CTX_DAG_RUN_ID=scheduled__2020-11-12T00:00:00+00:00
[2023-01-26T03:34:13.683+0000] {taskinstance.py:1768} ERROR - Task failed with exception
Traceback (most recent call last):
  File "/home/airflow/.local/lib/python3.7/site-packages/airflow/operators/python.py", line 175, in execute
    return_value = self.execute_callable()
  File "/home/airflow/.local/lib/python3.7/site-packages/airflow/operators/python.py", line 192, in execute_callable
    return self.python_callable(*self.op_args, **self.op_kwargs)
  File "/opt/airflow/dags/twitter_etl.py", line 54, in run_twitter_etl
    s3.put('s3://{BUCKET_NAME}/data/{KEY}', csv_buffer)
  File "/home/airflow/.local/lib/python3.7/site-packages/fsspec/asyn.py", line 114, in wrapper
    return sync(self.loop, func, *args, **kwargs)
  File "/home/airflow/.local/lib/python3.7/site-packages/fsspec/asyn.py", line 99, in sync
    raise return_result
  File "/home/airflow/.local/lib/python3.7/site-packages/fsspec/asyn.py", line 54, in _runner
    result[0] = await coro
  File "/home/airflow/.local/lib/python3.7/site-packages/fsspec/asyn.py", line 481, in _put
    rpath = self._strip_protocol(rpath)
  File "/home/airflow/.local/lib/python3.7/site-packages/fsspec/spec.py", line 188, in _strip_protocol
    if path.startswith(protocol + "://"):
TypeError: startswith first arg must be bytes or a tuple of bytes, not str
[2023-01-26T03:34:13.778+0000] {taskinstance.py:1323} INFO - Marking task as UP_FOR_RETRY. dag_id=twitter_dag, task_id=complete_twitter_etl, execution_date=20201112T000000, start_date=20230126T033409, end_date=20230126T033413
[2023-01-26T03:34:13.854+0000] {standard_task_runner.py:105} ERROR - Failed to execute job 3 for task complete_twitter_etl (startswith first arg must be bytes or a tuple of bytes, not str; 126)
[2023-01-26T03:34:14.023+0000] {local_task_job.py:208} INFO - Task exited with return code 1
[2023-01-26T03:34:14.110+0000] {taskinstance.py:2578} INFO - 0 downstream tasks scheduled from follow-on schedule check
[2023-01-26T05:59:22.152+0000] {taskinstance.py:1083} INFO - Dependencies all met for <TaskInstance: twitter_dag.complete_twitter_etl scheduled__2020-11-12T00:00:00+00:00 [queued]>
[2023-01-26T05:59:22.366+0000] {taskinstance.py:1083} INFO - Dependencies all met for <TaskInstance: twitter_dag.complete_twitter_etl scheduled__2020-11-12T00:00:00+00:00 [queued]>
[2023-01-26T05:59:22.374+0000] {taskinstance.py:1279} INFO - 
--------------------------------------------------------------------------------
[2023-01-26T05:59:22.377+0000] {taskinstance.py:1280} INFO - Starting attempt 1 of 2
[2023-01-26T05:59:22.383+0000] {taskinstance.py:1281} INFO - 
--------------------------------------------------------------------------------
[2023-01-26T05:59:22.655+0000] {taskinstance.py:1300} INFO - Executing <Task(PythonOperator): complete_twitter_etl> on 2020-11-12 00:00:00+00:00
[2023-01-26T05:59:22.845+0000] {standard_task_runner.py:55} INFO - Started process 941 to run task
[2023-01-26T05:59:22.859+0000] {standard_task_runner.py:82} INFO - Running: ['***', 'tasks', 'run', 'twitter_dag', 'complete_twitter_etl', 'scheduled__2020-11-12T00:00:00+00:00', '--job-id', '9', '--raw', '--subdir', 'DAGS_FOLDER/twitter_dag.py', '--cfg-path', '/tmp/tmpcrsiyq0b']
[2023-01-26T05:59:22.882+0000] {standard_task_runner.py:83} INFO - Job 9: Subtask complete_twitter_etl
[2023-01-26T05:59:39.606+0000] {task_command.py:388} INFO - Running <TaskInstance: twitter_dag.complete_twitter_etl scheduled__2020-11-12T00:00:00+00:00 [running]> on host 864c120ca3c2
[2023-01-26T05:59:40.839+0000] {taskinstance.py:1509} INFO - Exporting the following env vars:
AIRFLOW_CTX_DAG_EMAIL=***@example.com
AIRFLOW_CTX_DAG_OWNER=***
AIRFLOW_CTX_DAG_ID=twitter_dag
AIRFLOW_CTX_TASK_ID=complete_twitter_etl
AIRFLOW_CTX_EXECUTION_DATE=2020-11-12T00:00:00+00:00
AIRFLOW_CTX_TRY_NUMBER=1
AIRFLOW_CTX_DAG_RUN_ID=scheduled__2020-11-12T00:00:00+00:00
[2023-01-26T05:59:41.698+0000] {taskinstance.py:1768} ERROR - Task failed with exception
Traceback (most recent call last):
  File "/home/airflow/.local/lib/python3.7/site-packages/airflow/operators/python.py", line 175, in execute
    return_value = self.execute_callable()
  File "/home/airflow/.local/lib/python3.7/site-packages/airflow/operators/python.py", line 192, in execute_callable
    return self.python_callable(*self.op_args, **self.op_kwargs)
  File "/opt/airflow/dags/twitter_etl.py", line 51, in run_twitter_etl
    aws_access_key_id=os.environ['AWS_ACCESS_KEY_ID'],
  File "/usr/local/lib/python3.7/os.py", line 681, in __getitem__
    raise KeyError(key) from None
KeyError: 'AWS_ACCESS_KEY_ID'
[2023-01-26T05:59:41.745+0000] {taskinstance.py:1323} INFO - Marking task as UP_FOR_RETRY. dag_id=twitter_dag, task_id=complete_twitter_etl, execution_date=20201112T000000, start_date=20230126T055922, end_date=20230126T055941
[2023-01-26T05:59:41.834+0000] {standard_task_runner.py:105} ERROR - Failed to execute job 9 for task complete_twitter_etl ('AWS_ACCESS_KEY_ID'; 941)
[2023-01-26T05:59:42.512+0000] {local_task_job.py:208} INFO - Task exited with return code 1
[2023-01-26T05:59:43.997+0000] {taskinstance.py:2578} INFO - 0 downstream tasks scheduled from follow-on schedule check
[2023-01-26T06:59:30.965+0000] {taskinstance.py:1083} INFO - Dependencies all met for <TaskInstance: twitter_dag.complete_twitter_etl scheduled__2020-11-12T00:00:00+00:00 [queued]>
[2023-01-26T06:59:31.052+0000] {taskinstance.py:1083} INFO - Dependencies all met for <TaskInstance: twitter_dag.complete_twitter_etl scheduled__2020-11-12T00:00:00+00:00 [queued]>
[2023-01-26T06:59:31.060+0000] {taskinstance.py:1279} INFO - 
--------------------------------------------------------------------------------
[2023-01-26T06:59:31.064+0000] {taskinstance.py:1280} INFO - Starting attempt 1 of 2
[2023-01-26T06:59:31.065+0000] {taskinstance.py:1281} INFO - 
--------------------------------------------------------------------------------
[2023-01-26T06:59:31.271+0000] {taskinstance.py:1300} INFO - Executing <Task(PythonOperator): complete_twitter_etl> on 2020-11-12 00:00:00+00:00
[2023-01-26T06:59:31.353+0000] {standard_task_runner.py:55} INFO - Started process 128 to run task
[2023-01-26T06:59:31.401+0000] {standard_task_runner.py:82} INFO - Running: ['***', 'tasks', 'run', 'twitter_dag', 'complete_twitter_etl', 'scheduled__2020-11-12T00:00:00+00:00', '--job-id', '4', '--raw', '--subdir', 'DAGS_FOLDER/twitter_dag.py', '--cfg-path', '/tmp/tmpin1da9cr']
[2023-01-26T06:59:31.416+0000] {standard_task_runner.py:83} INFO - Job 4: Subtask complete_twitter_etl
[2023-01-26T06:59:33.514+0000] {task_command.py:388} INFO - Running <TaskInstance: twitter_dag.complete_twitter_etl scheduled__2020-11-12T00:00:00+00:00 [running]> on host 2221c1ebf970
[2023-01-26T06:59:34.981+0000] {taskinstance.py:1509} INFO - Exporting the following env vars:
AIRFLOW_CTX_DAG_EMAIL=***@example.com
AIRFLOW_CTX_DAG_OWNER=***
AIRFLOW_CTX_DAG_ID=twitter_dag
AIRFLOW_CTX_TASK_ID=complete_twitter_etl
AIRFLOW_CTX_EXECUTION_DATE=2020-11-12T00:00:00+00:00
AIRFLOW_CTX_TRY_NUMBER=1
AIRFLOW_CTX_DAG_RUN_ID=scheduled__2020-11-12T00:00:00+00:00
[2023-01-26T06:59:37.840+0000] {taskinstance.py:1768} ERROR - Task failed with exception
Traceback (most recent call last):
  File "/home/airflow/.local/lib/python3.7/site-packages/airflow/operators/python.py", line 175, in execute
    return_value = self.execute_callable()
  File "/home/airflow/.local/lib/python3.7/site-packages/airflow/operators/python.py", line 192, in execute_callable
    return self.python_callable(*self.op_args, **self.op_kwargs)
  File "/opt/airflow/dags/twitter_etl.py", line 63, in run_twitter_etl
    s3.Object(BUCKET_NAME, KEY).put(Body=csv_buffer.getvalue())
  File "/home/airflow/.local/lib/python3.7/site-packages/botocore/client.py", line 839, in __getattr__
    f"'{self.__class__.__name__}' object has no attribute '{item}'"
AttributeError: 'S3' object has no attribute 'Object'
[2023-01-26T06:59:37.907+0000] {taskinstance.py:1323} INFO - Marking task as UP_FOR_RETRY. dag_id=twitter_dag, task_id=complete_twitter_etl, execution_date=20201112T000000, start_date=20230126T065930, end_date=20230126T065937
[2023-01-26T06:59:38.055+0000] {standard_task_runner.py:105} ERROR - Failed to execute job 4 for task complete_twitter_etl ('S3' object has no attribute 'Object'; 128)
[2023-01-26T06:59:39.183+0000] {local_task_job.py:208} INFO - Task exited with return code 1
[2023-01-26T06:59:39.330+0000] {taskinstance.py:2578} INFO - 0 downstream tasks scheduled from follow-on schedule check
[2023-01-26T08:02:05.685+0000] {taskinstance.py:1083} INFO - Dependencies all met for <TaskInstance: twitter_dag.complete_twitter_etl scheduled__2020-11-12T00:00:00+00:00 [queued]>
[2023-01-26T08:02:06.026+0000] {taskinstance.py:1083} INFO - Dependencies all met for <TaskInstance: twitter_dag.complete_twitter_etl scheduled__2020-11-12T00:00:00+00:00 [queued]>
[2023-01-26T08:02:06.052+0000] {taskinstance.py:1279} INFO - 
--------------------------------------------------------------------------------
[2023-01-26T08:02:06.055+0000] {taskinstance.py:1280} INFO - Starting attempt 1 of 2
[2023-01-26T08:02:06.057+0000] {taskinstance.py:1281} INFO - 
--------------------------------------------------------------------------------
[2023-01-26T08:02:06.273+0000] {taskinstance.py:1300} INFO - Executing <Task(PythonOperator): complete_twitter_etl> on 2020-11-12 00:00:00+00:00
[2023-01-26T08:02:06.344+0000] {standard_task_runner.py:55} INFO - Started process 436 to run task
[2023-01-26T08:02:06.377+0000] {standard_task_runner.py:82} INFO - Running: ['***', 'tasks', 'run', 'twitter_dag', 'complete_twitter_etl', 'scheduled__2020-11-12T00:00:00+00:00', '--job-id', '6', '--raw', '--subdir', 'DAGS_FOLDER/twitter_dag.py', '--cfg-path', '/tmp/tmpkqcechp_']
[2023-01-26T08:02:06.394+0000] {standard_task_runner.py:83} INFO - Job 6: Subtask complete_twitter_etl
[2023-01-26T08:02:08.813+0000] {task_command.py:388} INFO - Running <TaskInstance: twitter_dag.complete_twitter_etl scheduled__2020-11-12T00:00:00+00:00 [running]> on host 3143b9e5b257
[2023-01-26T08:02:09.591+0000] {taskinstance.py:1509} INFO - Exporting the following env vars:
AIRFLOW_CTX_DAG_EMAIL=***@example.com
AIRFLOW_CTX_DAG_OWNER=***
AIRFLOW_CTX_DAG_ID=twitter_dag
AIRFLOW_CTX_TASK_ID=complete_twitter_etl
AIRFLOW_CTX_EXECUTION_DATE=2020-11-12T00:00:00+00:00
AIRFLOW_CTX_TRY_NUMBER=1
AIRFLOW_CTX_DAG_RUN_ID=scheduled__2020-11-12T00:00:00+00:00
[2023-01-26T08:02:20.759+0000] {taskinstance.py:1768} ERROR - Task failed with exception
Traceback (most recent call last):
  File "/home/airflow/.local/lib/python3.7/site-packages/airflow/operators/python.py", line 175, in execute
    return_value = self.execute_callable()
  File "/home/airflow/.local/lib/python3.7/site-packages/airflow/operators/python.py", line 192, in execute_callable
    return self.python_callable(*self.op_args, **self.op_kwargs)
  File "/opt/airflow/dags/twitter_etl.py", line 64, in run_twitter_etl
    s3.Object(BUCKET_NAME, KEY).put(Body=csv_buffer.getvalue())
  File "/home/airflow/.local/lib/python3.7/site-packages/boto3/resources/factory.py", line 580, in do_action
    response = action(self, *args, **kwargs)
  File "/home/airflow/.local/lib/python3.7/site-packages/boto3/resources/action.py", line 88, in __call__
    response = getattr(parent.meta.client, operation_name)(*args, **params)
  File "/home/airflow/.local/lib/python3.7/site-packages/botocore/client.py", line 508, in _api_call
    return self._make_api_call(operation_name, kwargs)
  File "/home/airflow/.local/lib/python3.7/site-packages/botocore/client.py", line 915, in _make_api_call
    raise error_class(parsed_response, operation_name)
botocore.exceptions.ClientError: An error occurred (InvalidAccessKeyId) when calling the PutObject operation: The AWS Access Key Id you provided does not exist in our records.
[2023-01-26T08:02:20.918+0000] {taskinstance.py:1323} INFO - Marking task as UP_FOR_RETRY. dag_id=twitter_dag, task_id=complete_twitter_etl, execution_date=20201112T000000, start_date=20230126T080205, end_date=20230126T080220
[2023-01-26T08:02:21.895+0000] {standard_task_runner.py:105} ERROR - Failed to execute job 6 for task complete_twitter_etl (An error occurred (InvalidAccessKeyId) when calling the PutObject operation: The AWS Access Key Id you provided does not exist in our records.; 436)
[2023-01-26T08:02:23.481+0000] {local_task_job.py:208} INFO - Task exited with return code 1
[2023-01-26T08:02:27.425+0000] {taskinstance.py:2578} INFO - 0 downstream tasks scheduled from follow-on schedule check
[2023-01-26T09:07:33.750+0000] {taskinstance.py:1083} INFO - Dependencies all met for <TaskInstance: twitter_dag.complete_twitter_etl scheduled__2020-11-12T00:00:00+00:00 [queued]>
[2023-01-26T09:07:34.082+0000] {taskinstance.py:1083} INFO - Dependencies all met for <TaskInstance: twitter_dag.complete_twitter_etl scheduled__2020-11-12T00:00:00+00:00 [queued]>
[2023-01-26T09:07:34.084+0000] {taskinstance.py:1279} INFO - 
--------------------------------------------------------------------------------
[2023-01-26T09:07:34.102+0000] {taskinstance.py:1280} INFO - Starting attempt 1 of 2
[2023-01-26T09:07:34.109+0000] {taskinstance.py:1281} INFO - 
--------------------------------------------------------------------------------
[2023-01-26T09:07:34.423+0000] {taskinstance.py:1300} INFO - Executing <Task(PythonOperator): complete_twitter_etl> on 2020-11-12 00:00:00+00:00
[2023-01-26T09:07:34.540+0000] {standard_task_runner.py:82} INFO - Running: ['***', 'tasks', 'run', 'twitter_dag', 'complete_twitter_etl', 'scheduled__2020-11-12T00:00:00+00:00', '--job-id', '9', '--raw', '--subdir', 'DAGS_FOLDER/twitter_dag.py', '--cfg-path', '/tmp/tmp8f2y_wmb']
[2023-01-26T09:07:34.562+0000] {standard_task_runner.py:83} INFO - Job 9: Subtask complete_twitter_etl
[2023-01-26T09:07:34.495+0000] {standard_task_runner.py:55} INFO - Started process 134 to run task
[2023-01-26T09:07:39.964+0000] {task_command.py:388} INFO - Running <TaskInstance: twitter_dag.complete_twitter_etl scheduled__2020-11-12T00:00:00+00:00 [running]> on host d0fc3b00c15c
[2023-01-26T09:07:41.282+0000] {taskinstance.py:1509} INFO - Exporting the following env vars:
AIRFLOW_CTX_DAG_EMAIL=***@example.com
AIRFLOW_CTX_DAG_OWNER=***
AIRFLOW_CTX_DAG_ID=twitter_dag
AIRFLOW_CTX_TASK_ID=complete_twitter_etl
AIRFLOW_CTX_EXECUTION_DATE=2020-11-12T00:00:00+00:00
AIRFLOW_CTX_TRY_NUMBER=1
AIRFLOW_CTX_DAG_RUN_ID=scheduled__2020-11-12T00:00:00+00:00
[2023-01-26T09:08:02.214+0000] {python.py:177} INFO - Done. Returned value was: None
[2023-01-26T09:08:02.786+0000] {taskinstance.py:1323} INFO - Marking task as SUCCESS. dag_id=twitter_dag, task_id=complete_twitter_etl, execution_date=20201112T000000, start_date=20230126T090733, end_date=20230126T090802
[2023-01-26T09:08:07.919+0000] {local_task_job.py:208} INFO - Task exited with return code 0
[2023-01-26T09:08:14.754+0000] {taskinstance.py:2578} INFO - 0 downstream tasks scheduled from follow-on schedule check
