[2023-01-25T18:44:10.815+0000] {taskinstance.py:1083} INFO - Dependencies all met for <TaskInstance: twitter_dag.complete_twitter_etl scheduled__2020-12-08T00:00:00+00:00 [queued]>
[2023-01-25T18:44:10.917+0000] {taskinstance.py:1083} INFO - Dependencies all met for <TaskInstance: twitter_dag.complete_twitter_etl scheduled__2020-12-08T00:00:00+00:00 [queued]>
[2023-01-25T18:44:10.920+0000] {taskinstance.py:1279} INFO - 
--------------------------------------------------------------------------------
[2023-01-25T18:44:10.926+0000] {taskinstance.py:1280} INFO - Starting attempt 1 of 2
[2023-01-25T18:44:10.930+0000] {taskinstance.py:1281} INFO - 
--------------------------------------------------------------------------------
[2023-01-25T18:44:11.298+0000] {taskinstance.py:1300} INFO - Executing <Task(PythonOperator): complete_twitter_etl> on 2020-12-08 00:00:00+00:00
[2023-01-25T18:44:11.714+0000] {standard_task_runner.py:55} INFO - Started process 663 to run task
[2023-01-25T18:44:12.007+0000] {standard_task_runner.py:82} INFO - Running: ['***', 'tasks', 'run', 'twitter_dag', 'complete_twitter_etl', 'scheduled__2020-12-08T00:00:00+00:00', '--job-id', '47', '--raw', '--subdir', 'DAGS_FOLDER/twitter_dag.py', '--cfg-path', '/tmp/tmp49zf2xcg']
[2023-01-25T18:44:12.080+0000] {standard_task_runner.py:83} INFO - Job 47: Subtask complete_twitter_etl
[2023-01-25T18:44:15.318+0000] {task_command.py:388} INFO - Running <TaskInstance: twitter_dag.complete_twitter_etl scheduled__2020-12-08T00:00:00+00:00 [running]> on host 512d0ff0785b
[2023-01-25T18:44:22.057+0000] {taskinstance.py:1509} INFO - Exporting the following env vars:
AIRFLOW_CTX_DAG_EMAIL=***@example.com
AIRFLOW_CTX_DAG_OWNER=***
AIRFLOW_CTX_DAG_ID=twitter_dag
AIRFLOW_CTX_TASK_ID=complete_twitter_etl
AIRFLOW_CTX_EXECUTION_DATE=2020-12-08T00:00:00+00:00
AIRFLOW_CTX_TRY_NUMBER=1
AIRFLOW_CTX_DAG_RUN_ID=scheduled__2020-12-08T00:00:00+00:00
[2023-01-25T18:44:36.183+0000] {taskinstance.py:1768} ERROR - Task failed with exception
Traceback (most recent call last):
  File "/home/airflow/.local/lib/python3.7/site-packages/s3fs/core.py", line 112, in _error_wrapper
    return await func(*args, **kwargs)
  File "/home/airflow/.local/lib/python3.7/site-packages/aiobotocore/client.py", line 358, in _make_api_call
    raise error_class(parsed_response, operation_name)
botocore.exceptions.ClientError: An error occurred (AccessDenied) when calling the CreateBucket operation: Anonymous access is forbidden for this operation

The above exception was the direct cause of the following exception:

Traceback (most recent call last):
  File "/home/airflow/.local/lib/python3.7/site-packages/airflow/operators/python.py", line 175, in execute
    return_value = self.execute_callable()
  File "/home/airflow/.local/lib/python3.7/site-packages/airflow/operators/python.py", line 192, in execute_callable
    return self.python_callable(*self.op_args, **self.op_kwargs)
  File "/opt/airflow/dags/twitter_etl.py", line 46, in run_twitter_etl
    df.to_csv("s3://jinchoi-airflow-bucket/data/elonmusk_tweets.csv")
  File "/home/airflow/.local/lib/python3.7/site-packages/pandas/core/generic.py", line 3482, in to_csv
    storage_options=storage_options,
  File "/home/airflow/.local/lib/python3.7/site-packages/pandas/io/formats/format.py", line 1105, in to_csv
    csv_formatter.save()
  File "/home/airflow/.local/lib/python3.7/site-packages/pandas/io/formats/csvs.py", line 243, in save
    storage_options=self.storage_options,
  File "/home/airflow/.local/lib/python3.7/site-packages/pandas/io/common.py", line 614, in get_handle
    storage_options=storage_options,
  File "/home/airflow/.local/lib/python3.7/site-packages/pandas/io/common.py", line 370, in _get_filepath_or_buffer
    filepath_or_buffer, mode=fsspec_mode, **(storage_options or {})
  File "/home/airflow/.local/lib/python3.7/site-packages/fsspec/core.py", line 428, in open
    **kwargs,
  File "/home/airflow/.local/lib/python3.7/site-packages/fsspec/core.py", line 283, in open_files
    [fs.makedirs(parent, exist_ok=True) for parent in parents]
  File "/home/airflow/.local/lib/python3.7/site-packages/fsspec/core.py", line 283, in <listcomp>
    [fs.makedirs(parent, exist_ok=True) for parent in parents]
  File "/home/airflow/.local/lib/python3.7/site-packages/fsspec/asyn.py", line 114, in wrapper
    return sync(self.loop, func, *args, **kwargs)
  File "/home/airflow/.local/lib/python3.7/site-packages/fsspec/asyn.py", line 99, in sync
    raise return_result
  File "/home/airflow/.local/lib/python3.7/site-packages/fsspec/asyn.py", line 54, in _runner
    result[0] = await coro
  File "/home/airflow/.local/lib/python3.7/site-packages/s3fs/core.py", line 883, in _makedirs
    await self._mkdir(path, create_parents=True)
  File "/home/airflow/.local/lib/python3.7/site-packages/s3fs/core.py", line 868, in _mkdir
    await self._call_s3("create_bucket", **params)
  File "/home/airflow/.local/lib/python3.7/site-packages/s3fs/core.py", line 340, in _call_s3
    method, kwargs=additional_kwargs, retries=self.retries
  File "/home/airflow/.local/lib/python3.7/site-packages/s3fs/core.py", line 139, in _error_wrapper
    raise err
PermissionError: Anonymous access is forbidden for this operation
[2023-01-25T18:44:36.306+0000] {taskinstance.py:1323} INFO - Marking task as UP_FOR_RETRY. dag_id=twitter_dag, task_id=complete_twitter_etl, execution_date=20201208T000000, start_date=20230125T184410, end_date=20230125T184436
[2023-01-25T18:44:36.691+0000] {standard_task_runner.py:105} ERROR - Failed to execute job 47 for task complete_twitter_etl (Anonymous access is forbidden for this operation; 663)
[2023-01-25T18:44:36.816+0000] {local_task_job.py:208} INFO - Task exited with return code 1
[2023-01-25T18:44:37.037+0000] {taskinstance.py:2578} INFO - 0 downstream tasks scheduled from follow-on schedule check
[2023-01-26T03:24:21.312+0000] {taskinstance.py:1083} INFO - Dependencies all met for <TaskInstance: twitter_dag.complete_twitter_etl scheduled__2020-12-08T00:00:00+00:00 [queued]>
[2023-01-26T03:24:21.444+0000] {taskinstance.py:1083} INFO - Dependencies all met for <TaskInstance: twitter_dag.complete_twitter_etl scheduled__2020-12-08T00:00:00+00:00 [queued]>
[2023-01-26T03:24:21.453+0000] {taskinstance.py:1279} INFO - 
--------------------------------------------------------------------------------
[2023-01-26T03:24:21.457+0000] {taskinstance.py:1280} INFO - Starting attempt 1 of 2
[2023-01-26T03:24:21.462+0000] {taskinstance.py:1281} INFO - 
--------------------------------------------------------------------------------
[2023-01-26T03:24:21.577+0000] {taskinstance.py:1300} INFO - Executing <Task(PythonOperator): complete_twitter_etl> on 2020-12-08 00:00:00+00:00
[2023-01-26T03:24:21.612+0000] {standard_task_runner.py:55} INFO - Started process 366 to run task
[2023-01-26T03:24:21.692+0000] {standard_task_runner.py:82} INFO - Running: ['***', 'tasks', 'run', 'twitter_dag', 'complete_twitter_etl', 'scheduled__2020-12-08T00:00:00+00:00', '--job-id', '49', '--raw', '--subdir', 'DAGS_FOLDER/twitter_dag.py', '--cfg-path', '/tmp/tmpgunoj7x0']
[2023-01-26T03:24:21.712+0000] {standard_task_runner.py:83} INFO - Job 49: Subtask complete_twitter_etl
[2023-01-26T03:24:22.165+0000] {task_command.py:388} INFO - Running <TaskInstance: twitter_dag.complete_twitter_etl scheduled__2020-12-08T00:00:00+00:00 [running]> on host 3db080823b1b
[2023-01-26T03:24:23.744+0000] {taskinstance.py:1509} INFO - Exporting the following env vars:
AIRFLOW_CTX_DAG_EMAIL=***@example.com
AIRFLOW_CTX_DAG_OWNER=***
AIRFLOW_CTX_DAG_ID=twitter_dag
AIRFLOW_CTX_TASK_ID=complete_twitter_etl
AIRFLOW_CTX_EXECUTION_DATE=2020-12-08T00:00:00+00:00
AIRFLOW_CTX_TRY_NUMBER=1
AIRFLOW_CTX_DAG_RUN_ID=scheduled__2020-12-08T00:00:00+00:00
[2023-01-26T03:24:25.742+0000] {taskinstance.py:1768} ERROR - Task failed with exception
Traceback (most recent call last):
  File "/home/airflow/.local/lib/python3.7/site-packages/airflow/operators/python.py", line 175, in execute
    return_value = self.execute_callable()
  File "/home/airflow/.local/lib/python3.7/site-packages/airflow/operators/python.py", line 192, in execute_callable
    return self.python_callable(*self.op_args, **self.op_kwargs)
  File "/opt/airflow/dags/twitter_etl.py", line 53, in run_twitter_etl
    df.to_csv('s3://{BUCKET_NAME}/data/{KEY}', index=False, header=False,sep=',', engine='python', filesystem=s3)
TypeError: to_csv() got an unexpected keyword argument 'engine'
[2023-01-26T03:24:25.779+0000] {taskinstance.py:1323} INFO - Marking task as UP_FOR_RETRY. dag_id=twitter_dag, task_id=complete_twitter_etl, execution_date=20201208T000000, start_date=20230126T032421, end_date=20230126T032425
[2023-01-26T03:24:25.826+0000] {standard_task_runner.py:105} ERROR - Failed to execute job 49 for task complete_twitter_etl (to_csv() got an unexpected keyword argument 'engine'; 366)
[2023-01-26T03:24:25.883+0000] {local_task_job.py:208} INFO - Task exited with return code 1
[2023-01-26T03:24:25.976+0000] {taskinstance.py:2578} INFO - 0 downstream tasks scheduled from follow-on schedule check
[2023-01-26T03:35:43.407+0000] {taskinstance.py:1083} INFO - Dependencies all met for <TaskInstance: twitter_dag.complete_twitter_etl scheduled__2020-12-08T00:00:00+00:00 [queued]>
[2023-01-26T03:35:43.510+0000] {taskinstance.py:1083} INFO - Dependencies all met for <TaskInstance: twitter_dag.complete_twitter_etl scheduled__2020-12-08T00:00:00+00:00 [queued]>
[2023-01-26T03:35:43.513+0000] {taskinstance.py:1279} INFO - 
--------------------------------------------------------------------------------
[2023-01-26T03:35:43.516+0000] {taskinstance.py:1280} INFO - Starting attempt 1 of 2
[2023-01-26T03:35:43.520+0000] {taskinstance.py:1281} INFO - 
--------------------------------------------------------------------------------
[2023-01-26T03:35:43.661+0000] {taskinstance.py:1300} INFO - Executing <Task(PythonOperator): complete_twitter_etl> on 2020-12-08 00:00:00+00:00
[2023-01-26T03:35:43.734+0000] {standard_task_runner.py:55} INFO - Started process 364 to run task
[2023-01-26T03:35:43.784+0000] {standard_task_runner.py:82} INFO - Running: ['***', 'tasks', 'run', 'twitter_dag', 'complete_twitter_etl', 'scheduled__2020-12-08T00:00:00+00:00', '--job-id', '49', '--raw', '--subdir', 'DAGS_FOLDER/twitter_dag.py', '--cfg-path', '/tmp/tmplyn0hyvg']
[2023-01-26T03:35:43.788+0000] {standard_task_runner.py:83} INFO - Job 49: Subtask complete_twitter_etl
[2023-01-26T03:35:44.289+0000] {task_command.py:388} INFO - Running <TaskInstance: twitter_dag.complete_twitter_etl scheduled__2020-12-08T00:00:00+00:00 [running]> on host 9c4f31e2db2b
[2023-01-26T03:35:45.237+0000] {taskinstance.py:1509} INFO - Exporting the following env vars:
AIRFLOW_CTX_DAG_EMAIL=***@example.com
AIRFLOW_CTX_DAG_OWNER=***
AIRFLOW_CTX_DAG_ID=twitter_dag
AIRFLOW_CTX_TASK_ID=complete_twitter_etl
AIRFLOW_CTX_EXECUTION_DATE=2020-12-08T00:00:00+00:00
AIRFLOW_CTX_TRY_NUMBER=1
AIRFLOW_CTX_DAG_RUN_ID=scheduled__2020-12-08T00:00:00+00:00
[2023-01-26T03:35:46.499+0000] {taskinstance.py:1768} ERROR - Task failed with exception
Traceback (most recent call last):
  File "/home/airflow/.local/lib/python3.7/site-packages/airflow/operators/python.py", line 175, in execute
    return_value = self.execute_callable()
  File "/home/airflow/.local/lib/python3.7/site-packages/airflow/operators/python.py", line 192, in execute_callable
    return self.python_callable(*self.op_args, **self.op_kwargs)
  File "/opt/airflow/dags/twitter_etl.py", line 54, in run_twitter_etl
    s3.put('s3://{BUCKET_NAME}/data/{KEY}', csv_buffer)
  File "/home/airflow/.local/lib/python3.7/site-packages/fsspec/asyn.py", line 114, in wrapper
    return sync(self.loop, func, *args, **kwargs)
  File "/home/airflow/.local/lib/python3.7/site-packages/fsspec/asyn.py", line 99, in sync
    raise return_result
  File "/home/airflow/.local/lib/python3.7/site-packages/fsspec/asyn.py", line 54, in _runner
    result[0] = await coro
  File "/home/airflow/.local/lib/python3.7/site-packages/fsspec/asyn.py", line 481, in _put
    rpath = self._strip_protocol(rpath)
  File "/home/airflow/.local/lib/python3.7/site-packages/fsspec/spec.py", line 188, in _strip_protocol
    if path.startswith(protocol + "://"):
TypeError: startswith first arg must be bytes or a tuple of bytes, not str
[2023-01-26T03:35:46.516+0000] {taskinstance.py:1323} INFO - Marking task as UP_FOR_RETRY. dag_id=twitter_dag, task_id=complete_twitter_etl, execution_date=20201208T000000, start_date=20230126T033543, end_date=20230126T033546
[2023-01-26T03:35:46.538+0000] {standard_task_runner.py:105} ERROR - Failed to execute job 49 for task complete_twitter_etl (startswith first arg must be bytes or a tuple of bytes, not str; 364)
[2023-01-26T03:35:46.606+0000] {local_task_job.py:208} INFO - Task exited with return code 1
[2023-01-26T03:35:46.653+0000] {taskinstance.py:2578} INFO - 0 downstream tasks scheduled from follow-on schedule check
[2023-01-26T06:05:14.449+0000] {taskinstance.py:1083} INFO - Dependencies all met for <TaskInstance: twitter_dag.complete_twitter_etl scheduled__2020-12-08T00:00:00+00:00 [queued]>
[2023-01-26T06:05:14.552+0000] {taskinstance.py:1083} INFO - Dependencies all met for <TaskInstance: twitter_dag.complete_twitter_etl scheduled__2020-12-08T00:00:00+00:00 [queued]>
[2023-01-26T06:05:14.554+0000] {taskinstance.py:1279} INFO - 
--------------------------------------------------------------------------------
[2023-01-26T06:05:14.562+0000] {taskinstance.py:1280} INFO - Starting attempt 1 of 2
[2023-01-26T06:05:14.568+0000] {taskinstance.py:1281} INFO - 
--------------------------------------------------------------------------------
[2023-01-26T06:05:14.643+0000] {taskinstance.py:1300} INFO - Executing <Task(PythonOperator): complete_twitter_etl> on 2020-12-08 00:00:00+00:00
[2023-01-26T06:05:14.688+0000] {standard_task_runner.py:55} INFO - Started process 1218 to run task
[2023-01-26T06:05:14.710+0000] {standard_task_runner.py:82} INFO - Running: ['***', 'tasks', 'run', 'twitter_dag', 'complete_twitter_etl', 'scheduled__2020-12-08T00:00:00+00:00', '--job-id', '49', '--raw', '--subdir', 'DAGS_FOLDER/twitter_dag.py', '--cfg-path', '/tmp/tmp9rq6mg4w']
[2023-01-26T06:05:14.713+0000] {standard_task_runner.py:83} INFO - Job 49: Subtask complete_twitter_etl
[2023-01-26T06:05:15.418+0000] {task_command.py:388} INFO - Running <TaskInstance: twitter_dag.complete_twitter_etl scheduled__2020-12-08T00:00:00+00:00 [running]> on host 864c120ca3c2
[2023-01-26T06:05:15.509+0000] {taskinstance.py:1509} INFO - Exporting the following env vars:
AIRFLOW_CTX_DAG_EMAIL=***@example.com
AIRFLOW_CTX_DAG_OWNER=***
AIRFLOW_CTX_DAG_ID=twitter_dag
AIRFLOW_CTX_TASK_ID=complete_twitter_etl
AIRFLOW_CTX_EXECUTION_DATE=2020-12-08T00:00:00+00:00
AIRFLOW_CTX_TRY_NUMBER=1
AIRFLOW_CTX_DAG_RUN_ID=scheduled__2020-12-08T00:00:00+00:00
[2023-01-26T06:05:16.051+0000] {taskinstance.py:1768} ERROR - Task failed with exception
Traceback (most recent call last):
  File "/home/airflow/.local/lib/python3.7/site-packages/airflow/operators/python.py", line 175, in execute
    return_value = self.execute_callable()
  File "/home/airflow/.local/lib/python3.7/site-packages/airflow/operators/python.py", line 192, in execute_callable
    return self.python_callable(*self.op_args, **self.op_kwargs)
  File "/opt/airflow/dags/twitter_etl.py", line 51, in run_twitter_etl
    aws_access_key_id=os.environ['AWS_ACCESS_KEY_ID'],
  File "/usr/local/lib/python3.7/os.py", line 681, in __getitem__
    raise KeyError(key) from None
KeyError: 'AWS_ACCESS_KEY_ID'
[2023-01-26T06:05:16.067+0000] {taskinstance.py:1323} INFO - Marking task as UP_FOR_RETRY. dag_id=twitter_dag, task_id=complete_twitter_etl, execution_date=20201208T000000, start_date=20230126T060514, end_date=20230126T060516
[2023-01-26T06:05:16.087+0000] {standard_task_runner.py:105} ERROR - Failed to execute job 49 for task complete_twitter_etl ('AWS_ACCESS_KEY_ID'; 1218)
[2023-01-26T06:05:16.139+0000] {local_task_job.py:208} INFO - Task exited with return code 1
[2023-01-26T06:05:16.167+0000] {taskinstance.py:2578} INFO - 0 downstream tasks scheduled from follow-on schedule check
[2023-01-26T07:05:11.691+0000] {taskinstance.py:1083} INFO - Dependencies all met for <TaskInstance: twitter_dag.complete_twitter_etl scheduled__2020-12-08T00:00:00+00:00 [queued]>
[2023-01-26T07:05:11.767+0000] {taskinstance.py:1083} INFO - Dependencies all met for <TaskInstance: twitter_dag.complete_twitter_etl scheduled__2020-12-08T00:00:00+00:00 [queued]>
[2023-01-26T07:05:11.770+0000] {taskinstance.py:1279} INFO - 
--------------------------------------------------------------------------------
[2023-01-26T07:05:11.782+0000] {taskinstance.py:1280} INFO - Starting attempt 1 of 2
[2023-01-26T07:05:11.783+0000] {taskinstance.py:1281} INFO - 
--------------------------------------------------------------------------------
[2023-01-26T07:05:11.844+0000] {taskinstance.py:1300} INFO - Executing <Task(PythonOperator): complete_twitter_etl> on 2020-12-08 00:00:00+00:00
[2023-01-26T07:05:11.854+0000] {standard_task_runner.py:55} INFO - Started process 540 to run task
[2023-01-26T07:05:11.866+0000] {standard_task_runner.py:82} INFO - Running: ['***', 'tasks', 'run', 'twitter_dag', 'complete_twitter_etl', 'scheduled__2020-12-08T00:00:00+00:00', '--job-id', '48', '--raw', '--subdir', 'DAGS_FOLDER/twitter_dag.py', '--cfg-path', '/tmp/tmpaqtfdcjv']
[2023-01-26T07:05:11.877+0000] {standard_task_runner.py:83} INFO - Job 48: Subtask complete_twitter_etl
[2023-01-26T07:05:12.732+0000] {task_command.py:388} INFO - Running <TaskInstance: twitter_dag.complete_twitter_etl scheduled__2020-12-08T00:00:00+00:00 [running]> on host 2221c1ebf970
[2023-01-26T07:05:12.997+0000] {taskinstance.py:1509} INFO - Exporting the following env vars:
AIRFLOW_CTX_DAG_EMAIL=***@example.com
AIRFLOW_CTX_DAG_OWNER=***
AIRFLOW_CTX_DAG_ID=twitter_dag
AIRFLOW_CTX_TASK_ID=complete_twitter_etl
AIRFLOW_CTX_EXECUTION_DATE=2020-12-08T00:00:00+00:00
AIRFLOW_CTX_TRY_NUMBER=1
AIRFLOW_CTX_DAG_RUN_ID=scheduled__2020-12-08T00:00:00+00:00
[2023-01-26T07:05:13.872+0000] {taskinstance.py:1768} ERROR - Task failed with exception
Traceback (most recent call last):
  File "/home/airflow/.local/lib/python3.7/site-packages/airflow/operators/python.py", line 175, in execute
    return_value = self.execute_callable()
  File "/home/airflow/.local/lib/python3.7/site-packages/airflow/operators/python.py", line 192, in execute_callable
    return self.python_callable(*self.op_args, **self.op_kwargs)
  File "/opt/airflow/dags/twitter_etl.py", line 63, in run_twitter_etl
    s3.Object(BUCKET_NAME, KEY).put(Body=csv_buffer.getvalue())
  File "/home/airflow/.local/lib/python3.7/site-packages/botocore/client.py", line 839, in __getattr__
    f"'{self.__class__.__name__}' object has no attribute '{item}'"
AttributeError: 'S3' object has no attribute 'Object'
[2023-01-26T07:05:13.908+0000] {taskinstance.py:1323} INFO - Marking task as UP_FOR_RETRY. dag_id=twitter_dag, task_id=complete_twitter_etl, execution_date=20201208T000000, start_date=20230126T070511, end_date=20230126T070513
[2023-01-26T07:05:13.966+0000] {standard_task_runner.py:105} ERROR - Failed to execute job 48 for task complete_twitter_etl ('S3' object has no attribute 'Object'; 540)
[2023-01-26T07:05:14.078+0000] {local_task_job.py:208} INFO - Task exited with return code 1
[2023-01-26T07:05:14.127+0000] {taskinstance.py:2578} INFO - 0 downstream tasks scheduled from follow-on schedule check
[2023-01-26T08:13:07.326+0000] {taskinstance.py:1083} INFO - Dependencies all met for <TaskInstance: twitter_dag.complete_twitter_etl scheduled__2020-12-08T00:00:00+00:00 [queued]>
[2023-01-26T08:13:07.430+0000] {taskinstance.py:1083} INFO - Dependencies all met for <TaskInstance: twitter_dag.complete_twitter_etl scheduled__2020-12-08T00:00:00+00:00 [queued]>
[2023-01-26T08:13:07.434+0000] {taskinstance.py:1279} INFO - 
--------------------------------------------------------------------------------
[2023-01-26T08:13:07.437+0000] {taskinstance.py:1280} INFO - Starting attempt 1 of 2
[2023-01-26T08:13:07.441+0000] {taskinstance.py:1281} INFO - 
--------------------------------------------------------------------------------
[2023-01-26T08:13:07.519+0000] {taskinstance.py:1300} INFO - Executing <Task(PythonOperator): complete_twitter_etl> on 2020-12-08 00:00:00+00:00
[2023-01-26T08:13:07.533+0000] {standard_task_runner.py:55} INFO - Started process 1143 to run task
[2023-01-26T08:13:07.557+0000] {standard_task_runner.py:82} INFO - Running: ['***', 'tasks', 'run', 'twitter_dag', 'complete_twitter_etl', 'scheduled__2020-12-08T00:00:00+00:00', '--job-id', '61', '--raw', '--subdir', 'DAGS_FOLDER/twitter_dag.py', '--cfg-path', '/tmp/tmpwe6wn1j9']
[2023-01-26T08:13:07.559+0000] {standard_task_runner.py:83} INFO - Job 61: Subtask complete_twitter_etl
[2023-01-26T08:13:08.308+0000] {task_command.py:388} INFO - Running <TaskInstance: twitter_dag.complete_twitter_etl scheduled__2020-12-08T00:00:00+00:00 [running]> on host 3143b9e5b257
[2023-01-26T08:13:08.477+0000] {taskinstance.py:1509} INFO - Exporting the following env vars:
AIRFLOW_CTX_DAG_EMAIL=***@example.com
AIRFLOW_CTX_DAG_OWNER=***
AIRFLOW_CTX_DAG_ID=twitter_dag
AIRFLOW_CTX_TASK_ID=complete_twitter_etl
AIRFLOW_CTX_EXECUTION_DATE=2020-12-08T00:00:00+00:00
AIRFLOW_CTX_TRY_NUMBER=1
AIRFLOW_CTX_DAG_RUN_ID=scheduled__2020-12-08T00:00:00+00:00
[2023-01-26T08:13:09.932+0000] {taskinstance.py:1768} ERROR - Task failed with exception
Traceback (most recent call last):
  File "/home/airflow/.local/lib/python3.7/site-packages/airflow/operators/python.py", line 175, in execute
    return_value = self.execute_callable()
  File "/home/airflow/.local/lib/python3.7/site-packages/airflow/operators/python.py", line 192, in execute_callable
    return self.python_callable(*self.op_args, **self.op_kwargs)
  File "/opt/airflow/dags/twitter_etl.py", line 64, in run_twitter_etl
    s3.Object(BUCKET_NAME, KEY).put(Body=csv_buffer.getvalue())
  File "/home/airflow/.local/lib/python3.7/site-packages/boto3/resources/factory.py", line 580, in do_action
    response = action(self, *args, **kwargs)
  File "/home/airflow/.local/lib/python3.7/site-packages/boto3/resources/action.py", line 88, in __call__
    response = getattr(parent.meta.client, operation_name)(*args, **params)
  File "/home/airflow/.local/lib/python3.7/site-packages/botocore/client.py", line 508, in _api_call
    return self._make_api_call(operation_name, kwargs)
  File "/home/airflow/.local/lib/python3.7/site-packages/botocore/client.py", line 915, in _make_api_call
    raise error_class(parsed_response, operation_name)
botocore.exceptions.ClientError: An error occurred (InvalidAccessKeyId) when calling the PutObject operation: The AWS Access Key Id you provided does not exist in our records.
[2023-01-26T08:13:09.961+0000] {taskinstance.py:1323} INFO - Marking task as UP_FOR_RETRY. dag_id=twitter_dag, task_id=complete_twitter_etl, execution_date=20201208T000000, start_date=20230126T081307, end_date=20230126T081309
[2023-01-26T08:13:09.993+0000] {standard_task_runner.py:105} ERROR - Failed to execute job 61 for task complete_twitter_etl (An error occurred (InvalidAccessKeyId) when calling the PutObject operation: The AWS Access Key Id you provided does not exist in our records.; 1143)
[2023-01-26T08:13:10.105+0000] {local_task_job.py:208} INFO - Task exited with return code 1
[2023-01-26T08:13:10.155+0000] {taskinstance.py:2578} INFO - 0 downstream tasks scheduled from follow-on schedule check
[2023-01-26T09:08:48.738+0000] {taskinstance.py:1083} INFO - Dependencies all met for <TaskInstance: twitter_dag.complete_twitter_etl scheduled__2020-12-08T00:00:00+00:00 [queued]>
[2023-01-26T09:08:48.840+0000] {taskinstance.py:1083} INFO - Dependencies all met for <TaskInstance: twitter_dag.complete_twitter_etl scheduled__2020-12-08T00:00:00+00:00 [queued]>
[2023-01-26T09:08:48.844+0000] {taskinstance.py:1279} INFO - 
--------------------------------------------------------------------------------
[2023-01-26T09:08:48.848+0000] {taskinstance.py:1280} INFO - Starting attempt 1 of 2
[2023-01-26T09:08:48.856+0000] {taskinstance.py:1281} INFO - 
--------------------------------------------------------------------------------
[2023-01-26T09:08:49.025+0000] {taskinstance.py:1300} INFO - Executing <Task(PythonOperator): complete_twitter_etl> on 2020-12-08 00:00:00+00:00
[2023-01-26T09:08:49.064+0000] {standard_task_runner.py:55} INFO - Started process 241 to run task
[2023-01-26T09:08:49.133+0000] {standard_task_runner.py:82} INFO - Running: ['***', 'tasks', 'run', 'twitter_dag', 'complete_twitter_etl', 'scheduled__2020-12-08T00:00:00+00:00', '--job-id', '33', '--raw', '--subdir', 'DAGS_FOLDER/twitter_dag.py', '--cfg-path', '/tmp/tmppqfyuh9l']
[2023-01-26T09:08:49.164+0000] {standard_task_runner.py:83} INFO - Job 33: Subtask complete_twitter_etl
[2023-01-26T09:08:50.833+0000] {task_command.py:388} INFO - Running <TaskInstance: twitter_dag.complete_twitter_etl scheduled__2020-12-08T00:00:00+00:00 [running]> on host d0fc3b00c15c
[2023-01-26T09:08:51.062+0000] {taskinstance.py:1509} INFO - Exporting the following env vars:
AIRFLOW_CTX_DAG_EMAIL=***@example.com
AIRFLOW_CTX_DAG_OWNER=***
AIRFLOW_CTX_DAG_ID=twitter_dag
AIRFLOW_CTX_TASK_ID=complete_twitter_etl
AIRFLOW_CTX_EXECUTION_DATE=2020-12-08T00:00:00+00:00
AIRFLOW_CTX_TRY_NUMBER=1
AIRFLOW_CTX_DAG_RUN_ID=scheduled__2020-12-08T00:00:00+00:00
[2023-01-26T09:08:52.831+0000] {python.py:177} INFO - Done. Returned value was: None
[2023-01-26T09:08:52.853+0000] {taskinstance.py:1323} INFO - Marking task as SUCCESS. dag_id=twitter_dag, task_id=complete_twitter_etl, execution_date=20201208T000000, start_date=20230126T090848, end_date=20230126T090852
[2023-01-26T09:08:52.972+0000] {local_task_job.py:208} INFO - Task exited with return code 0
[2023-01-26T09:08:53.005+0000] {taskinstance.py:2578} INFO - 0 downstream tasks scheduled from follow-on schedule check
