[2023-01-25T18:49:37.839+0000] {taskinstance.py:1083} INFO - Dependencies all met for <TaskInstance: twitter_dag.complete_twitter_etl scheduled__2021-01-10T00:00:00+00:00 [queued]>
[2023-01-25T18:49:37.887+0000] {taskinstance.py:1083} INFO - Dependencies all met for <TaskInstance: twitter_dag.complete_twitter_etl scheduled__2021-01-10T00:00:00+00:00 [queued]>
[2023-01-25T18:49:37.918+0000] {taskinstance.py:1279} INFO - 
--------------------------------------------------------------------------------
[2023-01-25T18:49:37.924+0000] {taskinstance.py:1280} INFO - Starting attempt 1 of 2
[2023-01-25T18:49:37.939+0000] {taskinstance.py:1281} INFO - 
--------------------------------------------------------------------------------
[2023-01-25T18:49:38.224+0000] {taskinstance.py:1300} INFO - Executing <Task(PythonOperator): complete_twitter_etl> on 2021-01-10 00:00:00+00:00
[2023-01-25T18:49:38.363+0000] {standard_task_runner.py:55} INFO - Started process 1308 to run task
[2023-01-25T18:49:38.464+0000] {standard_task_runner.py:82} INFO - Running: ['***', 'tasks', 'run', 'twitter_dag', 'complete_twitter_etl', 'scheduled__2021-01-10T00:00:00+00:00', '--job-id', '116', '--raw', '--subdir', 'DAGS_FOLDER/twitter_dag.py', '--cfg-path', '/tmp/tmp_oz4wv9u']
[2023-01-25T18:49:38.489+0000] {standard_task_runner.py:83} INFO - Job 116: Subtask complete_twitter_etl
[2023-01-25T18:49:39.961+0000] {task_command.py:388} INFO - Running <TaskInstance: twitter_dag.complete_twitter_etl scheduled__2021-01-10T00:00:00+00:00 [running]> on host 512d0ff0785b
[2023-01-25T18:49:45.934+0000] {taskinstance.py:1509} INFO - Exporting the following env vars:
AIRFLOW_CTX_DAG_EMAIL=***@example.com
AIRFLOW_CTX_DAG_OWNER=***
AIRFLOW_CTX_DAG_ID=twitter_dag
AIRFLOW_CTX_TASK_ID=complete_twitter_etl
AIRFLOW_CTX_EXECUTION_DATE=2021-01-10T00:00:00+00:00
AIRFLOW_CTX_TRY_NUMBER=1
AIRFLOW_CTX_DAG_RUN_ID=scheduled__2021-01-10T00:00:00+00:00
[2023-01-25T18:49:53.884+0000] {taskinstance.py:1768} ERROR - Task failed with exception
Traceback (most recent call last):
  File "/home/airflow/.local/lib/python3.7/site-packages/s3fs/core.py", line 112, in _error_wrapper
    return await func(*args, **kwargs)
  File "/home/airflow/.local/lib/python3.7/site-packages/aiobotocore/client.py", line 358, in _make_api_call
    raise error_class(parsed_response, operation_name)
botocore.exceptions.ClientError: An error occurred (AccessDenied) when calling the CreateBucket operation: Anonymous access is forbidden for this operation

The above exception was the direct cause of the following exception:

Traceback (most recent call last):
  File "/home/airflow/.local/lib/python3.7/site-packages/airflow/operators/python.py", line 175, in execute
    return_value = self.execute_callable()
  File "/home/airflow/.local/lib/python3.7/site-packages/airflow/operators/python.py", line 192, in execute_callable
    return self.python_callable(*self.op_args, **self.op_kwargs)
  File "/opt/airflow/dags/twitter_etl.py", line 46, in run_twitter_etl
    df.to_csv("s3://jinchoi-airflow-bucket/data/elonmusk_tweets.csv")
  File "/home/airflow/.local/lib/python3.7/site-packages/pandas/core/generic.py", line 3482, in to_csv
    storage_options=storage_options,
  File "/home/airflow/.local/lib/python3.7/site-packages/pandas/io/formats/format.py", line 1105, in to_csv
    csv_formatter.save()
  File "/home/airflow/.local/lib/python3.7/site-packages/pandas/io/formats/csvs.py", line 243, in save
    storage_options=self.storage_options,
  File "/home/airflow/.local/lib/python3.7/site-packages/pandas/io/common.py", line 614, in get_handle
    storage_options=storage_options,
  File "/home/airflow/.local/lib/python3.7/site-packages/pandas/io/common.py", line 370, in _get_filepath_or_buffer
    filepath_or_buffer, mode=fsspec_mode, **(storage_options or {})
  File "/home/airflow/.local/lib/python3.7/site-packages/fsspec/core.py", line 428, in open
    **kwargs,
  File "/home/airflow/.local/lib/python3.7/site-packages/fsspec/core.py", line 283, in open_files
    [fs.makedirs(parent, exist_ok=True) for parent in parents]
  File "/home/airflow/.local/lib/python3.7/site-packages/fsspec/core.py", line 283, in <listcomp>
    [fs.makedirs(parent, exist_ok=True) for parent in parents]
  File "/home/airflow/.local/lib/python3.7/site-packages/fsspec/asyn.py", line 114, in wrapper
    return sync(self.loop, func, *args, **kwargs)
  File "/home/airflow/.local/lib/python3.7/site-packages/fsspec/asyn.py", line 99, in sync
    raise return_result
  File "/home/airflow/.local/lib/python3.7/site-packages/fsspec/asyn.py", line 54, in _runner
    result[0] = await coro
  File "/home/airflow/.local/lib/python3.7/site-packages/s3fs/core.py", line 883, in _makedirs
    await self._mkdir(path, create_parents=True)
  File "/home/airflow/.local/lib/python3.7/site-packages/s3fs/core.py", line 868, in _mkdir
    await self._call_s3("create_bucket", **params)
  File "/home/airflow/.local/lib/python3.7/site-packages/s3fs/core.py", line 340, in _call_s3
    method, kwargs=additional_kwargs, retries=self.retries
  File "/home/airflow/.local/lib/python3.7/site-packages/s3fs/core.py", line 139, in _error_wrapper
    raise err
PermissionError: Anonymous access is forbidden for this operation
[2023-01-25T18:49:53.965+0000] {taskinstance.py:1323} INFO - Marking task as UP_FOR_RETRY. dag_id=twitter_dag, task_id=complete_twitter_etl, execution_date=20210110T000000, start_date=20230125T184937, end_date=20230125T184953
[2023-01-25T18:49:54.016+0000] {standard_task_runner.py:105} ERROR - Failed to execute job 116 for task complete_twitter_etl (Anonymous access is forbidden for this operation; 1308)
[2023-01-25T18:49:54.253+0000] {local_task_job.py:208} INFO - Task exited with return code 1
[2023-01-25T18:49:54.377+0000] {taskinstance.py:2578} INFO - 0 downstream tasks scheduled from follow-on schedule check
[2023-01-26T06:20:51.694+0000] {taskinstance.py:1083} INFO - Dependencies all met for <TaskInstance: twitter_dag.complete_twitter_etl scheduled__2021-01-10T00:00:00+00:00 [queued]>
[2023-01-26T06:20:51.717+0000] {taskinstance.py:1083} INFO - Dependencies all met for <TaskInstance: twitter_dag.complete_twitter_etl scheduled__2021-01-10T00:00:00+00:00 [queued]>
[2023-01-26T06:20:51.719+0000] {taskinstance.py:1279} INFO - 
--------------------------------------------------------------------------------
[2023-01-26T06:20:51.720+0000] {taskinstance.py:1280} INFO - Starting attempt 1 of 2
[2023-01-26T06:20:51.721+0000] {taskinstance.py:1281} INFO - 
--------------------------------------------------------------------------------
[2023-01-26T06:20:51.758+0000] {taskinstance.py:1300} INFO - Executing <Task(PythonOperator): complete_twitter_etl> on 2021-01-10 00:00:00+00:00
[2023-01-26T06:20:51.768+0000] {standard_task_runner.py:55} INFO - Started process 2302 to run task
[2023-01-26T06:20:51.781+0000] {standard_task_runner.py:82} INFO - Running: ['***', 'tasks', 'run', 'twitter_dag', 'complete_twitter_etl', 'scheduled__2021-01-10T00:00:00+00:00', '--job-id', '116', '--raw', '--subdir', 'DAGS_FOLDER/twitter_dag.py', '--cfg-path', '/tmp/tmpvahqigtt']
[2023-01-26T06:20:51.783+0000] {standard_task_runner.py:83} INFO - Job 116: Subtask complete_twitter_etl
[2023-01-26T06:20:52.167+0000] {task_command.py:388} INFO - Running <TaskInstance: twitter_dag.complete_twitter_etl scheduled__2021-01-10T00:00:00+00:00 [running]> on host 864c120ca3c2
[2023-01-26T06:20:52.258+0000] {taskinstance.py:1509} INFO - Exporting the following env vars:
AIRFLOW_CTX_DAG_EMAIL=***@example.com
AIRFLOW_CTX_DAG_OWNER=***
AIRFLOW_CTX_DAG_ID=twitter_dag
AIRFLOW_CTX_TASK_ID=complete_twitter_etl
AIRFLOW_CTX_EXECUTION_DATE=2021-01-10T00:00:00+00:00
AIRFLOW_CTX_TRY_NUMBER=1
AIRFLOW_CTX_DAG_RUN_ID=scheduled__2021-01-10T00:00:00+00:00
[2023-01-26T06:20:52.826+0000] {taskinstance.py:1768} ERROR - Task failed with exception
Traceback (most recent call last):
  File "/home/airflow/.local/lib/python3.7/site-packages/airflow/operators/python.py", line 175, in execute
    return_value = self.execute_callable()
  File "/home/airflow/.local/lib/python3.7/site-packages/airflow/operators/python.py", line 192, in execute_callable
    return self.python_callable(*self.op_args, **self.op_kwargs)
  File "/opt/airflow/dags/twitter_etl.py", line 51, in run_twitter_etl
    aws_access_key_id=os.environ['AWS_ACCESS_KEY_ID'],
  File "/usr/local/lib/python3.7/os.py", line 681, in __getitem__
    raise KeyError(key) from None
KeyError: 'AWS_ACCESS_KEY_ID'
[2023-01-26T06:20:52.843+0000] {taskinstance.py:1323} INFO - Marking task as UP_FOR_RETRY. dag_id=twitter_dag, task_id=complete_twitter_etl, execution_date=20210110T000000, start_date=20230126T062051, end_date=20230126T062052
[2023-01-26T06:20:52.860+0000] {standard_task_runner.py:105} ERROR - Failed to execute job 116 for task complete_twitter_etl ('AWS_ACCESS_KEY_ID'; 2302)
[2023-01-26T06:20:52.893+0000] {local_task_job.py:208} INFO - Task exited with return code 1
[2023-01-26T06:20:52.917+0000] {taskinstance.py:2578} INFO - 0 downstream tasks scheduled from follow-on schedule check
[2023-01-26T07:11:45.147+0000] {taskinstance.py:1083} INFO - Dependencies all met for <TaskInstance: twitter_dag.complete_twitter_etl scheduled__2021-01-10T00:00:00+00:00 [queued]>
[2023-01-26T07:11:45.328+0000] {taskinstance.py:1083} INFO - Dependencies all met for <TaskInstance: twitter_dag.complete_twitter_etl scheduled__2021-01-10T00:00:00+00:00 [queued]>
[2023-01-26T07:11:45.335+0000] {taskinstance.py:1279} INFO - 
--------------------------------------------------------------------------------
[2023-01-26T07:11:45.337+0000] {taskinstance.py:1280} INFO - Starting attempt 1 of 2
[2023-01-26T07:11:45.339+0000] {taskinstance.py:1281} INFO - 
--------------------------------------------------------------------------------
[2023-01-26T07:11:45.544+0000] {taskinstance.py:1300} INFO - Executing <Task(PythonOperator): complete_twitter_etl> on 2021-01-10 00:00:00+00:00
[2023-01-26T07:11:45.689+0000] {standard_task_runner.py:82} INFO - Running: ['***', 'tasks', 'run', 'twitter_dag', 'complete_twitter_etl', 'scheduled__2021-01-10T00:00:00+00:00', '--job-id', '102', '--raw', '--subdir', 'DAGS_FOLDER/twitter_dag.py', '--cfg-path', '/tmp/tmpv681_sqv']
[2023-01-26T07:11:45.732+0000] {standard_task_runner.py:83} INFO - Job 102: Subtask complete_twitter_etl
[2023-01-26T07:11:45.728+0000] {standard_task_runner.py:55} INFO - Started process 1030 to run task
[2023-01-26T07:11:52.481+0000] {task_command.py:388} INFO - Running <TaskInstance: twitter_dag.complete_twitter_etl scheduled__2021-01-10T00:00:00+00:00 [running]> on host 2221c1ebf970
[2023-01-26T07:11:53.271+0000] {taskinstance.py:1509} INFO - Exporting the following env vars:
AIRFLOW_CTX_DAG_EMAIL=***@example.com
AIRFLOW_CTX_DAG_OWNER=***
AIRFLOW_CTX_DAG_ID=twitter_dag
AIRFLOW_CTX_TASK_ID=complete_twitter_etl
AIRFLOW_CTX_EXECUTION_DATE=2021-01-10T00:00:00+00:00
AIRFLOW_CTX_TRY_NUMBER=1
AIRFLOW_CTX_DAG_RUN_ID=scheduled__2021-01-10T00:00:00+00:00
[2023-01-26T07:11:56.313+0000] {python.py:177} INFO - Done. Returned value was: None
[2023-01-26T07:11:56.352+0000] {taskinstance.py:1323} INFO - Marking task as SUCCESS. dag_id=twitter_dag, task_id=complete_twitter_etl, execution_date=20210110T000000, start_date=20230126T071145, end_date=20230126T071156
[2023-01-26T07:11:56.585+0000] {local_task_job.py:208} INFO - Task exited with return code 0
[2023-01-26T07:11:56.951+0000] {taskinstance.py:2578} INFO - 0 downstream tasks scheduled from follow-on schedule check
[2023-01-26T08:24:09.123+0000] {taskinstance.py:1083} INFO - Dependencies all met for <TaskInstance: twitter_dag.complete_twitter_etl scheduled__2021-01-10T00:00:00+00:00 [queued]>
[2023-01-26T08:24:09.160+0000] {taskinstance.py:1083} INFO - Dependencies all met for <TaskInstance: twitter_dag.complete_twitter_etl scheduled__2021-01-10T00:00:00+00:00 [queued]>
[2023-01-26T08:24:09.162+0000] {taskinstance.py:1279} INFO - 
--------------------------------------------------------------------------------
[2023-01-26T08:24:09.163+0000] {taskinstance.py:1280} INFO - Starting attempt 1 of 2
[2023-01-26T08:24:09.164+0000] {taskinstance.py:1281} INFO - 
--------------------------------------------------------------------------------
[2023-01-26T08:24:10.336+0000] {taskinstance.py:1300} INFO - Executing <Task(PythonOperator): complete_twitter_etl> on 2021-01-10 00:00:00+00:00
[2023-01-26T08:24:10.407+0000] {standard_task_runner.py:55} INFO - Started process 1953 to run task
[2023-01-26T08:24:10.421+0000] {standard_task_runner.py:82} INFO - Running: ['***', 'tasks', 'run', 'twitter_dag', 'complete_twitter_etl', 'scheduled__2021-01-10T00:00:00+00:00', '--job-id', '124', '--raw', '--subdir', 'DAGS_FOLDER/twitter_dag.py', '--cfg-path', '/tmp/tmpm590thra']
[2023-01-26T08:24:10.427+0000] {standard_task_runner.py:83} INFO - Job 124: Subtask complete_twitter_etl
[2023-01-26T08:24:10.631+0000] {task_command.py:388} INFO - Running <TaskInstance: twitter_dag.complete_twitter_etl scheduled__2021-01-10T00:00:00+00:00 [running]> on host 3143b9e5b257
[2023-01-26T08:24:10.967+0000] {taskinstance.py:1509} INFO - Exporting the following env vars:
AIRFLOW_CTX_DAG_EMAIL=***@example.com
AIRFLOW_CTX_DAG_OWNER=***
AIRFLOW_CTX_DAG_ID=twitter_dag
AIRFLOW_CTX_TASK_ID=complete_twitter_etl
AIRFLOW_CTX_EXECUTION_DATE=2021-01-10T00:00:00+00:00
AIRFLOW_CTX_TRY_NUMBER=1
AIRFLOW_CTX_DAG_RUN_ID=scheduled__2021-01-10T00:00:00+00:00
[2023-01-26T08:24:12.505+0000] {taskinstance.py:1768} ERROR - Task failed with exception
Traceback (most recent call last):
  File "/home/airflow/.local/lib/python3.7/site-packages/airflow/operators/python.py", line 175, in execute
    return_value = self.execute_callable()
  File "/home/airflow/.local/lib/python3.7/site-packages/airflow/operators/python.py", line 192, in execute_callable
    return self.python_callable(*self.op_args, **self.op_kwargs)
  File "/opt/airflow/dags/twitter_etl.py", line 64, in run_twitter_etl
    s3.Object(BUCKET_NAME, KEY).put(Body=csv_buffer.getvalue())
  File "/home/airflow/.local/lib/python3.7/site-packages/boto3/resources/factory.py", line 580, in do_action
    response = action(self, *args, **kwargs)
  File "/home/airflow/.local/lib/python3.7/site-packages/boto3/resources/action.py", line 88, in __call__
    response = getattr(parent.meta.client, operation_name)(*args, **params)
  File "/home/airflow/.local/lib/python3.7/site-packages/botocore/client.py", line 508, in _api_call
    return self._make_api_call(operation_name, kwargs)
  File "/home/airflow/.local/lib/python3.7/site-packages/botocore/client.py", line 915, in _make_api_call
    raise error_class(parsed_response, operation_name)
botocore.exceptions.ClientError: An error occurred (InvalidAccessKeyId) when calling the PutObject operation: The AWS Access Key Id you provided does not exist in our records.
[2023-01-26T08:24:12.521+0000] {taskinstance.py:1323} INFO - Marking task as UP_FOR_RETRY. dag_id=twitter_dag, task_id=complete_twitter_etl, execution_date=20210110T000000, start_date=20230126T082409, end_date=20230126T082412
[2023-01-26T08:24:12.569+0000] {standard_task_runner.py:105} ERROR - Failed to execute job 124 for task complete_twitter_etl (An error occurred (InvalidAccessKeyId) when calling the PutObject operation: The AWS Access Key Id you provided does not exist in our records.; 1953)
[2023-01-26T08:24:12.631+0000] {local_task_job.py:208} INFO - Task exited with return code 1
[2023-01-26T08:24:12.750+0000] {taskinstance.py:2578} INFO - 0 downstream tasks scheduled from follow-on schedule check
[2023-01-26T09:09:41.399+0000] {taskinstance.py:1083} INFO - Dependencies all met for <TaskInstance: twitter_dag.complete_twitter_etl scheduled__2021-01-10T00:00:00+00:00 [queued]>
[2023-01-26T09:09:41.441+0000] {taskinstance.py:1083} INFO - Dependencies all met for <TaskInstance: twitter_dag.complete_twitter_etl scheduled__2021-01-10T00:00:00+00:00 [queued]>
[2023-01-26T09:09:41.445+0000] {taskinstance.py:1279} INFO - 
--------------------------------------------------------------------------------
[2023-01-26T09:09:41.447+0000] {taskinstance.py:1280} INFO - Starting attempt 1 of 2
[2023-01-26T09:09:41.448+0000] {taskinstance.py:1281} INFO - 
--------------------------------------------------------------------------------
[2023-01-26T09:09:41.524+0000] {taskinstance.py:1300} INFO - Executing <Task(PythonOperator): complete_twitter_etl> on 2021-01-10 00:00:00+00:00
[2023-01-26T09:09:41.561+0000] {standard_task_runner.py:55} INFO - Started process 375 to run task
[2023-01-26T09:09:41.595+0000] {standard_task_runner.py:82} INFO - Running: ['***', 'tasks', 'run', 'twitter_dag', 'complete_twitter_etl', 'scheduled__2021-01-10T00:00:00+00:00', '--job-id', '67', '--raw', '--subdir', 'DAGS_FOLDER/twitter_dag.py', '--cfg-path', '/tmp/tmpk51z6zij']
[2023-01-26T09:09:41.597+0000] {standard_task_runner.py:83} INFO - Job 67: Subtask complete_twitter_etl
[2023-01-26T09:09:42.530+0000] {task_command.py:388} INFO - Running <TaskInstance: twitter_dag.complete_twitter_etl scheduled__2021-01-10T00:00:00+00:00 [running]> on host d0fc3b00c15c
[2023-01-26T09:09:43.180+0000] {taskinstance.py:1509} INFO - Exporting the following env vars:
AIRFLOW_CTX_DAG_EMAIL=***@example.com
AIRFLOW_CTX_DAG_OWNER=***
AIRFLOW_CTX_DAG_ID=twitter_dag
AIRFLOW_CTX_TASK_ID=complete_twitter_etl
AIRFLOW_CTX_EXECUTION_DATE=2021-01-10T00:00:00+00:00
AIRFLOW_CTX_TRY_NUMBER=1
AIRFLOW_CTX_DAG_RUN_ID=scheduled__2021-01-10T00:00:00+00:00
[2023-01-26T09:09:45.487+0000] {python.py:177} INFO - Done. Returned value was: None
[2023-01-26T09:09:45.561+0000] {taskinstance.py:1323} INFO - Marking task as SUCCESS. dag_id=twitter_dag, task_id=complete_twitter_etl, execution_date=20210110T000000, start_date=20230126T090941, end_date=20230126T090945
[2023-01-26T09:09:45.726+0000] {local_task_job.py:208} INFO - Task exited with return code 0
[2023-01-26T09:09:45.783+0000] {taskinstance.py:2578} INFO - 0 downstream tasks scheduled from follow-on schedule check
