[2023-01-25T18:45:55.814+0000] {taskinstance.py:1083} INFO - Dependencies all met for <TaskInstance: twitter_dag.complete_twitter_etl scheduled__2020-12-05T00:00:00+00:00 [queued]>
[2023-01-25T18:45:56.054+0000] {taskinstance.py:1083} INFO - Dependencies all met for <TaskInstance: twitter_dag.complete_twitter_etl scheduled__2020-12-05T00:00:00+00:00 [queued]>
[2023-01-25T18:45:56.056+0000] {taskinstance.py:1279} INFO - 
--------------------------------------------------------------------------------
[2023-01-25T18:45:56.059+0000] {taskinstance.py:1280} INFO - Starting attempt 2 of 2
[2023-01-25T18:45:56.084+0000] {taskinstance.py:1281} INFO - 
--------------------------------------------------------------------------------
[2023-01-25T18:45:56.504+0000] {taskinstance.py:1300} INFO - Executing <Task(PythonOperator): complete_twitter_etl> on 2020-12-05 00:00:00+00:00
[2023-01-25T18:45:56.577+0000] {standard_task_runner.py:55} INFO - Started process 856 to run task
[2023-01-25T18:45:56.727+0000] {standard_task_runner.py:82} INFO - Running: ['***', 'tasks', 'run', 'twitter_dag', 'complete_twitter_etl', 'scheduled__2020-12-05T00:00:00+00:00', '--job-id', '65', '--raw', '--subdir', 'DAGS_FOLDER/twitter_dag.py', '--cfg-path', '/tmp/tmp_8oq8zsd']
[2023-01-25T18:45:56.745+0000] {standard_task_runner.py:83} INFO - Job 65: Subtask complete_twitter_etl
[2023-01-25T18:45:57.994+0000] {task_command.py:388} INFO - Running <TaskInstance: twitter_dag.complete_twitter_etl scheduled__2020-12-05T00:00:00+00:00 [running]> on host 512d0ff0785b
[2023-01-25T18:46:01.546+0000] {taskinstance.py:1509} INFO - Exporting the following env vars:
AIRFLOW_CTX_DAG_EMAIL=***@example.com
AIRFLOW_CTX_DAG_OWNER=***
AIRFLOW_CTX_DAG_ID=twitter_dag
AIRFLOW_CTX_TASK_ID=complete_twitter_etl
AIRFLOW_CTX_EXECUTION_DATE=2020-12-05T00:00:00+00:00
AIRFLOW_CTX_TRY_NUMBER=2
AIRFLOW_CTX_DAG_RUN_ID=scheduled__2020-12-05T00:00:00+00:00
[2023-01-25T18:46:09.127+0000] {taskinstance.py:1768} ERROR - Task failed with exception
Traceback (most recent call last):
  File "/home/airflow/.local/lib/python3.7/site-packages/s3fs/core.py", line 112, in _error_wrapper
    return await func(*args, **kwargs)
  File "/home/airflow/.local/lib/python3.7/site-packages/aiobotocore/client.py", line 358, in _make_api_call
    raise error_class(parsed_response, operation_name)
botocore.exceptions.ClientError: An error occurred (AccessDenied) when calling the CreateBucket operation: Anonymous access is forbidden for this operation

The above exception was the direct cause of the following exception:

Traceback (most recent call last):
  File "/home/airflow/.local/lib/python3.7/site-packages/airflow/operators/python.py", line 175, in execute
    return_value = self.execute_callable()
  File "/home/airflow/.local/lib/python3.7/site-packages/airflow/operators/python.py", line 192, in execute_callable
    return self.python_callable(*self.op_args, **self.op_kwargs)
  File "/opt/airflow/dags/twitter_etl.py", line 46, in run_twitter_etl
    df.to_csv("s3://jinchoi-airflow-bucket/data/elonmusk_tweets.csv")
  File "/home/airflow/.local/lib/python3.7/site-packages/pandas/core/generic.py", line 3482, in to_csv
    storage_options=storage_options,
  File "/home/airflow/.local/lib/python3.7/site-packages/pandas/io/formats/format.py", line 1105, in to_csv
    csv_formatter.save()
  File "/home/airflow/.local/lib/python3.7/site-packages/pandas/io/formats/csvs.py", line 243, in save
    storage_options=self.storage_options,
  File "/home/airflow/.local/lib/python3.7/site-packages/pandas/io/common.py", line 614, in get_handle
    storage_options=storage_options,
  File "/home/airflow/.local/lib/python3.7/site-packages/pandas/io/common.py", line 370, in _get_filepath_or_buffer
    filepath_or_buffer, mode=fsspec_mode, **(storage_options or {})
  File "/home/airflow/.local/lib/python3.7/site-packages/fsspec/core.py", line 428, in open
    **kwargs,
  File "/home/airflow/.local/lib/python3.7/site-packages/fsspec/core.py", line 283, in open_files
    [fs.makedirs(parent, exist_ok=True) for parent in parents]
  File "/home/airflow/.local/lib/python3.7/site-packages/fsspec/core.py", line 283, in <listcomp>
    [fs.makedirs(parent, exist_ok=True) for parent in parents]
  File "/home/airflow/.local/lib/python3.7/site-packages/fsspec/asyn.py", line 114, in wrapper
    return sync(self.loop, func, *args, **kwargs)
  File "/home/airflow/.local/lib/python3.7/site-packages/fsspec/asyn.py", line 99, in sync
    raise return_result
  File "/home/airflow/.local/lib/python3.7/site-packages/fsspec/asyn.py", line 54, in _runner
    result[0] = await coro
  File "/home/airflow/.local/lib/python3.7/site-packages/s3fs/core.py", line 883, in _makedirs
    await self._mkdir(path, create_parents=True)
  File "/home/airflow/.local/lib/python3.7/site-packages/s3fs/core.py", line 868, in _mkdir
    await self._call_s3("create_bucket", **params)
  File "/home/airflow/.local/lib/python3.7/site-packages/s3fs/core.py", line 340, in _call_s3
    method, kwargs=additional_kwargs, retries=self.retries
  File "/home/airflow/.local/lib/python3.7/site-packages/s3fs/core.py", line 139, in _error_wrapper
    raise err
PermissionError: Anonymous access is forbidden for this operation
[2023-01-25T18:46:09.181+0000] {taskinstance.py:1323} INFO - Marking task as FAILED. dag_id=twitter_dag, task_id=complete_twitter_etl, execution_date=20201205T000000, start_date=20230125T184555, end_date=20230125T184609
[2023-01-25T18:46:09.232+0000] {standard_task_runner.py:105} ERROR - Failed to execute job 65 for task complete_twitter_etl (Anonymous access is forbidden for this operation; 856)
[2023-01-25T18:46:09.311+0000] {local_task_job.py:208} INFO - Task exited with return code 1
[2023-01-25T18:46:09.380+0000] {taskinstance.py:2578} INFO - 0 downstream tasks scheduled from follow-on schedule check
[2023-01-26T03:25:31.229+0000] {taskinstance.py:1083} INFO - Dependencies all met for <TaskInstance: twitter_dag.complete_twitter_etl scheduled__2020-12-05T00:00:00+00:00 [queued]>
[2023-01-26T03:25:31.334+0000] {taskinstance.py:1083} INFO - Dependencies all met for <TaskInstance: twitter_dag.complete_twitter_etl scheduled__2020-12-05T00:00:00+00:00 [queued]>
[2023-01-26T03:25:31.335+0000] {taskinstance.py:1279} INFO - 
--------------------------------------------------------------------------------
[2023-01-26T03:25:31.337+0000] {taskinstance.py:1280} INFO - Starting attempt 2 of 2
[2023-01-26T03:25:31.338+0000] {taskinstance.py:1281} INFO - 
--------------------------------------------------------------------------------
[2023-01-26T03:25:31.448+0000] {taskinstance.py:1300} INFO - Executing <Task(PythonOperator): complete_twitter_etl> on 2020-12-05 00:00:00+00:00
[2023-01-26T03:25:31.463+0000] {standard_task_runner.py:55} INFO - Started process 505 to run task
[2023-01-26T03:25:31.483+0000] {standard_task_runner.py:82} INFO - Running: ['***', 'tasks', 'run', 'twitter_dag', 'complete_twitter_etl', 'scheduled__2020-12-05T00:00:00+00:00', '--job-id', '69', '--raw', '--subdir', 'DAGS_FOLDER/twitter_dag.py', '--cfg-path', '/tmp/tmpe1d8yre4']
[2023-01-26T03:25:31.491+0000] {standard_task_runner.py:83} INFO - Job 69: Subtask complete_twitter_etl
[2023-01-26T03:25:31.987+0000] {task_command.py:388} INFO - Running <TaskInstance: twitter_dag.complete_twitter_etl scheduled__2020-12-05T00:00:00+00:00 [running]> on host 3db080823b1b
[2023-01-26T03:25:33.292+0000] {taskinstance.py:1509} INFO - Exporting the following env vars:
AIRFLOW_CTX_DAG_EMAIL=***@example.com
AIRFLOW_CTX_DAG_OWNER=***
AIRFLOW_CTX_DAG_ID=twitter_dag
AIRFLOW_CTX_TASK_ID=complete_twitter_etl
AIRFLOW_CTX_EXECUTION_DATE=2020-12-05T00:00:00+00:00
AIRFLOW_CTX_TRY_NUMBER=2
AIRFLOW_CTX_DAG_RUN_ID=scheduled__2020-12-05T00:00:00+00:00
[2023-01-26T03:25:34.485+0000] {taskinstance.py:1768} ERROR - Task failed with exception
Traceback (most recent call last):
  File "/home/airflow/.local/lib/python3.7/site-packages/airflow/operators/python.py", line 175, in execute
    return_value = self.execute_callable()
  File "/home/airflow/.local/lib/python3.7/site-packages/airflow/operators/python.py", line 192, in execute_callable
    return self.python_callable(*self.op_args, **self.op_kwargs)
  File "/opt/airflow/dags/twitter_etl.py", line 53, in run_twitter_etl
    df.to_csv('s3://{BUCKET_NAME}/data/{KEY}', index=False, header=False,sep=',', engine='python', filesystem=s3)
TypeError: to_csv() got an unexpected keyword argument 'engine'
[2023-01-26T03:25:34.507+0000] {taskinstance.py:1323} INFO - Marking task as FAILED. dag_id=twitter_dag, task_id=complete_twitter_etl, execution_date=20201205T000000, start_date=20230126T032531, end_date=20230126T032534
[2023-01-26T03:25:34.528+0000] {standard_task_runner.py:105} ERROR - Failed to execute job 69 for task complete_twitter_etl (to_csv() got an unexpected keyword argument 'engine'; 505)
[2023-01-26T03:25:34.589+0000] {local_task_job.py:208} INFO - Task exited with return code 1
[2023-01-26T03:25:34.627+0000] {taskinstance.py:2578} INFO - 0 downstream tasks scheduled from follow-on schedule check
[2023-01-26T03:36:50.407+0000] {taskinstance.py:1083} INFO - Dependencies all met for <TaskInstance: twitter_dag.complete_twitter_etl scheduled__2020-12-05T00:00:00+00:00 [queued]>
[2023-01-26T03:36:50.443+0000] {taskinstance.py:1083} INFO - Dependencies all met for <TaskInstance: twitter_dag.complete_twitter_etl scheduled__2020-12-05T00:00:00+00:00 [queued]>
[2023-01-26T03:36:50.444+0000] {taskinstance.py:1279} INFO - 
--------------------------------------------------------------------------------
[2023-01-26T03:36:50.445+0000] {taskinstance.py:1280} INFO - Starting attempt 2 of 2
[2023-01-26T03:36:50.446+0000] {taskinstance.py:1281} INFO - 
--------------------------------------------------------------------------------
[2023-01-26T03:36:50.560+0000] {taskinstance.py:1300} INFO - Executing <Task(PythonOperator): complete_twitter_etl> on 2020-12-05 00:00:00+00:00
[2023-01-26T03:36:50.635+0000] {standard_task_runner.py:82} INFO - Running: ['***', 'tasks', 'run', 'twitter_dag', 'complete_twitter_etl', 'scheduled__2020-12-05T00:00:00+00:00', '--job-id', '60', '--raw', '--subdir', 'DAGS_FOLDER/twitter_dag.py', '--cfg-path', '/tmp/tmphll8ka20']
[2023-01-26T03:36:50.611+0000] {standard_task_runner.py:55} INFO - Started process 486 to run task
[2023-01-26T03:36:50.647+0000] {standard_task_runner.py:83} INFO - Job 60: Subtask complete_twitter_etl
[2023-01-26T03:36:51.102+0000] {task_command.py:388} INFO - Running <TaskInstance: twitter_dag.complete_twitter_etl scheduled__2020-12-05T00:00:00+00:00 [running]> on host 9c4f31e2db2b
[2023-01-26T03:36:53.010+0000] {taskinstance.py:1509} INFO - Exporting the following env vars:
AIRFLOW_CTX_DAG_EMAIL=***@example.com
AIRFLOW_CTX_DAG_OWNER=***
AIRFLOW_CTX_DAG_ID=twitter_dag
AIRFLOW_CTX_TASK_ID=complete_twitter_etl
AIRFLOW_CTX_EXECUTION_DATE=2020-12-05T00:00:00+00:00
AIRFLOW_CTX_TRY_NUMBER=2
AIRFLOW_CTX_DAG_RUN_ID=scheduled__2020-12-05T00:00:00+00:00
[2023-01-26T03:36:54.811+0000] {taskinstance.py:1768} ERROR - Task failed with exception
Traceback (most recent call last):
  File "/home/airflow/.local/lib/python3.7/site-packages/airflow/operators/python.py", line 175, in execute
    return_value = self.execute_callable()
  File "/home/airflow/.local/lib/python3.7/site-packages/airflow/operators/python.py", line 192, in execute_callable
    return self.python_callable(*self.op_args, **self.op_kwargs)
  File "/opt/airflow/dags/twitter_etl.py", line 54, in run_twitter_etl
    s3.put('s3://{BUCKET_NAME}/data/{KEY}', csv_buffer)
  File "/home/airflow/.local/lib/python3.7/site-packages/fsspec/asyn.py", line 114, in wrapper
    return sync(self.loop, func, *args, **kwargs)
  File "/home/airflow/.local/lib/python3.7/site-packages/fsspec/asyn.py", line 99, in sync
    raise return_result
  File "/home/airflow/.local/lib/python3.7/site-packages/fsspec/asyn.py", line 54, in _runner
    result[0] = await coro
  File "/home/airflow/.local/lib/python3.7/site-packages/fsspec/asyn.py", line 481, in _put
    rpath = self._strip_protocol(rpath)
  File "/home/airflow/.local/lib/python3.7/site-packages/fsspec/spec.py", line 188, in _strip_protocol
    if path.startswith(protocol + "://"):
TypeError: startswith first arg must be bytes or a tuple of bytes, not str
[2023-01-26T03:36:54.857+0000] {taskinstance.py:1323} INFO - Marking task as FAILED. dag_id=twitter_dag, task_id=complete_twitter_etl, execution_date=20201205T000000, start_date=20230126T033650, end_date=20230126T033654
[2023-01-26T03:36:54.972+0000] {standard_task_runner.py:105} ERROR - Failed to execute job 60 for task complete_twitter_etl (startswith first arg must be bytes or a tuple of bytes, not str; 486)
[2023-01-26T03:36:55.059+0000] {local_task_job.py:208} INFO - Task exited with return code 1
[2023-01-26T03:36:55.109+0000] {taskinstance.py:2578} INFO - 0 downstream tasks scheduled from follow-on schedule check
[2023-01-26T06:10:22.845+0000] {taskinstance.py:1083} INFO - Dependencies all met for <TaskInstance: twitter_dag.complete_twitter_etl scheduled__2020-12-05T00:00:00+00:00 [queued]>
[2023-01-26T06:10:22.888+0000] {taskinstance.py:1083} INFO - Dependencies all met for <TaskInstance: twitter_dag.complete_twitter_etl scheduled__2020-12-05T00:00:00+00:00 [queued]>
[2023-01-26T06:10:22.891+0000] {taskinstance.py:1279} INFO - 
--------------------------------------------------------------------------------
[2023-01-26T06:10:22.893+0000] {taskinstance.py:1280} INFO - Starting attempt 2 of 2
[2023-01-26T06:10:22.895+0000] {taskinstance.py:1281} INFO - 
--------------------------------------------------------------------------------
[2023-01-26T06:10:22.932+0000] {taskinstance.py:1300} INFO - Executing <Task(PythonOperator): complete_twitter_etl> on 2020-12-05 00:00:00+00:00
[2023-01-26T06:10:22.962+0000] {standard_task_runner.py:55} INFO - Started process 1553 to run task
[2023-01-26T06:10:23.039+0000] {standard_task_runner.py:82} INFO - Running: ['***', 'tasks', 'run', 'twitter_dag', 'complete_twitter_etl', 'scheduled__2020-12-05T00:00:00+00:00', '--job-id', '65', '--raw', '--subdir', 'DAGS_FOLDER/twitter_dag.py', '--cfg-path', '/tmp/tmpu0z8bzyu']
[2023-01-26T06:10:23.050+0000] {standard_task_runner.py:83} INFO - Job 65: Subtask complete_twitter_etl
[2023-01-26T06:10:24.044+0000] {task_command.py:388} INFO - Running <TaskInstance: twitter_dag.complete_twitter_etl scheduled__2020-12-05T00:00:00+00:00 [running]> on host 864c120ca3c2
[2023-01-26T06:10:24.243+0000] {taskinstance.py:1509} INFO - Exporting the following env vars:
AIRFLOW_CTX_DAG_EMAIL=***@example.com
AIRFLOW_CTX_DAG_OWNER=***
AIRFLOW_CTX_DAG_ID=twitter_dag
AIRFLOW_CTX_TASK_ID=complete_twitter_etl
AIRFLOW_CTX_EXECUTION_DATE=2020-12-05T00:00:00+00:00
AIRFLOW_CTX_TRY_NUMBER=2
AIRFLOW_CTX_DAG_RUN_ID=scheduled__2020-12-05T00:00:00+00:00
[2023-01-26T06:10:25.242+0000] {taskinstance.py:1768} ERROR - Task failed with exception
Traceback (most recent call last):
  File "/home/airflow/.local/lib/python3.7/site-packages/airflow/operators/python.py", line 175, in execute
    return_value = self.execute_callable()
  File "/home/airflow/.local/lib/python3.7/site-packages/airflow/operators/python.py", line 192, in execute_callable
    return self.python_callable(*self.op_args, **self.op_kwargs)
  File "/opt/airflow/dags/twitter_etl.py", line 51, in run_twitter_etl
    aws_access_key_id=os.environ['AWS_ACCESS_KEY_ID'],
  File "/usr/local/lib/python3.7/os.py", line 681, in __getitem__
    raise KeyError(key) from None
KeyError: 'AWS_ACCESS_KEY_ID'
[2023-01-26T06:10:25.273+0000] {taskinstance.py:1323} INFO - Marking task as FAILED. dag_id=twitter_dag, task_id=complete_twitter_etl, execution_date=20201205T000000, start_date=20230126T061022, end_date=20230126T061025
[2023-01-26T06:10:25.331+0000] {standard_task_runner.py:105} ERROR - Failed to execute job 65 for task complete_twitter_etl ('AWS_ACCESS_KEY_ID'; 1553)
[2023-01-26T06:10:25.424+0000] {local_task_job.py:208} INFO - Task exited with return code 1
[2023-01-26T06:10:25.508+0000] {taskinstance.py:2578} INFO - 0 downstream tasks scheduled from follow-on schedule check
[2023-01-26T07:10:38.121+0000] {taskinstance.py:1083} INFO - Dependencies all met for <TaskInstance: twitter_dag.complete_twitter_etl scheduled__2020-12-05T00:00:00+00:00 [queued]>
[2023-01-26T07:10:38.545+0000] {taskinstance.py:1083} INFO - Dependencies all met for <TaskInstance: twitter_dag.complete_twitter_etl scheduled__2020-12-05T00:00:00+00:00 [queued]>
[2023-01-26T07:10:38.629+0000] {taskinstance.py:1279} INFO - 
--------------------------------------------------------------------------------
[2023-01-26T07:10:38.655+0000] {taskinstance.py:1280} INFO - Starting attempt 2 of 2
[2023-01-26T07:10:38.659+0000] {taskinstance.py:1281} INFO - 
--------------------------------------------------------------------------------
[2023-01-26T07:10:39.546+0000] {taskinstance.py:1300} INFO - Executing <Task(PythonOperator): complete_twitter_etl> on 2020-12-05 00:00:00+00:00
[2023-01-26T07:10:43.044+0000] {standard_task_runner.py:82} INFO - Running: ['***', 'tasks', 'run', 'twitter_dag', 'complete_twitter_etl', 'scheduled__2020-12-05T00:00:00+00:00', '--job-id', '67', '--raw', '--subdir', 'DAGS_FOLDER/twitter_dag.py', '--cfg-path', '/tmp/tmp_hia0uxq']
[2023-01-26T07:10:43.098+0000] {standard_task_runner.py:83} INFO - Job 67: Subtask complete_twitter_etl
[2023-01-26T07:10:42.954+0000] {standard_task_runner.py:55} INFO - Started process 887 to run task
[2023-01-26T07:10:51.971+0000] {task_command.py:388} INFO - Running <TaskInstance: twitter_dag.complete_twitter_etl scheduled__2020-12-05T00:00:00+00:00 [running]> on host 2221c1ebf970
[2023-01-26T07:10:53.251+0000] {taskinstance.py:1509} INFO - Exporting the following env vars:
AIRFLOW_CTX_DAG_EMAIL=***@example.com
AIRFLOW_CTX_DAG_OWNER=***
AIRFLOW_CTX_DAG_ID=twitter_dag
AIRFLOW_CTX_TASK_ID=complete_twitter_etl
AIRFLOW_CTX_EXECUTION_DATE=2020-12-05T00:00:00+00:00
AIRFLOW_CTX_TRY_NUMBER=2
AIRFLOW_CTX_DAG_RUN_ID=scheduled__2020-12-05T00:00:00+00:00
[2023-01-26T07:10:57.863+0000] {python.py:177} INFO - Done. Returned value was: None
[2023-01-26T07:10:57.943+0000] {taskinstance.py:1323} INFO - Marking task as SUCCESS. dag_id=twitter_dag, task_id=complete_twitter_etl, execution_date=20201205T000000, start_date=20230126T071038, end_date=20230126T071057
[2023-01-26T07:10:58.379+0000] {local_task_job.py:208} INFO - Task exited with return code 0
[2023-01-26T07:10:59.479+0000] {taskinstance.py:2578} INFO - 0 downstream tasks scheduled from follow-on schedule check
[2023-01-26T08:13:59.237+0000] {taskinstance.py:1083} INFO - Dependencies all met for <TaskInstance: twitter_dag.complete_twitter_etl scheduled__2020-12-05T00:00:00+00:00 [queued]>
[2023-01-26T08:13:59.255+0000] {taskinstance.py:1083} INFO - Dependencies all met for <TaskInstance: twitter_dag.complete_twitter_etl scheduled__2020-12-05T00:00:00+00:00 [queued]>
[2023-01-26T08:13:59.256+0000] {taskinstance.py:1279} INFO - 
--------------------------------------------------------------------------------
[2023-01-26T08:13:59.257+0000] {taskinstance.py:1280} INFO - Starting attempt 2 of 2
[2023-01-26T08:13:59.258+0000] {taskinstance.py:1281} INFO - 
--------------------------------------------------------------------------------
[2023-01-26T08:13:59.276+0000] {taskinstance.py:1300} INFO - Executing <Task(PythonOperator): complete_twitter_etl> on 2020-12-05 00:00:00+00:00
[2023-01-26T08:13:59.283+0000] {standard_task_runner.py:55} INFO - Started process 1242 to run task
[2023-01-26T08:13:59.289+0000] {standard_task_runner.py:82} INFO - Running: ['***', 'tasks', 'run', 'twitter_dag', 'complete_twitter_etl', 'scheduled__2020-12-05T00:00:00+00:00', '--job-id', '82', '--raw', '--subdir', 'DAGS_FOLDER/twitter_dag.py', '--cfg-path', '/tmp/tmphvdnnsf6']
[2023-01-26T08:13:59.291+0000] {standard_task_runner.py:83} INFO - Job 82: Subtask complete_twitter_etl
[2023-01-26T08:13:59.593+0000] {task_command.py:388} INFO - Running <TaskInstance: twitter_dag.complete_twitter_etl scheduled__2020-12-05T00:00:00+00:00 [running]> on host 3143b9e5b257
[2023-01-26T08:13:59.689+0000] {taskinstance.py:1509} INFO - Exporting the following env vars:
AIRFLOW_CTX_DAG_EMAIL=***@example.com
AIRFLOW_CTX_DAG_OWNER=***
AIRFLOW_CTX_DAG_ID=twitter_dag
AIRFLOW_CTX_TASK_ID=complete_twitter_etl
AIRFLOW_CTX_EXECUTION_DATE=2020-12-05T00:00:00+00:00
AIRFLOW_CTX_TRY_NUMBER=2
AIRFLOW_CTX_DAG_RUN_ID=scheduled__2020-12-05T00:00:00+00:00
[2023-01-26T08:14:00.656+0000] {taskinstance.py:1768} ERROR - Task failed with exception
Traceback (most recent call last):
  File "/home/airflow/.local/lib/python3.7/site-packages/airflow/operators/python.py", line 175, in execute
    return_value = self.execute_callable()
  File "/home/airflow/.local/lib/python3.7/site-packages/airflow/operators/python.py", line 192, in execute_callable
    return self.python_callable(*self.op_args, **self.op_kwargs)
  File "/opt/airflow/dags/twitter_etl.py", line 64, in run_twitter_etl
    s3.Object(BUCKET_NAME, KEY).put(Body=csv_buffer.getvalue())
  File "/home/airflow/.local/lib/python3.7/site-packages/boto3/resources/factory.py", line 580, in do_action
    response = action(self, *args, **kwargs)
  File "/home/airflow/.local/lib/python3.7/site-packages/boto3/resources/action.py", line 88, in __call__
    response = getattr(parent.meta.client, operation_name)(*args, **params)
  File "/home/airflow/.local/lib/python3.7/site-packages/botocore/client.py", line 508, in _api_call
    return self._make_api_call(operation_name, kwargs)
  File "/home/airflow/.local/lib/python3.7/site-packages/botocore/client.py", line 915, in _make_api_call
    raise error_class(parsed_response, operation_name)
botocore.exceptions.ClientError: An error occurred (InvalidAccessKeyId) when calling the PutObject operation: The AWS Access Key Id you provided does not exist in our records.
[2023-01-26T08:14:00.671+0000] {taskinstance.py:1323} INFO - Marking task as FAILED. dag_id=twitter_dag, task_id=complete_twitter_etl, execution_date=20201205T000000, start_date=20230126T081359, end_date=20230126T081400
[2023-01-26T08:14:00.690+0000] {standard_task_runner.py:105} ERROR - Failed to execute job 82 for task complete_twitter_etl (An error occurred (InvalidAccessKeyId) when calling the PutObject operation: The AWS Access Key Id you provided does not exist in our records.; 1242)
[2023-01-26T08:14:00.764+0000] {local_task_job.py:208} INFO - Task exited with return code 1
[2023-01-26T08:14:00.855+0000] {taskinstance.py:2578} INFO - 0 downstream tasks scheduled from follow-on schedule check
