[2023-01-25T18:44:13.215+0000] {taskinstance.py:1083} INFO - Dependencies all met for <TaskInstance: twitter_dag.complete_twitter_etl scheduled__2020-12-05T00:00:00+00:00 [queued]>
[2023-01-25T18:44:13.558+0000] {taskinstance.py:1083} INFO - Dependencies all met for <TaskInstance: twitter_dag.complete_twitter_etl scheduled__2020-12-05T00:00:00+00:00 [queued]>
[2023-01-25T18:44:13.572+0000] {taskinstance.py:1279} INFO - 
--------------------------------------------------------------------------------
[2023-01-25T18:44:13.576+0000] {taskinstance.py:1280} INFO - Starting attempt 1 of 2
[2023-01-25T18:44:13.593+0000] {taskinstance.py:1281} INFO - 
--------------------------------------------------------------------------------
[2023-01-25T18:44:13.804+0000] {taskinstance.py:1300} INFO - Executing <Task(PythonOperator): complete_twitter_etl> on 2020-12-05 00:00:00+00:00
[2023-01-25T18:44:14.069+0000] {standard_task_runner.py:55} INFO - Started process 672 to run task
[2023-01-25T18:44:14.364+0000] {standard_task_runner.py:82} INFO - Running: ['***', 'tasks', 'run', 'twitter_dag', 'complete_twitter_etl', 'scheduled__2020-12-05T00:00:00+00:00', '--job-id', '48', '--raw', '--subdir', 'DAGS_FOLDER/twitter_dag.py', '--cfg-path', '/tmp/tmphr5buik4']
[2023-01-25T18:44:14.396+0000] {standard_task_runner.py:83} INFO - Job 48: Subtask complete_twitter_etl
[2023-01-25T18:44:16.669+0000] {task_command.py:388} INFO - Running <TaskInstance: twitter_dag.complete_twitter_etl scheduled__2020-12-05T00:00:00+00:00 [running]> on host 512d0ff0785b
[2023-01-25T18:44:23.429+0000] {taskinstance.py:1509} INFO - Exporting the following env vars:
AIRFLOW_CTX_DAG_EMAIL=***@example.com
AIRFLOW_CTX_DAG_OWNER=***
AIRFLOW_CTX_DAG_ID=twitter_dag
AIRFLOW_CTX_TASK_ID=complete_twitter_etl
AIRFLOW_CTX_EXECUTION_DATE=2020-12-05T00:00:00+00:00
AIRFLOW_CTX_TRY_NUMBER=1
AIRFLOW_CTX_DAG_RUN_ID=scheduled__2020-12-05T00:00:00+00:00
[2023-01-25T18:44:36.226+0000] {taskinstance.py:1768} ERROR - Task failed with exception
Traceback (most recent call last):
  File "/home/airflow/.local/lib/python3.7/site-packages/s3fs/core.py", line 112, in _error_wrapper
    return await func(*args, **kwargs)
  File "/home/airflow/.local/lib/python3.7/site-packages/aiobotocore/client.py", line 358, in _make_api_call
    raise error_class(parsed_response, operation_name)
botocore.exceptions.ClientError: An error occurred (AccessDenied) when calling the CreateBucket operation: Anonymous access is forbidden for this operation

The above exception was the direct cause of the following exception:

Traceback (most recent call last):
  File "/home/airflow/.local/lib/python3.7/site-packages/airflow/operators/python.py", line 175, in execute
    return_value = self.execute_callable()
  File "/home/airflow/.local/lib/python3.7/site-packages/airflow/operators/python.py", line 192, in execute_callable
    return self.python_callable(*self.op_args, **self.op_kwargs)
  File "/opt/airflow/dags/twitter_etl.py", line 46, in run_twitter_etl
    df.to_csv("s3://jinchoi-airflow-bucket/data/elonmusk_tweets.csv")
  File "/home/airflow/.local/lib/python3.7/site-packages/pandas/core/generic.py", line 3482, in to_csv
    storage_options=storage_options,
  File "/home/airflow/.local/lib/python3.7/site-packages/pandas/io/formats/format.py", line 1105, in to_csv
    csv_formatter.save()
  File "/home/airflow/.local/lib/python3.7/site-packages/pandas/io/formats/csvs.py", line 243, in save
    storage_options=self.storage_options,
  File "/home/airflow/.local/lib/python3.7/site-packages/pandas/io/common.py", line 614, in get_handle
    storage_options=storage_options,
  File "/home/airflow/.local/lib/python3.7/site-packages/pandas/io/common.py", line 370, in _get_filepath_or_buffer
    filepath_or_buffer, mode=fsspec_mode, **(storage_options or {})
  File "/home/airflow/.local/lib/python3.7/site-packages/fsspec/core.py", line 428, in open
    **kwargs,
  File "/home/airflow/.local/lib/python3.7/site-packages/fsspec/core.py", line 283, in open_files
    [fs.makedirs(parent, exist_ok=True) for parent in parents]
  File "/home/airflow/.local/lib/python3.7/site-packages/fsspec/core.py", line 283, in <listcomp>
    [fs.makedirs(parent, exist_ok=True) for parent in parents]
  File "/home/airflow/.local/lib/python3.7/site-packages/fsspec/asyn.py", line 114, in wrapper
    return sync(self.loop, func, *args, **kwargs)
  File "/home/airflow/.local/lib/python3.7/site-packages/fsspec/asyn.py", line 99, in sync
    raise return_result
  File "/home/airflow/.local/lib/python3.7/site-packages/fsspec/asyn.py", line 54, in _runner
    result[0] = await coro
  File "/home/airflow/.local/lib/python3.7/site-packages/s3fs/core.py", line 883, in _makedirs
    await self._mkdir(path, create_parents=True)
  File "/home/airflow/.local/lib/python3.7/site-packages/s3fs/core.py", line 868, in _mkdir
    await self._call_s3("create_bucket", **params)
  File "/home/airflow/.local/lib/python3.7/site-packages/s3fs/core.py", line 340, in _call_s3
    method, kwargs=additional_kwargs, retries=self.retries
  File "/home/airflow/.local/lib/python3.7/site-packages/s3fs/core.py", line 139, in _error_wrapper
    raise err
PermissionError: Anonymous access is forbidden for this operation
[2023-01-25T18:44:36.322+0000] {taskinstance.py:1323} INFO - Marking task as UP_FOR_RETRY. dag_id=twitter_dag, task_id=complete_twitter_etl, execution_date=20201205T000000, start_date=20230125T184413, end_date=20230125T184436
[2023-01-25T18:44:36.664+0000] {standard_task_runner.py:105} ERROR - Failed to execute job 48 for task complete_twitter_etl (Anonymous access is forbidden for this operation; 672)
[2023-01-25T18:44:36.804+0000] {local_task_job.py:208} INFO - Task exited with return code 1
[2023-01-25T18:44:36.955+0000] {taskinstance.py:2578} INFO - 0 downstream tasks scheduled from follow-on schedule check
[2023-01-26T03:24:19.328+0000] {taskinstance.py:1083} INFO - Dependencies all met for <TaskInstance: twitter_dag.complete_twitter_etl scheduled__2020-12-05T00:00:00+00:00 [queued]>
[2023-01-26T03:24:19.451+0000] {taskinstance.py:1083} INFO - Dependencies all met for <TaskInstance: twitter_dag.complete_twitter_etl scheduled__2020-12-05T00:00:00+00:00 [queued]>
[2023-01-26T03:24:19.453+0000] {taskinstance.py:1279} INFO - 
--------------------------------------------------------------------------------
[2023-01-26T03:24:19.461+0000] {taskinstance.py:1280} INFO - Starting attempt 1 of 2
[2023-01-26T03:24:19.463+0000] {taskinstance.py:1281} INFO - 
--------------------------------------------------------------------------------
[2023-01-26T03:24:19.661+0000] {taskinstance.py:1300} INFO - Executing <Task(PythonOperator): complete_twitter_etl> on 2020-12-05 00:00:00+00:00
[2023-01-26T03:24:19.728+0000] {standard_task_runner.py:55} INFO - Started process 362 to run task
[2023-01-26T03:24:19.775+0000] {standard_task_runner.py:82} INFO - Running: ['***', 'tasks', 'run', 'twitter_dag', 'complete_twitter_etl', 'scheduled__2020-12-05T00:00:00+00:00', '--job-id', '47', '--raw', '--subdir', 'DAGS_FOLDER/twitter_dag.py', '--cfg-path', '/tmp/tmp3n22c930']
[2023-01-26T03:24:19.795+0000] {standard_task_runner.py:83} INFO - Job 47: Subtask complete_twitter_etl
[2023-01-26T03:24:20.607+0000] {task_command.py:388} INFO - Running <TaskInstance: twitter_dag.complete_twitter_etl scheduled__2020-12-05T00:00:00+00:00 [running]> on host 3db080823b1b
[2023-01-26T03:24:22.856+0000] {taskinstance.py:1509} INFO - Exporting the following env vars:
AIRFLOW_CTX_DAG_EMAIL=***@example.com
AIRFLOW_CTX_DAG_OWNER=***
AIRFLOW_CTX_DAG_ID=twitter_dag
AIRFLOW_CTX_TASK_ID=complete_twitter_etl
AIRFLOW_CTX_EXECUTION_DATE=2020-12-05T00:00:00+00:00
AIRFLOW_CTX_TRY_NUMBER=1
AIRFLOW_CTX_DAG_RUN_ID=scheduled__2020-12-05T00:00:00+00:00
[2023-01-26T03:24:24.304+0000] {taskinstance.py:1768} ERROR - Task failed with exception
Traceback (most recent call last):
  File "/home/airflow/.local/lib/python3.7/site-packages/airflow/operators/python.py", line 175, in execute
    return_value = self.execute_callable()
  File "/home/airflow/.local/lib/python3.7/site-packages/airflow/operators/python.py", line 192, in execute_callable
    return self.python_callable(*self.op_args, **self.op_kwargs)
  File "/opt/airflow/dags/twitter_etl.py", line 53, in run_twitter_etl
    df.to_csv('s3://{BUCKET_NAME}/data/{KEY}', index=False, header=False,sep=',', engine='python', filesystem=s3)
TypeError: to_csv() got an unexpected keyword argument 'engine'
[2023-01-26T03:24:24.328+0000] {taskinstance.py:1323} INFO - Marking task as UP_FOR_RETRY. dag_id=twitter_dag, task_id=complete_twitter_etl, execution_date=20201205T000000, start_date=20230126T032419, end_date=20230126T032424
[2023-01-26T03:24:24.373+0000] {standard_task_runner.py:105} ERROR - Failed to execute job 47 for task complete_twitter_etl (to_csv() got an unexpected keyword argument 'engine'; 362)
[2023-01-26T03:24:24.455+0000] {local_task_job.py:208} INFO - Task exited with return code 1
[2023-01-26T03:24:24.497+0000] {taskinstance.py:2578} INFO - 0 downstream tasks scheduled from follow-on schedule check
[2023-01-26T03:35:42.273+0000] {taskinstance.py:1083} INFO - Dependencies all met for <TaskInstance: twitter_dag.complete_twitter_etl scheduled__2020-12-05T00:00:00+00:00 [queued]>
[2023-01-26T03:35:42.314+0000] {taskinstance.py:1083} INFO - Dependencies all met for <TaskInstance: twitter_dag.complete_twitter_etl scheduled__2020-12-05T00:00:00+00:00 [queued]>
[2023-01-26T03:35:42.318+0000] {taskinstance.py:1279} INFO - 
--------------------------------------------------------------------------------
[2023-01-26T03:35:42.326+0000] {taskinstance.py:1280} INFO - Starting attempt 1 of 2
[2023-01-26T03:35:42.328+0000] {taskinstance.py:1281} INFO - 
--------------------------------------------------------------------------------
[2023-01-26T03:35:42.403+0000] {taskinstance.py:1300} INFO - Executing <Task(PythonOperator): complete_twitter_etl> on 2020-12-05 00:00:00+00:00
[2023-01-26T03:35:42.427+0000] {standard_task_runner.py:55} INFO - Started process 356 to run task
[2023-01-26T03:35:42.447+0000] {standard_task_runner.py:82} INFO - Running: ['***', 'tasks', 'run', 'twitter_dag', 'complete_twitter_etl', 'scheduled__2020-12-05T00:00:00+00:00', '--job-id', '46', '--raw', '--subdir', 'DAGS_FOLDER/twitter_dag.py', '--cfg-path', '/tmp/tmp20svmpex']
[2023-01-26T03:35:42.449+0000] {standard_task_runner.py:83} INFO - Job 46: Subtask complete_twitter_etl
[2023-01-26T03:35:42.762+0000] {task_command.py:388} INFO - Running <TaskInstance: twitter_dag.complete_twitter_etl scheduled__2020-12-05T00:00:00+00:00 [running]> on host 9c4f31e2db2b
[2023-01-26T03:35:44.239+0000] {taskinstance.py:1509} INFO - Exporting the following env vars:
AIRFLOW_CTX_DAG_EMAIL=***@example.com
AIRFLOW_CTX_DAG_OWNER=***
AIRFLOW_CTX_DAG_ID=twitter_dag
AIRFLOW_CTX_TASK_ID=complete_twitter_etl
AIRFLOW_CTX_EXECUTION_DATE=2020-12-05T00:00:00+00:00
AIRFLOW_CTX_TRY_NUMBER=1
AIRFLOW_CTX_DAG_RUN_ID=scheduled__2020-12-05T00:00:00+00:00
[2023-01-26T03:35:45.256+0000] {taskinstance.py:1768} ERROR - Task failed with exception
Traceback (most recent call last):
  File "/home/airflow/.local/lib/python3.7/site-packages/airflow/operators/python.py", line 175, in execute
    return_value = self.execute_callable()
  File "/home/airflow/.local/lib/python3.7/site-packages/airflow/operators/python.py", line 192, in execute_callable
    return self.python_callable(*self.op_args, **self.op_kwargs)
  File "/opt/airflow/dags/twitter_etl.py", line 54, in run_twitter_etl
    s3.put('s3://{BUCKET_NAME}/data/{KEY}', csv_buffer)
  File "/home/airflow/.local/lib/python3.7/site-packages/fsspec/asyn.py", line 114, in wrapper
    return sync(self.loop, func, *args, **kwargs)
  File "/home/airflow/.local/lib/python3.7/site-packages/fsspec/asyn.py", line 99, in sync
    raise return_result
  File "/home/airflow/.local/lib/python3.7/site-packages/fsspec/asyn.py", line 54, in _runner
    result[0] = await coro
  File "/home/airflow/.local/lib/python3.7/site-packages/fsspec/asyn.py", line 481, in _put
    rpath = self._strip_protocol(rpath)
  File "/home/airflow/.local/lib/python3.7/site-packages/fsspec/spec.py", line 188, in _strip_protocol
    if path.startswith(protocol + "://"):
TypeError: startswith first arg must be bytes or a tuple of bytes, not str
[2023-01-26T03:35:45.279+0000] {taskinstance.py:1323} INFO - Marking task as UP_FOR_RETRY. dag_id=twitter_dag, task_id=complete_twitter_etl, execution_date=20201205T000000, start_date=20230126T033542, end_date=20230126T033545
[2023-01-26T03:35:45.336+0000] {standard_task_runner.py:105} ERROR - Failed to execute job 46 for task complete_twitter_etl (startswith first arg must be bytes or a tuple of bytes, not str; 356)
[2023-01-26T03:35:45.389+0000] {local_task_job.py:208} INFO - Task exited with return code 1
[2023-01-26T03:35:45.434+0000] {taskinstance.py:2578} INFO - 0 downstream tasks scheduled from follow-on schedule check
[2023-01-26T06:05:12.545+0000] {taskinstance.py:1083} INFO - Dependencies all met for <TaskInstance: twitter_dag.complete_twitter_etl scheduled__2020-12-05T00:00:00+00:00 [queued]>
[2023-01-26T06:05:12.637+0000] {taskinstance.py:1083} INFO - Dependencies all met for <TaskInstance: twitter_dag.complete_twitter_etl scheduled__2020-12-05T00:00:00+00:00 [queued]>
[2023-01-26T06:05:12.639+0000] {taskinstance.py:1279} INFO - 
--------------------------------------------------------------------------------
[2023-01-26T06:05:12.643+0000] {taskinstance.py:1280} INFO - Starting attempt 1 of 2
[2023-01-26T06:05:12.648+0000] {taskinstance.py:1281} INFO - 
--------------------------------------------------------------------------------
[2023-01-26T06:05:12.796+0000] {taskinstance.py:1300} INFO - Executing <Task(PythonOperator): complete_twitter_etl> on 2020-12-05 00:00:00+00:00
[2023-01-26T06:05:12.834+0000] {standard_task_runner.py:55} INFO - Started process 1215 to run task
[2023-01-26T06:05:12.855+0000] {standard_task_runner.py:82} INFO - Running: ['***', 'tasks', 'run', 'twitter_dag', 'complete_twitter_etl', 'scheduled__2020-12-05T00:00:00+00:00', '--job-id', '46', '--raw', '--subdir', 'DAGS_FOLDER/twitter_dag.py', '--cfg-path', '/tmp/tmpg4le74dj']
[2023-01-26T06:05:12.881+0000] {standard_task_runner.py:83} INFO - Job 46: Subtask complete_twitter_etl
[2023-01-26T06:05:14.020+0000] {task_command.py:388} INFO - Running <TaskInstance: twitter_dag.complete_twitter_etl scheduled__2020-12-05T00:00:00+00:00 [running]> on host 864c120ca3c2
[2023-01-26T06:05:14.345+0000] {taskinstance.py:1509} INFO - Exporting the following env vars:
AIRFLOW_CTX_DAG_EMAIL=***@example.com
AIRFLOW_CTX_DAG_OWNER=***
AIRFLOW_CTX_DAG_ID=twitter_dag
AIRFLOW_CTX_TASK_ID=complete_twitter_etl
AIRFLOW_CTX_EXECUTION_DATE=2020-12-05T00:00:00+00:00
AIRFLOW_CTX_TRY_NUMBER=1
AIRFLOW_CTX_DAG_RUN_ID=scheduled__2020-12-05T00:00:00+00:00
[2023-01-26T06:05:14.998+0000] {taskinstance.py:1768} ERROR - Task failed with exception
Traceback (most recent call last):
  File "/home/airflow/.local/lib/python3.7/site-packages/airflow/operators/python.py", line 175, in execute
    return_value = self.execute_callable()
  File "/home/airflow/.local/lib/python3.7/site-packages/airflow/operators/python.py", line 192, in execute_callable
    return self.python_callable(*self.op_args, **self.op_kwargs)
  File "/opt/airflow/dags/twitter_etl.py", line 51, in run_twitter_etl
    aws_access_key_id=os.environ['AWS_ACCESS_KEY_ID'],
  File "/usr/local/lib/python3.7/os.py", line 681, in __getitem__
    raise KeyError(key) from None
KeyError: 'AWS_ACCESS_KEY_ID'
[2023-01-26T06:05:15.032+0000] {taskinstance.py:1323} INFO - Marking task as UP_FOR_RETRY. dag_id=twitter_dag, task_id=complete_twitter_etl, execution_date=20201205T000000, start_date=20230126T060512, end_date=20230126T060515
[2023-01-26T06:05:15.055+0000] {standard_task_runner.py:105} ERROR - Failed to execute job 46 for task complete_twitter_etl ('AWS_ACCESS_KEY_ID'; 1215)
[2023-01-26T06:05:15.130+0000] {local_task_job.py:208} INFO - Task exited with return code 1
[2023-01-26T06:05:15.180+0000] {taskinstance.py:2578} INFO - 0 downstream tasks scheduled from follow-on schedule check
[2023-01-26T07:05:12.427+0000] {taskinstance.py:1083} INFO - Dependencies all met for <TaskInstance: twitter_dag.complete_twitter_etl scheduled__2020-12-05T00:00:00+00:00 [queued]>
[2023-01-26T07:05:12.553+0000] {taskinstance.py:1083} INFO - Dependencies all met for <TaskInstance: twitter_dag.complete_twitter_etl scheduled__2020-12-05T00:00:00+00:00 [queued]>
[2023-01-26T07:05:12.555+0000] {taskinstance.py:1279} INFO - 
--------------------------------------------------------------------------------
[2023-01-26T07:05:12.557+0000] {taskinstance.py:1280} INFO - Starting attempt 1 of 2
[2023-01-26T07:05:12.559+0000] {taskinstance.py:1281} INFO - 
--------------------------------------------------------------------------------
[2023-01-26T07:05:12.631+0000] {taskinstance.py:1300} INFO - Executing <Task(PythonOperator): complete_twitter_etl> on 2020-12-05 00:00:00+00:00
[2023-01-26T07:05:12.659+0000] {standard_task_runner.py:55} INFO - Started process 541 to run task
[2023-01-26T07:05:12.695+0000] {standard_task_runner.py:82} INFO - Running: ['***', 'tasks', 'run', 'twitter_dag', 'complete_twitter_etl', 'scheduled__2020-12-05T00:00:00+00:00', '--job-id', '49', '--raw', '--subdir', 'DAGS_FOLDER/twitter_dag.py', '--cfg-path', '/tmp/tmpkff0vr74']
[2023-01-26T07:05:12.727+0000] {standard_task_runner.py:83} INFO - Job 49: Subtask complete_twitter_etl
[2023-01-26T07:05:13.691+0000] {task_command.py:388} INFO - Running <TaskInstance: twitter_dag.complete_twitter_etl scheduled__2020-12-05T00:00:00+00:00 [running]> on host 2221c1ebf970
[2023-01-26T07:05:13.965+0000] {taskinstance.py:1509} INFO - Exporting the following env vars:
AIRFLOW_CTX_DAG_EMAIL=***@example.com
AIRFLOW_CTX_DAG_OWNER=***
AIRFLOW_CTX_DAG_ID=twitter_dag
AIRFLOW_CTX_TASK_ID=complete_twitter_etl
AIRFLOW_CTX_EXECUTION_DATE=2020-12-05T00:00:00+00:00
AIRFLOW_CTX_TRY_NUMBER=1
AIRFLOW_CTX_DAG_RUN_ID=scheduled__2020-12-05T00:00:00+00:00
[2023-01-26T07:05:14.634+0000] {taskinstance.py:1768} ERROR - Task failed with exception
Traceback (most recent call last):
  File "/home/airflow/.local/lib/python3.7/site-packages/airflow/operators/python.py", line 175, in execute
    return_value = self.execute_callable()
  File "/home/airflow/.local/lib/python3.7/site-packages/airflow/operators/python.py", line 192, in execute_callable
    return self.python_callable(*self.op_args, **self.op_kwargs)
  File "/opt/airflow/dags/twitter_etl.py", line 63, in run_twitter_etl
    s3.Object(BUCKET_NAME, KEY).put(Body=csv_buffer.getvalue())
  File "/home/airflow/.local/lib/python3.7/site-packages/botocore/client.py", line 839, in __getattr__
    f"'{self.__class__.__name__}' object has no attribute '{item}'"
AttributeError: 'S3' object has no attribute 'Object'
[2023-01-26T07:05:14.650+0000] {taskinstance.py:1323} INFO - Marking task as UP_FOR_RETRY. dag_id=twitter_dag, task_id=complete_twitter_etl, execution_date=20201205T000000, start_date=20230126T070512, end_date=20230126T070514
[2023-01-26T07:05:14.666+0000] {standard_task_runner.py:105} ERROR - Failed to execute job 49 for task complete_twitter_etl ('S3' object has no attribute 'Object'; 541)
[2023-01-26T07:05:14.711+0000] {local_task_job.py:208} INFO - Task exited with return code 1
[2023-01-26T07:05:14.920+0000] {taskinstance.py:2578} INFO - 0 downstream tasks scheduled from follow-on schedule check
[2023-01-26T08:08:54.906+0000] {taskinstance.py:1083} INFO - Dependencies all met for <TaskInstance: twitter_dag.complete_twitter_etl scheduled__2020-12-05T00:00:00+00:00 [queued]>
[2023-01-26T08:08:54.931+0000] {taskinstance.py:1083} INFO - Dependencies all met for <TaskInstance: twitter_dag.complete_twitter_etl scheduled__2020-12-05T00:00:00+00:00 [queued]>
[2023-01-26T08:08:54.933+0000] {taskinstance.py:1279} INFO - 
--------------------------------------------------------------------------------
[2023-01-26T08:08:54.935+0000] {taskinstance.py:1280} INFO - Starting attempt 1 of 2
[2023-01-26T08:08:54.936+0000] {taskinstance.py:1281} INFO - 
--------------------------------------------------------------------------------
[2023-01-26T08:08:54.971+0000] {taskinstance.py:1300} INFO - Executing <Task(PythonOperator): complete_twitter_etl> on 2020-12-05 00:00:00+00:00
[2023-01-26T08:08:54.984+0000] {standard_task_runner.py:55} INFO - Started process 885 to run task
[2023-01-26T08:08:54.993+0000] {standard_task_runner.py:82} INFO - Running: ['***', 'tasks', 'run', 'twitter_dag', 'complete_twitter_etl', 'scheduled__2020-12-05T00:00:00+00:00', '--job-id', '51', '--raw', '--subdir', 'DAGS_FOLDER/twitter_dag.py', '--cfg-path', '/tmp/tmp0vvzd44b']
[2023-01-26T08:08:54.995+0000] {standard_task_runner.py:83} INFO - Job 51: Subtask complete_twitter_etl
[2023-01-26T08:08:55.490+0000] {task_command.py:388} INFO - Running <TaskInstance: twitter_dag.complete_twitter_etl scheduled__2020-12-05T00:00:00+00:00 [running]> on host 3143b9e5b257
[2023-01-26T08:08:55.635+0000] {taskinstance.py:1509} INFO - Exporting the following env vars:
AIRFLOW_CTX_DAG_EMAIL=***@example.com
AIRFLOW_CTX_DAG_OWNER=***
AIRFLOW_CTX_DAG_ID=twitter_dag
AIRFLOW_CTX_TASK_ID=complete_twitter_etl
AIRFLOW_CTX_EXECUTION_DATE=2020-12-05T00:00:00+00:00
AIRFLOW_CTX_TRY_NUMBER=1
AIRFLOW_CTX_DAG_RUN_ID=scheduled__2020-12-05T00:00:00+00:00
[2023-01-26T08:08:57.082+0000] {taskinstance.py:1768} ERROR - Task failed with exception
Traceback (most recent call last):
  File "/home/airflow/.local/lib/python3.7/site-packages/airflow/operators/python.py", line 175, in execute
    return_value = self.execute_callable()
  File "/home/airflow/.local/lib/python3.7/site-packages/airflow/operators/python.py", line 192, in execute_callable
    return self.python_callable(*self.op_args, **self.op_kwargs)
  File "/opt/airflow/dags/twitter_etl.py", line 64, in run_twitter_etl
    s3.Object(BUCKET_NAME, KEY).put(Body=csv_buffer.getvalue())
  File "/home/airflow/.local/lib/python3.7/site-packages/boto3/resources/factory.py", line 580, in do_action
    response = action(self, *args, **kwargs)
  File "/home/airflow/.local/lib/python3.7/site-packages/boto3/resources/action.py", line 88, in __call__
    response = getattr(parent.meta.client, operation_name)(*args, **params)
  File "/home/airflow/.local/lib/python3.7/site-packages/botocore/client.py", line 508, in _api_call
    return self._make_api_call(operation_name, kwargs)
  File "/home/airflow/.local/lib/python3.7/site-packages/botocore/client.py", line 915, in _make_api_call
    raise error_class(parsed_response, operation_name)
botocore.exceptions.ClientError: An error occurred (InvalidAccessKeyId) when calling the PutObject operation: The AWS Access Key Id you provided does not exist in our records.
[2023-01-26T08:08:57.130+0000] {taskinstance.py:1323} INFO - Marking task as UP_FOR_RETRY. dag_id=twitter_dag, task_id=complete_twitter_etl, execution_date=20201205T000000, start_date=20230126T080854, end_date=20230126T080857
[2023-01-26T08:08:57.208+0000] {standard_task_runner.py:105} ERROR - Failed to execute job 51 for task complete_twitter_etl (An error occurred (InvalidAccessKeyId) when calling the PutObject operation: The AWS Access Key Id you provided does not exist in our records.; 885)
[2023-01-26T08:08:57.431+0000] {local_task_job.py:208} INFO - Task exited with return code 1
[2023-01-26T08:08:58.324+0000] {taskinstance.py:2578} INFO - 0 downstream tasks scheduled from follow-on schedule check
[2023-01-26T09:08:44.135+0000] {taskinstance.py:1083} INFO - Dependencies all met for <TaskInstance: twitter_dag.complete_twitter_etl scheduled__2020-12-05T00:00:00+00:00 [queued]>
[2023-01-26T09:08:44.419+0000] {taskinstance.py:1083} INFO - Dependencies all met for <TaskInstance: twitter_dag.complete_twitter_etl scheduled__2020-12-05T00:00:00+00:00 [queued]>
[2023-01-26T09:08:44.423+0000] {taskinstance.py:1279} INFO - 
--------------------------------------------------------------------------------
[2023-01-26T09:08:44.428+0000] {taskinstance.py:1280} INFO - Starting attempt 1 of 2
[2023-01-26T09:08:44.433+0000] {taskinstance.py:1281} INFO - 
--------------------------------------------------------------------------------
[2023-01-26T09:08:44.691+0000] {taskinstance.py:1300} INFO - Executing <Task(PythonOperator): complete_twitter_etl> on 2020-12-05 00:00:00+00:00
[2023-01-26T09:08:44.844+0000] {standard_task_runner.py:55} INFO - Started process 237 to run task
[2023-01-26T09:08:45.136+0000] {standard_task_runner.py:82} INFO - Running: ['***', 'tasks', 'run', 'twitter_dag', 'complete_twitter_etl', 'scheduled__2020-12-05T00:00:00+00:00', '--job-id', '31', '--raw', '--subdir', 'DAGS_FOLDER/twitter_dag.py', '--cfg-path', '/tmp/tmpfeaeb2j2']
[2023-01-26T09:08:45.158+0000] {standard_task_runner.py:83} INFO - Job 31: Subtask complete_twitter_etl
[2023-01-26T09:08:48.582+0000] {task_command.py:388} INFO - Running <TaskInstance: twitter_dag.complete_twitter_etl scheduled__2020-12-05T00:00:00+00:00 [running]> on host d0fc3b00c15c
[2023-01-26T09:08:49.317+0000] {taskinstance.py:1509} INFO - Exporting the following env vars:
AIRFLOW_CTX_DAG_EMAIL=***@example.com
AIRFLOW_CTX_DAG_OWNER=***
AIRFLOW_CTX_DAG_ID=twitter_dag
AIRFLOW_CTX_TASK_ID=complete_twitter_etl
AIRFLOW_CTX_EXECUTION_DATE=2020-12-05T00:00:00+00:00
AIRFLOW_CTX_TRY_NUMBER=1
AIRFLOW_CTX_DAG_RUN_ID=scheduled__2020-12-05T00:00:00+00:00
[2023-01-26T09:08:51.411+0000] {python.py:177} INFO - Done. Returned value was: None
[2023-01-26T09:08:51.449+0000] {taskinstance.py:1323} INFO - Marking task as SUCCESS. dag_id=twitter_dag, task_id=complete_twitter_etl, execution_date=20201205T000000, start_date=20230126T090844, end_date=20230126T090851
[2023-01-26T09:08:51.568+0000] {local_task_job.py:208} INFO - Task exited with return code 0
[2023-01-26T09:08:52.199+0000] {taskinstance.py:2578} INFO - 0 downstream tasks scheduled from follow-on schedule check
