[2023-01-25T18:58:47.094+0000] {taskinstance.py:1083} INFO - Dependencies all met for <TaskInstance: twitter_dag.complete_twitter_etl scheduled__2021-03-16T00:00:00+00:00 [queued]>
[2023-01-25T18:58:47.209+0000] {taskinstance.py:1083} INFO - Dependencies all met for <TaskInstance: twitter_dag.complete_twitter_etl scheduled__2021-03-16T00:00:00+00:00 [queued]>
[2023-01-25T18:58:47.214+0000] {taskinstance.py:1279} INFO - 
--------------------------------------------------------------------------------
[2023-01-25T18:58:47.217+0000] {taskinstance.py:1280} INFO - Starting attempt 1 of 2
[2023-01-25T18:58:47.219+0000] {taskinstance.py:1281} INFO - 
--------------------------------------------------------------------------------
[2023-01-25T18:58:47.428+0000] {taskinstance.py:1300} INFO - Executing <Task(PythonOperator): complete_twitter_etl> on 2021-03-16 00:00:00+00:00
[2023-01-25T18:58:47.488+0000] {standard_task_runner.py:55} INFO - Started process 2498 to run task
[2023-01-25T18:58:47.527+0000] {standard_task_runner.py:82} INFO - Running: ['***', 'tasks', 'run', 'twitter_dag', 'complete_twitter_etl', 'scheduled__2021-03-16T00:00:00+00:00', '--job-id', '252', '--raw', '--subdir', 'DAGS_FOLDER/twitter_dag.py', '--cfg-path', '/tmp/tmppdokmbax']
[2023-01-25T18:58:47.539+0000] {standard_task_runner.py:83} INFO - Job 252: Subtask complete_twitter_etl
[2023-01-25T18:58:48.157+0000] {task_command.py:388} INFO - Running <TaskInstance: twitter_dag.complete_twitter_etl scheduled__2021-03-16T00:00:00+00:00 [running]> on host 512d0ff0785b
[2023-01-25T18:58:50.954+0000] {taskinstance.py:1509} INFO - Exporting the following env vars:
AIRFLOW_CTX_DAG_EMAIL=***@example.com
AIRFLOW_CTX_DAG_OWNER=***
AIRFLOW_CTX_DAG_ID=twitter_dag
AIRFLOW_CTX_TASK_ID=complete_twitter_etl
AIRFLOW_CTX_EXECUTION_DATE=2021-03-16T00:00:00+00:00
AIRFLOW_CTX_TRY_NUMBER=1
AIRFLOW_CTX_DAG_RUN_ID=scheduled__2021-03-16T00:00:00+00:00
[2023-01-25T18:58:59.467+0000] {taskinstance.py:1768} ERROR - Task failed with exception
Traceback (most recent call last):
  File "/home/airflow/.local/lib/python3.7/site-packages/s3fs/core.py", line 112, in _error_wrapper
    return await func(*args, **kwargs)
  File "/home/airflow/.local/lib/python3.7/site-packages/aiobotocore/client.py", line 358, in _make_api_call
    raise error_class(parsed_response, operation_name)
botocore.exceptions.ClientError: An error occurred (AccessDenied) when calling the CreateBucket operation: Anonymous access is forbidden for this operation

The above exception was the direct cause of the following exception:

Traceback (most recent call last):
  File "/home/airflow/.local/lib/python3.7/site-packages/airflow/operators/python.py", line 175, in execute
    return_value = self.execute_callable()
  File "/home/airflow/.local/lib/python3.7/site-packages/airflow/operators/python.py", line 192, in execute_callable
    return self.python_callable(*self.op_args, **self.op_kwargs)
  File "/opt/airflow/dags/twitter_etl.py", line 46, in run_twitter_etl
    df.to_csv("s3://jinchoi-airflow-bucket/data/elonmusk_tweets.csv")
  File "/home/airflow/.local/lib/python3.7/site-packages/pandas/core/generic.py", line 3482, in to_csv
    storage_options=storage_options,
  File "/home/airflow/.local/lib/python3.7/site-packages/pandas/io/formats/format.py", line 1105, in to_csv
    csv_formatter.save()
  File "/home/airflow/.local/lib/python3.7/site-packages/pandas/io/formats/csvs.py", line 243, in save
    storage_options=self.storage_options,
  File "/home/airflow/.local/lib/python3.7/site-packages/pandas/io/common.py", line 614, in get_handle
    storage_options=storage_options,
  File "/home/airflow/.local/lib/python3.7/site-packages/pandas/io/common.py", line 370, in _get_filepath_or_buffer
    filepath_or_buffer, mode=fsspec_mode, **(storage_options or {})
  File "/home/airflow/.local/lib/python3.7/site-packages/fsspec/core.py", line 428, in open
    **kwargs,
  File "/home/airflow/.local/lib/python3.7/site-packages/fsspec/core.py", line 283, in open_files
    [fs.makedirs(parent, exist_ok=True) for parent in parents]
  File "/home/airflow/.local/lib/python3.7/site-packages/fsspec/core.py", line 283, in <listcomp>
    [fs.makedirs(parent, exist_ok=True) for parent in parents]
  File "/home/airflow/.local/lib/python3.7/site-packages/fsspec/asyn.py", line 114, in wrapper
    return sync(self.loop, func, *args, **kwargs)
  File "/home/airflow/.local/lib/python3.7/site-packages/fsspec/asyn.py", line 99, in sync
    raise return_result
  File "/home/airflow/.local/lib/python3.7/site-packages/fsspec/asyn.py", line 54, in _runner
    result[0] = await coro
  File "/home/airflow/.local/lib/python3.7/site-packages/s3fs/core.py", line 883, in _makedirs
    await self._mkdir(path, create_parents=True)
  File "/home/airflow/.local/lib/python3.7/site-packages/s3fs/core.py", line 868, in _mkdir
    await self._call_s3("create_bucket", **params)
  File "/home/airflow/.local/lib/python3.7/site-packages/s3fs/core.py", line 340, in _call_s3
    method, kwargs=additional_kwargs, retries=self.retries
  File "/home/airflow/.local/lib/python3.7/site-packages/s3fs/core.py", line 139, in _error_wrapper
    raise err
PermissionError: Anonymous access is forbidden for this operation
[2023-01-25T18:58:59.641+0000] {taskinstance.py:1323} INFO - Marking task as UP_FOR_RETRY. dag_id=twitter_dag, task_id=complete_twitter_etl, execution_date=20210316T000000, start_date=20230125T185847, end_date=20230125T185859
[2023-01-25T18:58:59.739+0000] {standard_task_runner.py:105} ERROR - Failed to execute job 252 for task complete_twitter_etl (Anonymous access is forbidden for this operation; 2498)
[2023-01-25T18:58:59.924+0000] {local_task_job.py:208} INFO - Task exited with return code 1
[2023-01-25T18:59:00.007+0000] {taskinstance.py:2578} INFO - 0 downstream tasks scheduled from follow-on schedule check
[2023-01-26T06:53:59.748+0000] {taskinstance.py:1083} INFO - Dependencies all met for <TaskInstance: twitter_dag.complete_twitter_etl scheduled__2021-03-16T00:00:00+00:00 [queued]>
[2023-01-26T06:53:59.791+0000] {taskinstance.py:1083} INFO - Dependencies all met for <TaskInstance: twitter_dag.complete_twitter_etl scheduled__2021-03-16T00:00:00+00:00 [queued]>
[2023-01-26T06:53:59.792+0000] {taskinstance.py:1279} INFO - 
--------------------------------------------------------------------------------
[2023-01-26T06:53:59.796+0000] {taskinstance.py:1280} INFO - Starting attempt 1 of 2
[2023-01-26T06:53:59.798+0000] {taskinstance.py:1281} INFO - 
--------------------------------------------------------------------------------
[2023-01-26T06:53:59.851+0000] {taskinstance.py:1300} INFO - Executing <Task(PythonOperator): complete_twitter_etl> on 2021-03-16 00:00:00+00:00
[2023-01-26T06:53:59.879+0000] {standard_task_runner.py:55} INFO - Started process 345 to run task
[2023-01-26T06:53:59.900+0000] {standard_task_runner.py:82} INFO - Running: ['***', 'tasks', 'run', 'twitter_dag', 'complete_twitter_etl', 'scheduled__2021-03-16T00:00:00+00:00', '--job-id', '248', '--raw', '--subdir', 'DAGS_FOLDER/twitter_dag.py', '--cfg-path', '/tmp/tmpzend7ijn']
[2023-01-26T06:53:59.909+0000] {standard_task_runner.py:83} INFO - Job 248: Subtask complete_twitter_etl
[2023-01-26T06:54:00.661+0000] {task_command.py:388} INFO - Running <TaskInstance: twitter_dag.complete_twitter_etl scheduled__2021-03-16T00:00:00+00:00 [running]> on host 47843127de93
[2023-01-26T06:54:00.854+0000] {taskinstance.py:1509} INFO - Exporting the following env vars:
AIRFLOW_CTX_DAG_EMAIL=***@example.com
AIRFLOW_CTX_DAG_OWNER=***
AIRFLOW_CTX_DAG_ID=twitter_dag
AIRFLOW_CTX_TASK_ID=complete_twitter_etl
AIRFLOW_CTX_EXECUTION_DATE=2021-03-16T00:00:00+00:00
AIRFLOW_CTX_TRY_NUMBER=1
AIRFLOW_CTX_DAG_RUN_ID=scheduled__2021-03-16T00:00:00+00:00
[2023-01-26T06:54:01.436+0000] {taskinstance.py:1768} ERROR - Task failed with exception
Traceback (most recent call last):
  File "/home/airflow/.local/lib/python3.7/site-packages/airflow/operators/python.py", line 175, in execute
    return_value = self.execute_callable()
  File "/home/airflow/.local/lib/python3.7/site-packages/airflow/operators/python.py", line 192, in execute_callable
    return self.python_callable(*self.op_args, **self.op_kwargs)
  File "/opt/airflow/dags/twitter_etl.py", line 51, in run_twitter_etl
    aws_access_key_id=os.environ['aws_access_key_id'],
  File "/usr/local/lib/python3.7/os.py", line 681, in __getitem__
    raise KeyError(key) from None
KeyError: 'aws_access_key_id'
[2023-01-26T06:54:01.466+0000] {taskinstance.py:1323} INFO - Marking task as UP_FOR_RETRY. dag_id=twitter_dag, task_id=complete_twitter_etl, execution_date=20210316T000000, start_date=20230126T065359, end_date=20230126T065401
[2023-01-26T06:54:01.510+0000] {standard_task_runner.py:105} ERROR - Failed to execute job 248 for task complete_twitter_etl ('aws_access_key_id'; 345)
[2023-01-26T06:54:01.584+0000] {local_task_job.py:208} INFO - Task exited with return code 1
[2023-01-26T06:54:01.928+0000] {taskinstance.py:2578} INFO - 0 downstream tasks scheduled from follow-on schedule check
[2023-01-26T07:13:47.812+0000] {taskinstance.py:1083} INFO - Dependencies all met for <TaskInstance: twitter_dag.complete_twitter_etl scheduled__2021-03-16T00:00:00+00:00 [queued]>
[2023-01-26T07:13:47.847+0000] {taskinstance.py:1083} INFO - Dependencies all met for <TaskInstance: twitter_dag.complete_twitter_etl scheduled__2021-03-16T00:00:00+00:00 [queued]>
[2023-01-26T07:13:47.849+0000] {taskinstance.py:1279} INFO - 
--------------------------------------------------------------------------------
[2023-01-26T07:13:47.850+0000] {taskinstance.py:1280} INFO - Starting attempt 1 of 2
[2023-01-26T07:13:47.851+0000] {taskinstance.py:1281} INFO - 
--------------------------------------------------------------------------------
[2023-01-26T07:13:47.879+0000] {taskinstance.py:1300} INFO - Executing <Task(PythonOperator): complete_twitter_etl> on 2021-03-16 00:00:00+00:00
[2023-01-26T07:13:47.898+0000] {standard_task_runner.py:55} INFO - Started process 1304 to run task
[2023-01-26T07:13:47.915+0000] {standard_task_runner.py:82} INFO - Running: ['***', 'tasks', 'run', 'twitter_dag', 'complete_twitter_etl', 'scheduled__2021-03-16T00:00:00+00:00', '--job-id', '167', '--raw', '--subdir', 'DAGS_FOLDER/twitter_dag.py', '--cfg-path', '/tmp/tmpw8f7tqn3']
[2023-01-26T07:13:47.918+0000] {standard_task_runner.py:83} INFO - Job 167: Subtask complete_twitter_etl
[2023-01-26T07:13:49.500+0000] {task_command.py:388} INFO - Running <TaskInstance: twitter_dag.complete_twitter_etl scheduled__2021-03-16T00:00:00+00:00 [running]> on host 2221c1ebf970
[2023-01-26T07:13:49.829+0000] {taskinstance.py:1509} INFO - Exporting the following env vars:
AIRFLOW_CTX_DAG_EMAIL=***@example.com
AIRFLOW_CTX_DAG_OWNER=***
AIRFLOW_CTX_DAG_ID=twitter_dag
AIRFLOW_CTX_TASK_ID=complete_twitter_etl
AIRFLOW_CTX_EXECUTION_DATE=2021-03-16T00:00:00+00:00
AIRFLOW_CTX_TRY_NUMBER=1
AIRFLOW_CTX_DAG_RUN_ID=scheduled__2021-03-16T00:00:00+00:00
[2023-01-26T07:13:51.379+0000] {python.py:177} INFO - Done. Returned value was: None
[2023-01-26T07:13:51.402+0000] {taskinstance.py:1323} INFO - Marking task as SUCCESS. dag_id=twitter_dag, task_id=complete_twitter_etl, execution_date=20210316T000000, start_date=20230126T071347, end_date=20230126T071351
[2023-01-26T07:13:51.479+0000] {local_task_job.py:208} INFO - Task exited with return code 0
[2023-01-26T07:13:51.539+0000] {taskinstance.py:2578} INFO - 0 downstream tasks scheduled from follow-on schedule check
[2023-01-26T09:11:38.034+0000] {taskinstance.py:1083} INFO - Dependencies all met for <TaskInstance: twitter_dag.complete_twitter_etl scheduled__2021-03-16T00:00:00+00:00 [queued]>
[2023-01-26T09:11:38.179+0000] {taskinstance.py:1083} INFO - Dependencies all met for <TaskInstance: twitter_dag.complete_twitter_etl scheduled__2021-03-16T00:00:00+00:00 [queued]>
[2023-01-26T09:11:38.180+0000] {taskinstance.py:1279} INFO - 
--------------------------------------------------------------------------------
[2023-01-26T09:11:38.182+0000] {taskinstance.py:1280} INFO - Starting attempt 1 of 2
[2023-01-26T09:11:38.191+0000] {taskinstance.py:1281} INFO - 
--------------------------------------------------------------------------------
[2023-01-26T09:11:38.348+0000] {taskinstance.py:1300} INFO - Executing <Task(PythonOperator): complete_twitter_etl> on 2021-03-16 00:00:00+00:00
[2023-01-26T09:11:38.443+0000] {standard_task_runner.py:55} INFO - Started process 643 to run task
[2023-01-26T09:11:38.516+0000] {standard_task_runner.py:82} INFO - Running: ['***', 'tasks', 'run', 'twitter_dag', 'complete_twitter_etl', 'scheduled__2021-03-16T00:00:00+00:00', '--job-id', '129', '--raw', '--subdir', 'DAGS_FOLDER/twitter_dag.py', '--cfg-path', '/tmp/tmpx28imeym']
[2023-01-26T09:11:38.522+0000] {standard_task_runner.py:83} INFO - Job 129: Subtask complete_twitter_etl
[2023-01-26T09:11:40.972+0000] {task_command.py:388} INFO - Running <TaskInstance: twitter_dag.complete_twitter_etl scheduled__2021-03-16T00:00:00+00:00 [running]> on host d0fc3b00c15c
[2023-01-26T09:11:41.414+0000] {taskinstance.py:1509} INFO - Exporting the following env vars:
AIRFLOW_CTX_DAG_EMAIL=***@example.com
AIRFLOW_CTX_DAG_OWNER=***
AIRFLOW_CTX_DAG_ID=twitter_dag
AIRFLOW_CTX_TASK_ID=complete_twitter_etl
AIRFLOW_CTX_EXECUTION_DATE=2021-03-16T00:00:00+00:00
AIRFLOW_CTX_TRY_NUMBER=1
AIRFLOW_CTX_DAG_RUN_ID=scheduled__2021-03-16T00:00:00+00:00
[2023-01-26T09:11:43.339+0000] {python.py:177} INFO - Done. Returned value was: None
[2023-01-26T09:11:43.390+0000] {taskinstance.py:1323} INFO - Marking task as SUCCESS. dag_id=twitter_dag, task_id=complete_twitter_etl, execution_date=20210316T000000, start_date=20230126T091138, end_date=20230126T091143
[2023-01-26T09:11:43.650+0000] {local_task_job.py:208} INFO - Task exited with return code 0
[2023-01-26T09:11:44.521+0000] {taskinstance.py:2578} INFO - 0 downstream tasks scheduled from follow-on schedule check
