[2023-01-25T19:22:47.654+0000] {taskinstance.py:1083} INFO - Dependencies all met for <TaskInstance: twitter_dag.complete_twitter_etl scheduled__2021-09-17T00:00:00+00:00 [queued]>
[2023-01-25T19:22:47.723+0000] {taskinstance.py:1083} INFO - Dependencies all met for <TaskInstance: twitter_dag.complete_twitter_etl scheduled__2021-09-17T00:00:00+00:00 [queued]>
[2023-01-25T19:22:47.725+0000] {taskinstance.py:1279} INFO - 
--------------------------------------------------------------------------------
[2023-01-25T19:22:47.727+0000] {taskinstance.py:1280} INFO - Starting attempt 1 of 2
[2023-01-25T19:22:47.729+0000] {taskinstance.py:1281} INFO - 
--------------------------------------------------------------------------------
[2023-01-25T19:22:47.838+0000] {taskinstance.py:1300} INFO - Executing <Task(PythonOperator): complete_twitter_etl> on 2021-09-17 00:00:00+00:00
[2023-01-25T19:22:47.880+0000] {standard_task_runner.py:55} INFO - Started process 5636 to run task
[2023-01-25T19:22:47.930+0000] {standard_task_runner.py:82} INFO - Running: ['***', 'tasks', 'run', 'twitter_dag', 'complete_twitter_etl', 'scheduled__2021-09-17T00:00:00+00:00', '--job-id', '619', '--raw', '--subdir', 'DAGS_FOLDER/twitter_dag.py', '--cfg-path', '/tmp/tmpxmq5xgpc']
[2023-01-25T19:22:47.933+0000] {standard_task_runner.py:83} INFO - Job 619: Subtask complete_twitter_etl
[2023-01-25T19:22:48.604+0000] {task_command.py:388} INFO - Running <TaskInstance: twitter_dag.complete_twitter_etl scheduled__2021-09-17T00:00:00+00:00 [running]> on host 512d0ff0785b
[2023-01-25T19:22:50.073+0000] {taskinstance.py:1509} INFO - Exporting the following env vars:
AIRFLOW_CTX_DAG_EMAIL=***@example.com
AIRFLOW_CTX_DAG_OWNER=***
AIRFLOW_CTX_DAG_ID=twitter_dag
AIRFLOW_CTX_TASK_ID=complete_twitter_etl
AIRFLOW_CTX_EXECUTION_DATE=2021-09-17T00:00:00+00:00
AIRFLOW_CTX_TRY_NUMBER=1
AIRFLOW_CTX_DAG_RUN_ID=scheduled__2021-09-17T00:00:00+00:00
[2023-01-25T20:34:49.746+0000] {taskinstance.py:1768} ERROR - Task failed with exception
Traceback (most recent call last):
  File "/home/airflow/.local/lib/python3.7/site-packages/urllib3/connectionpool.py", line 710, in urlopen
    chunked=chunked,
  File "/home/airflow/.local/lib/python3.7/site-packages/urllib3/connectionpool.py", line 449, in _make_request
    six.raise_from(e, None)
  File "<string>", line 3, in raise_from
  File "/home/airflow/.local/lib/python3.7/site-packages/urllib3/connectionpool.py", line 444, in _make_request
    httplib_response = conn.getresponse()
  File "/usr/local/lib/python3.7/http/client.py", line 1373, in getresponse
    response.begin()
  File "/usr/local/lib/python3.7/http/client.py", line 319, in begin
    version, status, reason = self._read_status()
  File "/usr/local/lib/python3.7/http/client.py", line 288, in _read_status
    raise RemoteDisconnected("Remote end closed connection without"
http.client.RemoteDisconnected: Remote end closed connection without response

During handling of the above exception, another exception occurred:

Traceback (most recent call last):
  File "/home/airflow/.local/lib/python3.7/site-packages/requests/adapters.py", line 499, in send
    timeout=timeout,
  File "/home/airflow/.local/lib/python3.7/site-packages/urllib3/connectionpool.py", line 788, in urlopen
    method, url, error=e, _pool=self, _stacktrace=sys.exc_info()[2]
  File "/home/airflow/.local/lib/python3.7/site-packages/urllib3/util/retry.py", line 550, in increment
    raise six.reraise(type(error), error, _stacktrace)
  File "/home/airflow/.local/lib/python3.7/site-packages/urllib3/packages/six.py", line 769, in reraise
    raise value.with_traceback(tb)
  File "/home/airflow/.local/lib/python3.7/site-packages/urllib3/connectionpool.py", line 710, in urlopen
    chunked=chunked,
  File "/home/airflow/.local/lib/python3.7/site-packages/urllib3/connectionpool.py", line 449, in _make_request
    six.raise_from(e, None)
  File "<string>", line 3, in raise_from
  File "/home/airflow/.local/lib/python3.7/site-packages/urllib3/connectionpool.py", line 444, in _make_request
    httplib_response = conn.getresponse()
  File "/usr/local/lib/python3.7/http/client.py", line 1373, in getresponse
    response.begin()
  File "/usr/local/lib/python3.7/http/client.py", line 319, in begin
    version, status, reason = self._read_status()
  File "/usr/local/lib/python3.7/http/client.py", line 288, in _read_status
    raise RemoteDisconnected("Remote end closed connection without"
urllib3.exceptions.ProtocolError: ('Connection aborted.', RemoteDisconnected('Remote end closed connection without response'))

During handling of the above exception, another exception occurred:

Traceback (most recent call last):
  File "/home/airflow/.local/lib/python3.7/site-packages/tweepy/api.py", line 225, in request
    timeout=self.timeout, auth=auth, proxies=self.proxy
  File "/home/airflow/.local/lib/python3.7/site-packages/requests/sessions.py", line 587, in request
    resp = self.send(prep, **send_kwargs)
  File "/home/airflow/.local/lib/python3.7/site-packages/requests/sessions.py", line 701, in send
    r = adapter.send(request, **kwargs)
  File "/home/airflow/.local/lib/python3.7/site-packages/requests/adapters.py", line 547, in send
    raise ConnectionError(err, request=request)
requests.exceptions.ConnectionError: ('Connection aborted.', RemoteDisconnected('Remote end closed connection without response'))

During handling of the above exception, another exception occurred:

Traceback (most recent call last):
  File "/home/airflow/.local/lib/python3.7/site-packages/airflow/operators/python.py", line 175, in execute
    return_value = self.execute_callable()
  File "/home/airflow/.local/lib/python3.7/site-packages/airflow/operators/python.py", line 192, in execute_callable
    return self.python_callable(*self.op_args, **self.op_kwargs)
  File "/opt/airflow/dags/twitter_etl.py", line 29, in run_twitter_etl
    tweet_mode='extended'
  File "/home/airflow/.local/lib/python3.7/site-packages/tweepy/api.py", line 33, in wrapper
    return method(*args, **kwargs)
  File "/home/airflow/.local/lib/python3.7/site-packages/tweepy/api.py", line 46, in wrapper
    return method(*args, **kwargs)
  File "/home/airflow/.local/lib/python3.7/site-packages/tweepy/api.py", line 581, in user_timeline
    ), **kwargs
  File "/home/airflow/.local/lib/python3.7/site-packages/tweepy/api.py", line 228, in request
    raise TweepyException(f'Failed to send request: {e}').with_traceback(sys.exc_info()[2])
  File "/home/airflow/.local/lib/python3.7/site-packages/tweepy/api.py", line 225, in request
    timeout=self.timeout, auth=auth, proxies=self.proxy
  File "/home/airflow/.local/lib/python3.7/site-packages/requests/sessions.py", line 587, in request
    resp = self.send(prep, **send_kwargs)
  File "/home/airflow/.local/lib/python3.7/site-packages/requests/sessions.py", line 701, in send
    r = adapter.send(request, **kwargs)
  File "/home/airflow/.local/lib/python3.7/site-packages/requests/adapters.py", line 547, in send
    raise ConnectionError(err, request=request)
tweepy.errors.TweepyException: Failed to send request: ('Connection aborted.', RemoteDisconnected('Remote end closed connection without response'))
[2023-01-25T20:34:50.313+0000] {taskinstance.py:1323} INFO - Marking task as UP_FOR_RETRY. dag_id=twitter_dag, task_id=complete_twitter_etl, execution_date=20210917T000000, start_date=20230125T192247, end_date=20230125T203450
[2023-01-25T20:34:51.312+0000] {standard_task_runner.py:105} ERROR - Failed to execute job 619 for task complete_twitter_etl (Failed to send request: ('Connection aborted.', RemoteDisconnected('Remote end closed connection without response')); 5636)
[2023-01-25T20:34:53.237+0000] {local_task_job.py:208} INFO - Task exited with return code 1
[2023-01-25T20:34:54.043+0000] {taskinstance.py:2578} INFO - 0 downstream tasks scheduled from follow-on schedule check
[2023-01-26T07:18:11.474+0000] {taskinstance.py:1083} INFO - Dependencies all met for <TaskInstance: twitter_dag.complete_twitter_etl scheduled__2021-09-17T00:00:00+00:00 [queued]>
[2023-01-26T07:18:11.556+0000] {taskinstance.py:1083} INFO - Dependencies all met for <TaskInstance: twitter_dag.complete_twitter_etl scheduled__2021-09-17T00:00:00+00:00 [queued]>
[2023-01-26T07:18:11.558+0000] {taskinstance.py:1279} INFO - 
--------------------------------------------------------------------------------
[2023-01-26T07:18:11.569+0000] {taskinstance.py:1280} INFO - Starting attempt 1 of 2
[2023-01-26T07:18:11.571+0000] {taskinstance.py:1281} INFO - 
--------------------------------------------------------------------------------
[2023-01-26T07:18:11.705+0000] {taskinstance.py:1300} INFO - Executing <Task(PythonOperator): complete_twitter_etl> on 2021-09-17 00:00:00+00:00
[2023-01-26T07:18:11.839+0000] {standard_task_runner.py:55} INFO - Started process 2024 to run task
[2023-01-26T07:18:11.916+0000] {standard_task_runner.py:82} INFO - Running: ['***', 'tasks', 'run', 'twitter_dag', 'complete_twitter_etl', 'scheduled__2021-09-17T00:00:00+00:00', '--job-id', '351', '--raw', '--subdir', 'DAGS_FOLDER/twitter_dag.py', '--cfg-path', '/tmp/tmpjvq2p977']
[2023-01-26T07:18:11.921+0000] {standard_task_runner.py:83} INFO - Job 351: Subtask complete_twitter_etl
[2023-01-26T07:18:13.827+0000] {task_command.py:388} INFO - Running <TaskInstance: twitter_dag.complete_twitter_etl scheduled__2021-09-17T00:00:00+00:00 [running]> on host 2221c1ebf970
[2023-01-26T07:18:14.576+0000] {taskinstance.py:1509} INFO - Exporting the following env vars:
AIRFLOW_CTX_DAG_EMAIL=***@example.com
AIRFLOW_CTX_DAG_OWNER=***
AIRFLOW_CTX_DAG_ID=twitter_dag
AIRFLOW_CTX_TASK_ID=complete_twitter_etl
AIRFLOW_CTX_EXECUTION_DATE=2021-09-17T00:00:00+00:00
AIRFLOW_CTX_TRY_NUMBER=1
AIRFLOW_CTX_DAG_RUN_ID=scheduled__2021-09-17T00:00:00+00:00
[2023-01-26T07:18:16.672+0000] {python.py:177} INFO - Done. Returned value was: None
[2023-01-26T07:18:16.704+0000] {taskinstance.py:1323} INFO - Marking task as SUCCESS. dag_id=twitter_dag, task_id=complete_twitter_etl, execution_date=20210917T000000, start_date=20230126T071811, end_date=20230126T071816
[2023-01-26T07:18:16.848+0000] {local_task_job.py:208} INFO - Task exited with return code 0
[2023-01-26T07:18:16.894+0000] {taskinstance.py:2578} INFO - 0 downstream tasks scheduled from follow-on schedule check
