[2023-01-25T18:43:58.421+0000] {taskinstance.py:1083} INFO - Dependencies all met for <TaskInstance: twitter_dag.complete_twitter_etl scheduled__2020-11-26T00:00:00+00:00 [queued]>
[2023-01-25T18:43:58.591+0000] {taskinstance.py:1083} INFO - Dependencies all met for <TaskInstance: twitter_dag.complete_twitter_etl scheduled__2020-11-26T00:00:00+00:00 [queued]>
[2023-01-25T18:43:58.607+0000] {taskinstance.py:1279} INFO - 
--------------------------------------------------------------------------------
[2023-01-25T18:43:58.616+0000] {taskinstance.py:1280} INFO - Starting attempt 1 of 2
[2023-01-25T18:43:58.623+0000] {taskinstance.py:1281} INFO - 
--------------------------------------------------------------------------------
[2023-01-25T18:43:58.850+0000] {taskinstance.py:1300} INFO - Executing <Task(PythonOperator): complete_twitter_etl> on 2020-11-26 00:00:00+00:00
[2023-01-25T18:43:58.961+0000] {standard_task_runner.py:55} INFO - Started process 649 to run task
[2023-01-25T18:43:59.006+0000] {standard_task_runner.py:82} INFO - Running: ['***', 'tasks', 'run', 'twitter_dag', 'complete_twitter_etl', 'scheduled__2020-11-26T00:00:00+00:00', '--job-id', '37', '--raw', '--subdir', 'DAGS_FOLDER/twitter_dag.py', '--cfg-path', '/tmp/tmpdpnw6oh0']
[2023-01-25T18:43:59.022+0000] {standard_task_runner.py:83} INFO - Job 37: Subtask complete_twitter_etl
[2023-01-25T18:44:02.627+0000] {task_command.py:388} INFO - Running <TaskInstance: twitter_dag.complete_twitter_etl scheduled__2020-11-26T00:00:00+00:00 [running]> on host 512d0ff0785b
[2023-01-25T18:44:04.172+0000] {taskinstance.py:1509} INFO - Exporting the following env vars:
AIRFLOW_CTX_DAG_EMAIL=***@example.com
AIRFLOW_CTX_DAG_OWNER=***
AIRFLOW_CTX_DAG_ID=twitter_dag
AIRFLOW_CTX_TASK_ID=complete_twitter_etl
AIRFLOW_CTX_EXECUTION_DATE=2020-11-26T00:00:00+00:00
AIRFLOW_CTX_TRY_NUMBER=1
AIRFLOW_CTX_DAG_RUN_ID=scheduled__2020-11-26T00:00:00+00:00
[2023-01-25T18:44:21.901+0000] {taskinstance.py:1768} ERROR - Task failed with exception
Traceback (most recent call last):
  File "/home/airflow/.local/lib/python3.7/site-packages/s3fs/core.py", line 112, in _error_wrapper
    return await func(*args, **kwargs)
  File "/home/airflow/.local/lib/python3.7/site-packages/aiobotocore/client.py", line 358, in _make_api_call
    raise error_class(parsed_response, operation_name)
botocore.exceptions.ClientError: An error occurred (AccessDenied) when calling the CreateBucket operation: Anonymous access is forbidden for this operation

The above exception was the direct cause of the following exception:

Traceback (most recent call last):
  File "/home/airflow/.local/lib/python3.7/site-packages/airflow/operators/python.py", line 175, in execute
    return_value = self.execute_callable()
  File "/home/airflow/.local/lib/python3.7/site-packages/airflow/operators/python.py", line 192, in execute_callable
    return self.python_callable(*self.op_args, **self.op_kwargs)
  File "/opt/airflow/dags/twitter_etl.py", line 46, in run_twitter_etl
    df.to_csv("s3://jinchoi-airflow-bucket/data/elonmusk_tweets.csv")
  File "/home/airflow/.local/lib/python3.7/site-packages/pandas/core/generic.py", line 3482, in to_csv
    storage_options=storage_options,
  File "/home/airflow/.local/lib/python3.7/site-packages/pandas/io/formats/format.py", line 1105, in to_csv
    csv_formatter.save()
  File "/home/airflow/.local/lib/python3.7/site-packages/pandas/io/formats/csvs.py", line 243, in save
    storage_options=self.storage_options,
  File "/home/airflow/.local/lib/python3.7/site-packages/pandas/io/common.py", line 614, in get_handle
    storage_options=storage_options,
  File "/home/airflow/.local/lib/python3.7/site-packages/pandas/io/common.py", line 370, in _get_filepath_or_buffer
    filepath_or_buffer, mode=fsspec_mode, **(storage_options or {})
  File "/home/airflow/.local/lib/python3.7/site-packages/fsspec/core.py", line 428, in open
    **kwargs,
  File "/home/airflow/.local/lib/python3.7/site-packages/fsspec/core.py", line 283, in open_files
    [fs.makedirs(parent, exist_ok=True) for parent in parents]
  File "/home/airflow/.local/lib/python3.7/site-packages/fsspec/core.py", line 283, in <listcomp>
    [fs.makedirs(parent, exist_ok=True) for parent in parents]
  File "/home/airflow/.local/lib/python3.7/site-packages/fsspec/asyn.py", line 114, in wrapper
    return sync(self.loop, func, *args, **kwargs)
  File "/home/airflow/.local/lib/python3.7/site-packages/fsspec/asyn.py", line 99, in sync
    raise return_result
  File "/home/airflow/.local/lib/python3.7/site-packages/fsspec/asyn.py", line 54, in _runner
    result[0] = await coro
  File "/home/airflow/.local/lib/python3.7/site-packages/s3fs/core.py", line 883, in _makedirs
    await self._mkdir(path, create_parents=True)
  File "/home/airflow/.local/lib/python3.7/site-packages/s3fs/core.py", line 868, in _mkdir
    await self._call_s3("create_bucket", **params)
  File "/home/airflow/.local/lib/python3.7/site-packages/s3fs/core.py", line 340, in _call_s3
    method, kwargs=additional_kwargs, retries=self.retries
  File "/home/airflow/.local/lib/python3.7/site-packages/s3fs/core.py", line 139, in _error_wrapper
    raise err
PermissionError: Anonymous access is forbidden for this operation
[2023-01-25T18:44:22.209+0000] {taskinstance.py:1323} INFO - Marking task as UP_FOR_RETRY. dag_id=twitter_dag, task_id=complete_twitter_etl, execution_date=20201126T000000, start_date=20230125T184358, end_date=20230125T184422
[2023-01-25T18:44:24.630+0000] {standard_task_runner.py:105} ERROR - Failed to execute job 37 for task complete_twitter_etl (Anonymous access is forbidden for this operation; 649)
[2023-01-25T18:44:24.906+0000] {local_task_job.py:208} INFO - Task exited with return code 1
[2023-01-25T18:44:26.375+0000] {taskinstance.py:2578} INFO - 0 downstream tasks scheduled from follow-on schedule check
[2023-01-26T03:23:53.899+0000] {taskinstance.py:1083} INFO - Dependencies all met for <TaskInstance: twitter_dag.complete_twitter_etl scheduled__2020-11-26T00:00:00+00:00 [queued]>
[2023-01-26T03:23:53.971+0000] {taskinstance.py:1083} INFO - Dependencies all met for <TaskInstance: twitter_dag.complete_twitter_etl scheduled__2020-11-26T00:00:00+00:00 [queued]>
[2023-01-26T03:23:53.975+0000] {taskinstance.py:1279} INFO - 
--------------------------------------------------------------------------------
[2023-01-26T03:23:53.976+0000] {taskinstance.py:1280} INFO - Starting attempt 1 of 2
[2023-01-26T03:23:53.985+0000] {taskinstance.py:1281} INFO - 
--------------------------------------------------------------------------------
[2023-01-26T03:23:54.075+0000] {taskinstance.py:1300} INFO - Executing <Task(PythonOperator): complete_twitter_etl> on 2020-11-26 00:00:00+00:00
[2023-01-26T03:23:54.094+0000] {standard_task_runner.py:55} INFO - Started process 300 to run task
[2023-01-26T03:23:54.120+0000] {standard_task_runner.py:82} INFO - Running: ['***', 'tasks', 'run', 'twitter_dag', 'complete_twitter_etl', 'scheduled__2020-11-26T00:00:00+00:00', '--job-id', '36', '--raw', '--subdir', 'DAGS_FOLDER/twitter_dag.py', '--cfg-path', '/tmp/tmp04s7hm8p']
[2023-01-26T03:23:54.124+0000] {standard_task_runner.py:83} INFO - Job 36: Subtask complete_twitter_etl
[2023-01-26T03:23:54.424+0000] {task_command.py:388} INFO - Running <TaskInstance: twitter_dag.complete_twitter_etl scheduled__2020-11-26T00:00:00+00:00 [running]> on host 3db080823b1b
[2023-01-26T03:23:55.244+0000] {taskinstance.py:1509} INFO - Exporting the following env vars:
AIRFLOW_CTX_DAG_EMAIL=***@example.com
AIRFLOW_CTX_DAG_OWNER=***
AIRFLOW_CTX_DAG_ID=twitter_dag
AIRFLOW_CTX_TASK_ID=complete_twitter_etl
AIRFLOW_CTX_EXECUTION_DATE=2020-11-26T00:00:00+00:00
AIRFLOW_CTX_TRY_NUMBER=1
AIRFLOW_CTX_DAG_RUN_ID=scheduled__2020-11-26T00:00:00+00:00
[2023-01-26T03:23:56.219+0000] {taskinstance.py:1768} ERROR - Task failed with exception
Traceback (most recent call last):
  File "/home/airflow/.local/lib/python3.7/site-packages/airflow/operators/python.py", line 175, in execute
    return_value = self.execute_callable()
  File "/home/airflow/.local/lib/python3.7/site-packages/airflow/operators/python.py", line 192, in execute_callable
    return self.python_callable(*self.op_args, **self.op_kwargs)
  File "/opt/airflow/dags/twitter_etl.py", line 53, in run_twitter_etl
    df.to_csv('s3://{BUCKET_NAME}/data/{KEY}', index=False, header=False,sep=',', engine='python', filesystem=s3)
TypeError: to_csv() got an unexpected keyword argument 'engine'
[2023-01-26T03:23:56.236+0000] {taskinstance.py:1323} INFO - Marking task as UP_FOR_RETRY. dag_id=twitter_dag, task_id=complete_twitter_etl, execution_date=20201126T000000, start_date=20230126T032353, end_date=20230126T032356
[2023-01-26T03:23:56.260+0000] {standard_task_runner.py:105} ERROR - Failed to execute job 36 for task complete_twitter_etl (to_csv() got an unexpected keyword argument 'engine'; 300)
[2023-01-26T03:23:56.337+0000] {local_task_job.py:208} INFO - Task exited with return code 1
[2023-01-26T03:23:56.385+0000] {taskinstance.py:2578} INFO - 0 downstream tasks scheduled from follow-on schedule check
[2023-01-26T03:35:34.308+0000] {taskinstance.py:1083} INFO - Dependencies all met for <TaskInstance: twitter_dag.complete_twitter_etl scheduled__2020-11-26T00:00:00+00:00 [queued]>
[2023-01-26T03:35:34.488+0000] {taskinstance.py:1083} INFO - Dependencies all met for <TaskInstance: twitter_dag.complete_twitter_etl scheduled__2020-11-26T00:00:00+00:00 [queued]>
[2023-01-26T03:35:34.494+0000] {taskinstance.py:1279} INFO - 
--------------------------------------------------------------------------------
[2023-01-26T03:35:34.496+0000] {taskinstance.py:1280} INFO - Starting attempt 1 of 2
[2023-01-26T03:35:34.497+0000] {taskinstance.py:1281} INFO - 
--------------------------------------------------------------------------------
[2023-01-26T03:35:34.794+0000] {taskinstance.py:1300} INFO - Executing <Task(PythonOperator): complete_twitter_etl> on 2020-11-26 00:00:00+00:00
[2023-01-26T03:35:34.835+0000] {standard_task_runner.py:55} INFO - Started process 327 to run task
[2023-01-26T03:35:34.879+0000] {standard_task_runner.py:82} INFO - Running: ['***', 'tasks', 'run', 'twitter_dag', 'complete_twitter_etl', 'scheduled__2020-11-26T00:00:00+00:00', '--job-id', '37', '--raw', '--subdir', 'DAGS_FOLDER/twitter_dag.py', '--cfg-path', '/tmp/tmp4n584gys']
[2023-01-26T03:35:34.892+0000] {standard_task_runner.py:83} INFO - Job 37: Subtask complete_twitter_etl
[2023-01-26T03:35:37.613+0000] {task_command.py:388} INFO - Running <TaskInstance: twitter_dag.complete_twitter_etl scheduled__2020-11-26T00:00:00+00:00 [running]> on host 9c4f31e2db2b
[2023-01-26T03:35:37.942+0000] {taskinstance.py:1509} INFO - Exporting the following env vars:
AIRFLOW_CTX_DAG_EMAIL=***@example.com
AIRFLOW_CTX_DAG_OWNER=***
AIRFLOW_CTX_DAG_ID=twitter_dag
AIRFLOW_CTX_TASK_ID=complete_twitter_etl
AIRFLOW_CTX_EXECUTION_DATE=2020-11-26T00:00:00+00:00
AIRFLOW_CTX_TRY_NUMBER=1
AIRFLOW_CTX_DAG_RUN_ID=scheduled__2020-11-26T00:00:00+00:00
[2023-01-26T03:35:39.482+0000] {taskinstance.py:1768} ERROR - Task failed with exception
Traceback (most recent call last):
  File "/home/airflow/.local/lib/python3.7/site-packages/airflow/operators/python.py", line 175, in execute
    return_value = self.execute_callable()
  File "/home/airflow/.local/lib/python3.7/site-packages/airflow/operators/python.py", line 192, in execute_callable
    return self.python_callable(*self.op_args, **self.op_kwargs)
  File "/opt/airflow/dags/twitter_etl.py", line 54, in run_twitter_etl
    s3.put('s3://{BUCKET_NAME}/data/{KEY}', csv_buffer)
  File "/home/airflow/.local/lib/python3.7/site-packages/fsspec/asyn.py", line 114, in wrapper
    return sync(self.loop, func, *args, **kwargs)
  File "/home/airflow/.local/lib/python3.7/site-packages/fsspec/asyn.py", line 99, in sync
    raise return_result
  File "/home/airflow/.local/lib/python3.7/site-packages/fsspec/asyn.py", line 54, in _runner
    result[0] = await coro
  File "/home/airflow/.local/lib/python3.7/site-packages/fsspec/asyn.py", line 481, in _put
    rpath = self._strip_protocol(rpath)
  File "/home/airflow/.local/lib/python3.7/site-packages/fsspec/spec.py", line 188, in _strip_protocol
    if path.startswith(protocol + "://"):
TypeError: startswith first arg must be bytes or a tuple of bytes, not str
[2023-01-26T03:35:39.556+0000] {taskinstance.py:1323} INFO - Marking task as UP_FOR_RETRY. dag_id=twitter_dag, task_id=complete_twitter_etl, execution_date=20201126T000000, start_date=20230126T033534, end_date=20230126T033539
[2023-01-26T03:35:39.749+0000] {standard_task_runner.py:105} ERROR - Failed to execute job 37 for task complete_twitter_etl (startswith first arg must be bytes or a tuple of bytes, not str; 327)
[2023-01-26T03:35:40.046+0000] {local_task_job.py:208} INFO - Task exited with return code 1
[2023-01-26T03:35:42.183+0000] {taskinstance.py:2578} INFO - 0 downstream tasks scheduled from follow-on schedule check
[2023-01-26T06:04:59.221+0000] {taskinstance.py:1083} INFO - Dependencies all met for <TaskInstance: twitter_dag.complete_twitter_etl scheduled__2020-11-26T00:00:00+00:00 [queued]>
[2023-01-26T06:04:59.237+0000] {taskinstance.py:1083} INFO - Dependencies all met for <TaskInstance: twitter_dag.complete_twitter_etl scheduled__2020-11-26T00:00:00+00:00 [queued]>
[2023-01-26T06:04:59.238+0000] {taskinstance.py:1279} INFO - 
--------------------------------------------------------------------------------
[2023-01-26T06:04:59.239+0000] {taskinstance.py:1280} INFO - Starting attempt 1 of 2
[2023-01-26T06:04:59.240+0000] {taskinstance.py:1281} INFO - 
--------------------------------------------------------------------------------
[2023-01-26T06:04:59.266+0000] {taskinstance.py:1300} INFO - Executing <Task(PythonOperator): complete_twitter_etl> on 2020-11-26 00:00:00+00:00
[2023-01-26T06:04:59.277+0000] {standard_task_runner.py:55} INFO - Started process 1171 to run task
[2023-01-26T06:04:59.282+0000] {standard_task_runner.py:82} INFO - Running: ['***', 'tasks', 'run', 'twitter_dag', 'complete_twitter_etl', 'scheduled__2020-11-26T00:00:00+00:00', '--job-id', '38', '--raw', '--subdir', 'DAGS_FOLDER/twitter_dag.py', '--cfg-path', '/tmp/tmpjsx0mwof']
[2023-01-26T06:04:59.284+0000] {standard_task_runner.py:83} INFO - Job 38: Subtask complete_twitter_etl
[2023-01-26T06:04:59.615+0000] {task_command.py:388} INFO - Running <TaskInstance: twitter_dag.complete_twitter_etl scheduled__2020-11-26T00:00:00+00:00 [running]> on host 864c120ca3c2
[2023-01-26T06:04:59.707+0000] {taskinstance.py:1509} INFO - Exporting the following env vars:
AIRFLOW_CTX_DAG_EMAIL=***@example.com
AIRFLOW_CTX_DAG_OWNER=***
AIRFLOW_CTX_DAG_ID=twitter_dag
AIRFLOW_CTX_TASK_ID=complete_twitter_etl
AIRFLOW_CTX_EXECUTION_DATE=2020-11-26T00:00:00+00:00
AIRFLOW_CTX_TRY_NUMBER=1
AIRFLOW_CTX_DAG_RUN_ID=scheduled__2020-11-26T00:00:00+00:00
[2023-01-26T06:05:00.198+0000] {taskinstance.py:1768} ERROR - Task failed with exception
Traceback (most recent call last):
  File "/home/airflow/.local/lib/python3.7/site-packages/airflow/operators/python.py", line 175, in execute
    return_value = self.execute_callable()
  File "/home/airflow/.local/lib/python3.7/site-packages/airflow/operators/python.py", line 192, in execute_callable
    return self.python_callable(*self.op_args, **self.op_kwargs)
  File "/opt/airflow/dags/twitter_etl.py", line 51, in run_twitter_etl
    aws_access_key_id=os.environ['AWS_ACCESS_KEY_ID'],
  File "/usr/local/lib/python3.7/os.py", line 681, in __getitem__
    raise KeyError(key) from None
KeyError: 'AWS_ACCESS_KEY_ID'
[2023-01-26T06:05:00.217+0000] {taskinstance.py:1323} INFO - Marking task as UP_FOR_RETRY. dag_id=twitter_dag, task_id=complete_twitter_etl, execution_date=20201126T000000, start_date=20230126T060459, end_date=20230126T060500
[2023-01-26T06:05:00.241+0000] {standard_task_runner.py:105} ERROR - Failed to execute job 38 for task complete_twitter_etl ('AWS_ACCESS_KEY_ID'; 1171)
[2023-01-26T06:05:00.307+0000] {local_task_job.py:208} INFO - Task exited with return code 1
[2023-01-26T06:05:00.335+0000] {taskinstance.py:2578} INFO - 0 downstream tasks scheduled from follow-on schedule check
[2023-01-26T07:05:03.402+0000] {taskinstance.py:1083} INFO - Dependencies all met for <TaskInstance: twitter_dag.complete_twitter_etl scheduled__2020-11-26T00:00:00+00:00 [queued]>
[2023-01-26T07:05:04.037+0000] {taskinstance.py:1083} INFO - Dependencies all met for <TaskInstance: twitter_dag.complete_twitter_etl scheduled__2020-11-26T00:00:00+00:00 [queued]>
[2023-01-26T07:05:04.054+0000] {taskinstance.py:1279} INFO - 
--------------------------------------------------------------------------------
[2023-01-26T07:05:04.063+0000] {taskinstance.py:1280} INFO - Starting attempt 1 of 2
[2023-01-26T07:05:04.079+0000] {taskinstance.py:1281} INFO - 
--------------------------------------------------------------------------------
[2023-01-26T07:05:04.495+0000] {taskinstance.py:1300} INFO - Executing <Task(PythonOperator): complete_twitter_etl> on 2020-11-26 00:00:00+00:00
[2023-01-26T07:05:04.754+0000] {standard_task_runner.py:55} INFO - Started process 523 to run task
[2023-01-26T07:05:04.869+0000] {standard_task_runner.py:82} INFO - Running: ['***', 'tasks', 'run', 'twitter_dag', 'complete_twitter_etl', 'scheduled__2020-11-26T00:00:00+00:00', '--job-id', '38', '--raw', '--subdir', 'DAGS_FOLDER/twitter_dag.py', '--cfg-path', '/tmp/tmppkeey2rv']
[2023-01-26T07:05:04.933+0000] {standard_task_runner.py:83} INFO - Job 38: Subtask complete_twitter_etl
[2023-01-26T07:05:07.195+0000] {task_command.py:388} INFO - Running <TaskInstance: twitter_dag.complete_twitter_etl scheduled__2020-11-26T00:00:00+00:00 [running]> on host 2221c1ebf970
[2023-01-26T07:05:07.813+0000] {taskinstance.py:1509} INFO - Exporting the following env vars:
AIRFLOW_CTX_DAG_EMAIL=***@example.com
AIRFLOW_CTX_DAG_OWNER=***
AIRFLOW_CTX_DAG_ID=twitter_dag
AIRFLOW_CTX_TASK_ID=complete_twitter_etl
AIRFLOW_CTX_EXECUTION_DATE=2020-11-26T00:00:00+00:00
AIRFLOW_CTX_TRY_NUMBER=1
AIRFLOW_CTX_DAG_RUN_ID=scheduled__2020-11-26T00:00:00+00:00
[2023-01-26T07:05:09.058+0000] {taskinstance.py:1768} ERROR - Task failed with exception
Traceback (most recent call last):
  File "/home/airflow/.local/lib/python3.7/site-packages/airflow/operators/python.py", line 175, in execute
    return_value = self.execute_callable()
  File "/home/airflow/.local/lib/python3.7/site-packages/airflow/operators/python.py", line 192, in execute_callable
    return self.python_callable(*self.op_args, **self.op_kwargs)
  File "/opt/airflow/dags/twitter_etl.py", line 63, in run_twitter_etl
    s3.Object(BUCKET_NAME, KEY).put(Body=csv_buffer.getvalue())
  File "/home/airflow/.local/lib/python3.7/site-packages/botocore/client.py", line 839, in __getattr__
    f"'{self.__class__.__name__}' object has no attribute '{item}'"
AttributeError: 'S3' object has no attribute 'Object'
[2023-01-26T07:05:09.092+0000] {taskinstance.py:1323} INFO - Marking task as UP_FOR_RETRY. dag_id=twitter_dag, task_id=complete_twitter_etl, execution_date=20201126T000000, start_date=20230126T070503, end_date=20230126T070509
[2023-01-26T07:05:09.366+0000] {standard_task_runner.py:105} ERROR - Failed to execute job 38 for task complete_twitter_etl ('S3' object has no attribute 'Object'; 523)
[2023-01-26T07:05:09.481+0000] {local_task_job.py:208} INFO - Task exited with return code 1
[2023-01-26T07:05:09.639+0000] {taskinstance.py:2578} INFO - 0 downstream tasks scheduled from follow-on schedule check
[2023-01-26T08:07:59.912+0000] {taskinstance.py:1083} INFO - Dependencies all met for <TaskInstance: twitter_dag.complete_twitter_etl scheduled__2020-11-26T00:00:00+00:00 [queued]>
[2023-01-26T08:07:59.945+0000] {taskinstance.py:1083} INFO - Dependencies all met for <TaskInstance: twitter_dag.complete_twitter_etl scheduled__2020-11-26T00:00:00+00:00 [queued]>
[2023-01-26T08:07:59.946+0000] {taskinstance.py:1279} INFO - 
--------------------------------------------------------------------------------
[2023-01-26T08:07:59.951+0000] {taskinstance.py:1280} INFO - Starting attempt 1 of 2
[2023-01-26T08:07:59.952+0000] {taskinstance.py:1281} INFO - 
--------------------------------------------------------------------------------
[2023-01-26T08:07:59.996+0000] {taskinstance.py:1300} INFO - Executing <Task(PythonOperator): complete_twitter_etl> on 2020-11-26 00:00:00+00:00
[2023-01-26T08:08:00.023+0000] {standard_task_runner.py:55} INFO - Started process 814 to run task
[2023-01-26T08:08:00.060+0000] {standard_task_runner.py:82} INFO - Running: ['***', 'tasks', 'run', 'twitter_dag', 'complete_twitter_etl', 'scheduled__2020-11-26T00:00:00+00:00', '--job-id', '41', '--raw', '--subdir', 'DAGS_FOLDER/twitter_dag.py', '--cfg-path', '/tmp/tmp2ywj9ygt']
[2023-01-26T08:08:00.065+0000] {standard_task_runner.py:83} INFO - Job 41: Subtask complete_twitter_etl
[2023-01-26T08:08:02.043+0000] {task_command.py:388} INFO - Running <TaskInstance: twitter_dag.complete_twitter_etl scheduled__2020-11-26T00:00:00+00:00 [running]> on host 3143b9e5b257
[2023-01-26T08:08:02.443+0000] {taskinstance.py:1509} INFO - Exporting the following env vars:
AIRFLOW_CTX_DAG_EMAIL=***@example.com
AIRFLOW_CTX_DAG_OWNER=***
AIRFLOW_CTX_DAG_ID=twitter_dag
AIRFLOW_CTX_TASK_ID=complete_twitter_etl
AIRFLOW_CTX_EXECUTION_DATE=2020-11-26T00:00:00+00:00
AIRFLOW_CTX_TRY_NUMBER=1
AIRFLOW_CTX_DAG_RUN_ID=scheduled__2020-11-26T00:00:00+00:00
[2023-01-26T08:08:04.062+0000] {taskinstance.py:1768} ERROR - Task failed with exception
Traceback (most recent call last):
  File "/home/airflow/.local/lib/python3.7/site-packages/airflow/operators/python.py", line 175, in execute
    return_value = self.execute_callable()
  File "/home/airflow/.local/lib/python3.7/site-packages/airflow/operators/python.py", line 192, in execute_callable
    return self.python_callable(*self.op_args, **self.op_kwargs)
  File "/opt/airflow/dags/twitter_etl.py", line 64, in run_twitter_etl
    s3.Object(BUCKET_NAME, KEY).put(Body=csv_buffer.getvalue())
  File "/home/airflow/.local/lib/python3.7/site-packages/boto3/resources/factory.py", line 580, in do_action
    response = action(self, *args, **kwargs)
  File "/home/airflow/.local/lib/python3.7/site-packages/boto3/resources/action.py", line 88, in __call__
    response = getattr(parent.meta.client, operation_name)(*args, **params)
  File "/home/airflow/.local/lib/python3.7/site-packages/botocore/client.py", line 508, in _api_call
    return self._make_api_call(operation_name, kwargs)
  File "/home/airflow/.local/lib/python3.7/site-packages/botocore/client.py", line 915, in _make_api_call
    raise error_class(parsed_response, operation_name)
botocore.exceptions.ClientError: An error occurred (InvalidAccessKeyId) when calling the PutObject operation: The AWS Access Key Id you provided does not exist in our records.
[2023-01-26T08:08:04.089+0000] {taskinstance.py:1323} INFO - Marking task as UP_FOR_RETRY. dag_id=twitter_dag, task_id=complete_twitter_etl, execution_date=20201126T000000, start_date=20230126T080759, end_date=20230126T080804
[2023-01-26T08:08:04.137+0000] {standard_task_runner.py:105} ERROR - Failed to execute job 41 for task complete_twitter_etl (An error occurred (InvalidAccessKeyId) when calling the PutObject operation: The AWS Access Key Id you provided does not exist in our records.; 814)
[2023-01-26T08:08:04.359+0000] {local_task_job.py:208} INFO - Task exited with return code 1
[2023-01-26T08:08:04.560+0000] {taskinstance.py:2578} INFO - 0 downstream tasks scheduled from follow-on schedule check
[2023-01-26T09:08:37.468+0000] {taskinstance.py:1083} INFO - Dependencies all met for <TaskInstance: twitter_dag.complete_twitter_etl scheduled__2020-11-26T00:00:00+00:00 [queued]>
[2023-01-26T09:08:37.507+0000] {taskinstance.py:1083} INFO - Dependencies all met for <TaskInstance: twitter_dag.complete_twitter_etl scheduled__2020-11-26T00:00:00+00:00 [queued]>
[2023-01-26T09:08:37.509+0000] {taskinstance.py:1279} INFO - 
--------------------------------------------------------------------------------
[2023-01-26T09:08:37.510+0000] {taskinstance.py:1280} INFO - Starting attempt 1 of 2
[2023-01-26T09:08:37.511+0000] {taskinstance.py:1281} INFO - 
--------------------------------------------------------------------------------
[2023-01-26T09:08:40.179+0000] {taskinstance.py:1300} INFO - Executing <Task(PythonOperator): complete_twitter_etl> on 2020-11-26 00:00:00+00:00
[2023-01-26T09:08:40.239+0000] {standard_task_runner.py:55} INFO - Started process 229 to run task
[2023-01-26T09:08:40.270+0000] {standard_task_runner.py:82} INFO - Running: ['***', 'tasks', 'run', 'twitter_dag', 'complete_twitter_etl', 'scheduled__2020-11-26T00:00:00+00:00', '--job-id', '22', '--raw', '--subdir', 'DAGS_FOLDER/twitter_dag.py', '--cfg-path', '/tmp/tmp9fauql8j']
[2023-01-26T09:08:40.272+0000] {standard_task_runner.py:83} INFO - Job 22: Subtask complete_twitter_etl
[2023-01-26T09:08:41.947+0000] {task_command.py:388} INFO - Running <TaskInstance: twitter_dag.complete_twitter_etl scheduled__2020-11-26T00:00:00+00:00 [running]> on host d0fc3b00c15c
[2023-01-26T09:08:43.631+0000] {taskinstance.py:1509} INFO - Exporting the following env vars:
AIRFLOW_CTX_DAG_EMAIL=***@example.com
AIRFLOW_CTX_DAG_OWNER=***
AIRFLOW_CTX_DAG_ID=twitter_dag
AIRFLOW_CTX_TASK_ID=complete_twitter_etl
AIRFLOW_CTX_EXECUTION_DATE=2020-11-26T00:00:00+00:00
AIRFLOW_CTX_TRY_NUMBER=1
AIRFLOW_CTX_DAG_RUN_ID=scheduled__2020-11-26T00:00:00+00:00
[2023-01-26T09:08:48.147+0000] {python.py:177} INFO - Done. Returned value was: None
[2023-01-26T09:08:48.180+0000] {taskinstance.py:1323} INFO - Marking task as SUCCESS. dag_id=twitter_dag, task_id=complete_twitter_etl, execution_date=20201126T000000, start_date=20230126T090837, end_date=20230126T090848
[2023-01-26T09:08:48.510+0000] {local_task_job.py:208} INFO - Task exited with return code 0
[2023-01-26T09:08:48.660+0000] {taskinstance.py:2578} INFO - 0 downstream tasks scheduled from follow-on schedule check
