[2023-01-25T18:49:45.616+0000] {taskinstance.py:1083} INFO - Dependencies all met for <TaskInstance: twitter_dag.complete_twitter_etl scheduled__2020-12-30T00:00:00+00:00 [queued]>
[2023-01-25T18:49:45.861+0000] {taskinstance.py:1083} INFO - Dependencies all met for <TaskInstance: twitter_dag.complete_twitter_etl scheduled__2020-12-30T00:00:00+00:00 [queued]>
[2023-01-25T18:49:45.879+0000] {taskinstance.py:1279} INFO - 
--------------------------------------------------------------------------------
[2023-01-25T18:49:45.898+0000] {taskinstance.py:1280} INFO - Starting attempt 2 of 2
[2023-01-25T18:49:45.928+0000] {taskinstance.py:1281} INFO - 
--------------------------------------------------------------------------------
[2023-01-25T18:49:46.990+0000] {taskinstance.py:1300} INFO - Executing <Task(PythonOperator): complete_twitter_etl> on 2020-12-30 00:00:00+00:00
[2023-01-25T18:49:47.185+0000] {standard_task_runner.py:55} INFO - Started process 1326 to run task
[2023-01-25T18:49:47.302+0000] {standard_task_runner.py:82} INFO - Running: ['***', 'tasks', 'run', 'twitter_dag', 'complete_twitter_etl', 'scheduled__2020-12-30T00:00:00+00:00', '--job-id', '121', '--raw', '--subdir', 'DAGS_FOLDER/twitter_dag.py', '--cfg-path', '/tmp/tmppjn9wpqm']
[2023-01-25T18:49:47.335+0000] {standard_task_runner.py:83} INFO - Job 121: Subtask complete_twitter_etl
[2023-01-25T18:49:48.229+0000] {task_command.py:388} INFO - Running <TaskInstance: twitter_dag.complete_twitter_etl scheduled__2020-12-30T00:00:00+00:00 [running]> on host 512d0ff0785b
[2023-01-25T18:49:51.726+0000] {taskinstance.py:1509} INFO - Exporting the following env vars:
AIRFLOW_CTX_DAG_EMAIL=***@example.com
AIRFLOW_CTX_DAG_OWNER=***
AIRFLOW_CTX_DAG_ID=twitter_dag
AIRFLOW_CTX_TASK_ID=complete_twitter_etl
AIRFLOW_CTX_EXECUTION_DATE=2020-12-30T00:00:00+00:00
AIRFLOW_CTX_TRY_NUMBER=2
AIRFLOW_CTX_DAG_RUN_ID=scheduled__2020-12-30T00:00:00+00:00
[2023-01-25T18:49:57.665+0000] {taskinstance.py:1768} ERROR - Task failed with exception
Traceback (most recent call last):
  File "/home/airflow/.local/lib/python3.7/site-packages/s3fs/core.py", line 112, in _error_wrapper
    return await func(*args, **kwargs)
  File "/home/airflow/.local/lib/python3.7/site-packages/aiobotocore/client.py", line 358, in _make_api_call
    raise error_class(parsed_response, operation_name)
botocore.exceptions.ClientError: An error occurred (AccessDenied) when calling the CreateBucket operation: Anonymous access is forbidden for this operation

The above exception was the direct cause of the following exception:

Traceback (most recent call last):
  File "/home/airflow/.local/lib/python3.7/site-packages/airflow/operators/python.py", line 175, in execute
    return_value = self.execute_callable()
  File "/home/airflow/.local/lib/python3.7/site-packages/airflow/operators/python.py", line 192, in execute_callable
    return self.python_callable(*self.op_args, **self.op_kwargs)
  File "/opt/airflow/dags/twitter_etl.py", line 46, in run_twitter_etl
    df.to_csv("s3://jinchoi-airflow-bucket/data/elonmusk_tweets.csv")
  File "/home/airflow/.local/lib/python3.7/site-packages/pandas/core/generic.py", line 3482, in to_csv
    storage_options=storage_options,
  File "/home/airflow/.local/lib/python3.7/site-packages/pandas/io/formats/format.py", line 1105, in to_csv
    csv_formatter.save()
  File "/home/airflow/.local/lib/python3.7/site-packages/pandas/io/formats/csvs.py", line 243, in save
    storage_options=self.storage_options,
  File "/home/airflow/.local/lib/python3.7/site-packages/pandas/io/common.py", line 614, in get_handle
    storage_options=storage_options,
  File "/home/airflow/.local/lib/python3.7/site-packages/pandas/io/common.py", line 370, in _get_filepath_or_buffer
    filepath_or_buffer, mode=fsspec_mode, **(storage_options or {})
  File "/home/airflow/.local/lib/python3.7/site-packages/fsspec/core.py", line 428, in open
    **kwargs,
  File "/home/airflow/.local/lib/python3.7/site-packages/fsspec/core.py", line 283, in open_files
    [fs.makedirs(parent, exist_ok=True) for parent in parents]
  File "/home/airflow/.local/lib/python3.7/site-packages/fsspec/core.py", line 283, in <listcomp>
    [fs.makedirs(parent, exist_ok=True) for parent in parents]
  File "/home/airflow/.local/lib/python3.7/site-packages/fsspec/asyn.py", line 114, in wrapper
    return sync(self.loop, func, *args, **kwargs)
  File "/home/airflow/.local/lib/python3.7/site-packages/fsspec/asyn.py", line 99, in sync
    raise return_result
  File "/home/airflow/.local/lib/python3.7/site-packages/fsspec/asyn.py", line 54, in _runner
    result[0] = await coro
  File "/home/airflow/.local/lib/python3.7/site-packages/s3fs/core.py", line 883, in _makedirs
    await self._mkdir(path, create_parents=True)
  File "/home/airflow/.local/lib/python3.7/site-packages/s3fs/core.py", line 868, in _mkdir
    await self._call_s3("create_bucket", **params)
  File "/home/airflow/.local/lib/python3.7/site-packages/s3fs/core.py", line 340, in _call_s3
    method, kwargs=additional_kwargs, retries=self.retries
  File "/home/airflow/.local/lib/python3.7/site-packages/s3fs/core.py", line 139, in _error_wrapper
    raise err
PermissionError: Anonymous access is forbidden for this operation
[2023-01-25T18:49:57.742+0000] {taskinstance.py:1323} INFO - Marking task as FAILED. dag_id=twitter_dag, task_id=complete_twitter_etl, execution_date=20201230T000000, start_date=20230125T184945, end_date=20230125T184957
[2023-01-25T18:49:57.825+0000] {standard_task_runner.py:105} ERROR - Failed to execute job 121 for task complete_twitter_etl (Anonymous access is forbidden for this operation; 1326)
[2023-01-25T18:49:57.919+0000] {local_task_job.py:208} INFO - Task exited with return code 1
[2023-01-25T18:49:57.987+0000] {taskinstance.py:2578} INFO - 0 downstream tasks scheduled from follow-on schedule check
[2023-01-26T06:21:12.505+0000] {taskinstance.py:1083} INFO - Dependencies all met for <TaskInstance: twitter_dag.complete_twitter_etl scheduled__2020-12-30T00:00:00+00:00 [queued]>
[2023-01-26T06:21:12.533+0000] {taskinstance.py:1083} INFO - Dependencies all met for <TaskInstance: twitter_dag.complete_twitter_etl scheduled__2020-12-30T00:00:00+00:00 [queued]>
[2023-01-26T06:21:12.535+0000] {taskinstance.py:1279} INFO - 
--------------------------------------------------------------------------------
[2023-01-26T06:21:12.536+0000] {taskinstance.py:1280} INFO - Starting attempt 2 of 2
[2023-01-26T06:21:12.537+0000] {taskinstance.py:1281} INFO - 
--------------------------------------------------------------------------------
[2023-01-26T06:21:12.583+0000] {taskinstance.py:1300} INFO - Executing <Task(PythonOperator): complete_twitter_etl> on 2020-12-30 00:00:00+00:00
[2023-01-26T06:21:12.601+0000] {standard_task_runner.py:55} INFO - Started process 2337 to run task
[2023-01-26T06:21:12.609+0000] {standard_task_runner.py:82} INFO - Running: ['***', 'tasks', 'run', 'twitter_dag', 'complete_twitter_etl', 'scheduled__2020-12-30T00:00:00+00:00', '--job-id', '123', '--raw', '--subdir', 'DAGS_FOLDER/twitter_dag.py', '--cfg-path', '/tmp/tmpuah8jz0z']
[2023-01-26T06:21:12.614+0000] {standard_task_runner.py:83} INFO - Job 123: Subtask complete_twitter_etl
[2023-01-26T06:21:13.828+0000] {task_command.py:388} INFO - Running <TaskInstance: twitter_dag.complete_twitter_etl scheduled__2020-12-30T00:00:00+00:00 [running]> on host 864c120ca3c2
[2023-01-26T06:21:14.095+0000] {taskinstance.py:1509} INFO - Exporting the following env vars:
AIRFLOW_CTX_DAG_EMAIL=***@example.com
AIRFLOW_CTX_DAG_OWNER=***
AIRFLOW_CTX_DAG_ID=twitter_dag
AIRFLOW_CTX_TASK_ID=complete_twitter_etl
AIRFLOW_CTX_EXECUTION_DATE=2020-12-30T00:00:00+00:00
AIRFLOW_CTX_TRY_NUMBER=2
AIRFLOW_CTX_DAG_RUN_ID=scheduled__2020-12-30T00:00:00+00:00
[2023-01-26T06:21:14.606+0000] {taskinstance.py:1768} ERROR - Task failed with exception
Traceback (most recent call last):
  File "/home/airflow/.local/lib/python3.7/site-packages/airflow/operators/python.py", line 175, in execute
    return_value = self.execute_callable()
  File "/home/airflow/.local/lib/python3.7/site-packages/airflow/operators/python.py", line 192, in execute_callable
    return self.python_callable(*self.op_args, **self.op_kwargs)
  File "/opt/airflow/dags/twitter_etl.py", line 51, in run_twitter_etl
    aws_access_key_id=os.environ['AWS_ACCESS_KEY_ID'],
  File "/usr/local/lib/python3.7/os.py", line 681, in __getitem__
    raise KeyError(key) from None
KeyError: 'AWS_ACCESS_KEY_ID'
[2023-01-26T06:21:14.645+0000] {taskinstance.py:1323} INFO - Marking task as FAILED. dag_id=twitter_dag, task_id=complete_twitter_etl, execution_date=20201230T000000, start_date=20230126T062112, end_date=20230126T062114
[2023-01-26T06:21:14.728+0000] {standard_task_runner.py:105} ERROR - Failed to execute job 123 for task complete_twitter_etl ('AWS_ACCESS_KEY_ID'; 2337)
[2023-01-26T06:21:14.896+0000] {local_task_job.py:208} INFO - Task exited with return code 1
[2023-01-26T06:21:14.950+0000] {taskinstance.py:2578} INFO - 0 downstream tasks scheduled from follow-on schedule check
[2023-01-26T08:24:11.589+0000] {taskinstance.py:1083} INFO - Dependencies all met for <TaskInstance: twitter_dag.complete_twitter_etl scheduled__2020-12-30T00:00:00+00:00 [queued]>
[2023-01-26T08:24:11.619+0000] {taskinstance.py:1083} INFO - Dependencies all met for <TaskInstance: twitter_dag.complete_twitter_etl scheduled__2020-12-30T00:00:00+00:00 [queued]>
[2023-01-26T08:24:11.622+0000] {taskinstance.py:1279} INFO - 
--------------------------------------------------------------------------------
[2023-01-26T08:24:11.624+0000] {taskinstance.py:1280} INFO - Starting attempt 2 of 2
[2023-01-26T08:24:11.625+0000] {taskinstance.py:1281} INFO - 
--------------------------------------------------------------------------------
[2023-01-26T08:24:11.667+0000] {taskinstance.py:1300} INFO - Executing <Task(PythonOperator): complete_twitter_etl> on 2020-12-30 00:00:00+00:00
[2023-01-26T08:24:11.675+0000] {standard_task_runner.py:55} INFO - Started process 1960 to run task
[2023-01-26T08:24:11.691+0000] {standard_task_runner.py:82} INFO - Running: ['***', 'tasks', 'run', 'twitter_dag', 'complete_twitter_etl', 'scheduled__2020-12-30T00:00:00+00:00', '--job-id', '128', '--raw', '--subdir', 'DAGS_FOLDER/twitter_dag.py', '--cfg-path', '/tmp/tmpmbn1sw6a']
[2023-01-26T08:24:11.695+0000] {standard_task_runner.py:83} INFO - Job 128: Subtask complete_twitter_etl
[2023-01-26T08:24:12.601+0000] {task_command.py:388} INFO - Running <TaskInstance: twitter_dag.complete_twitter_etl scheduled__2020-12-30T00:00:00+00:00 [running]> on host 3143b9e5b257
[2023-01-26T08:24:12.991+0000] {taskinstance.py:1509} INFO - Exporting the following env vars:
AIRFLOW_CTX_DAG_EMAIL=***@example.com
AIRFLOW_CTX_DAG_OWNER=***
AIRFLOW_CTX_DAG_ID=twitter_dag
AIRFLOW_CTX_TASK_ID=complete_twitter_etl
AIRFLOW_CTX_EXECUTION_DATE=2020-12-30T00:00:00+00:00
AIRFLOW_CTX_TRY_NUMBER=2
AIRFLOW_CTX_DAG_RUN_ID=scheduled__2020-12-30T00:00:00+00:00
[2023-01-26T08:24:14.301+0000] {taskinstance.py:1768} ERROR - Task failed with exception
Traceback (most recent call last):
  File "/home/airflow/.local/lib/python3.7/site-packages/airflow/operators/python.py", line 175, in execute
    return_value = self.execute_callable()
  File "/home/airflow/.local/lib/python3.7/site-packages/airflow/operators/python.py", line 192, in execute_callable
    return self.python_callable(*self.op_args, **self.op_kwargs)
  File "/opt/airflow/dags/twitter_etl.py", line 64, in run_twitter_etl
    s3.Object(BUCKET_NAME, KEY).put(Body=csv_buffer.getvalue())
  File "/home/airflow/.local/lib/python3.7/site-packages/boto3/resources/factory.py", line 580, in do_action
    response = action(self, *args, **kwargs)
  File "/home/airflow/.local/lib/python3.7/site-packages/boto3/resources/action.py", line 88, in __call__
    response = getattr(parent.meta.client, operation_name)(*args, **params)
  File "/home/airflow/.local/lib/python3.7/site-packages/botocore/client.py", line 508, in _api_call
    return self._make_api_call(operation_name, kwargs)
  File "/home/airflow/.local/lib/python3.7/site-packages/botocore/client.py", line 915, in _make_api_call
    raise error_class(parsed_response, operation_name)
botocore.exceptions.ClientError: An error occurred (InvalidAccessKeyId) when calling the PutObject operation: The AWS Access Key Id you provided does not exist in our records.
[2023-01-26T08:24:14.320+0000] {taskinstance.py:1323} INFO - Marking task as FAILED. dag_id=twitter_dag, task_id=complete_twitter_etl, execution_date=20201230T000000, start_date=20230126T082411, end_date=20230126T082414
[2023-01-26T08:24:14.363+0000] {standard_task_runner.py:105} ERROR - Failed to execute job 128 for task complete_twitter_etl (An error occurred (InvalidAccessKeyId) when calling the PutObject operation: The AWS Access Key Id you provided does not exist in our records.; 1960)
[2023-01-26T08:24:14.470+0000] {local_task_job.py:208} INFO - Task exited with return code 1
[2023-01-26T08:24:14.641+0000] {taskinstance.py:2578} INFO - 0 downstream tasks scheduled from follow-on schedule check
