[2023-01-26T07:04:42.352+0000] {taskinstance.py:1083} INFO - Dependencies all met for <TaskInstance: twitter_dag.complete_twitter_etl manual__2023-01-26T06:59:13.978474+00:00 [queued]>
[2023-01-26T07:04:42.374+0000] {taskinstance.py:1083} INFO - Dependencies all met for <TaskInstance: twitter_dag.complete_twitter_etl manual__2023-01-26T06:59:13.978474+00:00 [queued]>
[2023-01-26T07:04:42.376+0000] {taskinstance.py:1279} INFO - 
--------------------------------------------------------------------------------
[2023-01-26T07:04:42.377+0000] {taskinstance.py:1280} INFO - Starting attempt 2 of 2
[2023-01-26T07:04:42.378+0000] {taskinstance.py:1281} INFO - 
--------------------------------------------------------------------------------
[2023-01-26T07:04:42.421+0000] {taskinstance.py:1300} INFO - Executing <Task(PythonOperator): complete_twitter_etl> on 2023-01-26 06:59:13.978474+00:00
[2023-01-26T07:04:42.441+0000] {standard_task_runner.py:55} INFO - Started process 454 to run task
[2023-01-26T07:04:42.457+0000] {standard_task_runner.py:82} INFO - Running: ['***', 'tasks', 'run', 'twitter_dag', 'complete_twitter_etl', 'manual__2023-01-26T06:59:13.978474+00:00', '--job-id', '24', '--raw', '--subdir', 'DAGS_FOLDER/twitter_dag.py', '--cfg-path', '/tmp/tmp8c6r2y9k']
[2023-01-26T07:04:42.459+0000] {standard_task_runner.py:83} INFO - Job 24: Subtask complete_twitter_etl
[2023-01-26T07:04:44.334+0000] {task_command.py:388} INFO - Running <TaskInstance: twitter_dag.complete_twitter_etl manual__2023-01-26T06:59:13.978474+00:00 [running]> on host 2221c1ebf970
[2023-01-26T07:04:44.777+0000] {taskinstance.py:1509} INFO - Exporting the following env vars:
AIRFLOW_CTX_DAG_EMAIL=***@example.com
AIRFLOW_CTX_DAG_OWNER=***
AIRFLOW_CTX_DAG_ID=twitter_dag
AIRFLOW_CTX_TASK_ID=complete_twitter_etl
AIRFLOW_CTX_EXECUTION_DATE=2023-01-26T06:59:13.978474+00:00
AIRFLOW_CTX_TRY_NUMBER=2
AIRFLOW_CTX_DAG_RUN_ID=manual__2023-01-26T06:59:13.978474+00:00
[2023-01-26T07:04:45.982+0000] {taskinstance.py:1768} ERROR - Task failed with exception
Traceback (most recent call last):
  File "/home/airflow/.local/lib/python3.7/site-packages/airflow/operators/python.py", line 175, in execute
    return_value = self.execute_callable()
  File "/home/airflow/.local/lib/python3.7/site-packages/airflow/operators/python.py", line 192, in execute_callable
    return self.python_callable(*self.op_args, **self.op_kwargs)
  File "/opt/airflow/dags/twitter_etl.py", line 63, in run_twitter_etl
    s3.Object(BUCKET_NAME, KEY).put(Body=csv_buffer.getvalue())
  File "/home/airflow/.local/lib/python3.7/site-packages/botocore/client.py", line 839, in __getattr__
    f"'{self.__class__.__name__}' object has no attribute '{item}'"
AttributeError: 'S3' object has no attribute 'Object'
[2023-01-26T07:04:46.022+0000] {taskinstance.py:1323} INFO - Marking task as FAILED. dag_id=twitter_dag, task_id=complete_twitter_etl, execution_date=20230126T065913, start_date=20230126T070442, end_date=20230126T070446
[2023-01-26T07:04:46.079+0000] {standard_task_runner.py:105} ERROR - Failed to execute job 24 for task complete_twitter_etl ('S3' object has no attribute 'Object'; 454)
[2023-01-26T07:04:46.316+0000] {local_task_job.py:208} INFO - Task exited with return code 1
[2023-01-26T07:04:46.405+0000] {taskinstance.py:2578} INFO - 0 downstream tasks scheduled from follow-on schedule check
