[2023-01-25T18:56:35.411+0000] {taskinstance.py:1083} INFO - Dependencies all met for <TaskInstance: twitter_dag.complete_twitter_etl scheduled__2021-03-02T00:00:00+00:00 [queued]>
[2023-01-25T18:56:35.718+0000] {taskinstance.py:1083} INFO - Dependencies all met for <TaskInstance: twitter_dag.complete_twitter_etl scheduled__2021-03-02T00:00:00+00:00 [queued]>
[2023-01-25T18:56:35.723+0000] {taskinstance.py:1279} INFO - 
--------------------------------------------------------------------------------
[2023-01-25T18:56:35.740+0000] {taskinstance.py:1280} INFO - Starting attempt 1 of 2
[2023-01-25T18:56:35.764+0000] {taskinstance.py:1281} INFO - 
--------------------------------------------------------------------------------
[2023-01-25T18:56:36.480+0000] {taskinstance.py:1300} INFO - Executing <Task(PythonOperator): complete_twitter_etl> on 2021-03-02 00:00:00+00:00
[2023-01-25T18:56:36.675+0000] {standard_task_runner.py:82} INFO - Running: ['***', 'tasks', 'run', 'twitter_dag', 'complete_twitter_etl', 'scheduled__2021-03-02T00:00:00+00:00', '--job-id', '223', '--raw', '--subdir', 'DAGS_FOLDER/twitter_dag.py', '--cfg-path', '/tmp/tmp2px4f2ch']
[2023-01-25T18:56:36.688+0000] {standard_task_runner.py:83} INFO - Job 223: Subtask complete_twitter_etl
[2023-01-25T18:56:36.626+0000] {standard_task_runner.py:55} INFO - Started process 2221 to run task
[2023-01-25T18:56:38.173+0000] {task_command.py:388} INFO - Running <TaskInstance: twitter_dag.complete_twitter_etl scheduled__2021-03-02T00:00:00+00:00 [running]> on host 512d0ff0785b
[2023-01-25T18:56:42.275+0000] {taskinstance.py:1509} INFO - Exporting the following env vars:
AIRFLOW_CTX_DAG_EMAIL=***@example.com
AIRFLOW_CTX_DAG_OWNER=***
AIRFLOW_CTX_DAG_ID=twitter_dag
AIRFLOW_CTX_TASK_ID=complete_twitter_etl
AIRFLOW_CTX_EXECUTION_DATE=2021-03-02T00:00:00+00:00
AIRFLOW_CTX_TRY_NUMBER=1
AIRFLOW_CTX_DAG_RUN_ID=scheduled__2021-03-02T00:00:00+00:00
[2023-01-25T18:56:49.080+0000] {taskinstance.py:1768} ERROR - Task failed with exception
Traceback (most recent call last):
  File "/home/airflow/.local/lib/python3.7/site-packages/s3fs/core.py", line 112, in _error_wrapper
    return await func(*args, **kwargs)
  File "/home/airflow/.local/lib/python3.7/site-packages/aiobotocore/client.py", line 358, in _make_api_call
    raise error_class(parsed_response, operation_name)
botocore.exceptions.ClientError: An error occurred (AccessDenied) when calling the CreateBucket operation: Anonymous access is forbidden for this operation

The above exception was the direct cause of the following exception:

Traceback (most recent call last):
  File "/home/airflow/.local/lib/python3.7/site-packages/airflow/operators/python.py", line 175, in execute
    return_value = self.execute_callable()
  File "/home/airflow/.local/lib/python3.7/site-packages/airflow/operators/python.py", line 192, in execute_callable
    return self.python_callable(*self.op_args, **self.op_kwargs)
  File "/opt/airflow/dags/twitter_etl.py", line 46, in run_twitter_etl
    df.to_csv("s3://jinchoi-airflow-bucket/data/elonmusk_tweets.csv")
  File "/home/airflow/.local/lib/python3.7/site-packages/pandas/core/generic.py", line 3482, in to_csv
    storage_options=storage_options,
  File "/home/airflow/.local/lib/python3.7/site-packages/pandas/io/formats/format.py", line 1105, in to_csv
    csv_formatter.save()
  File "/home/airflow/.local/lib/python3.7/site-packages/pandas/io/formats/csvs.py", line 243, in save
    storage_options=self.storage_options,
  File "/home/airflow/.local/lib/python3.7/site-packages/pandas/io/common.py", line 614, in get_handle
    storage_options=storage_options,
  File "/home/airflow/.local/lib/python3.7/site-packages/pandas/io/common.py", line 370, in _get_filepath_or_buffer
    filepath_or_buffer, mode=fsspec_mode, **(storage_options or {})
  File "/home/airflow/.local/lib/python3.7/site-packages/fsspec/core.py", line 428, in open
    **kwargs,
  File "/home/airflow/.local/lib/python3.7/site-packages/fsspec/core.py", line 283, in open_files
    [fs.makedirs(parent, exist_ok=True) for parent in parents]
  File "/home/airflow/.local/lib/python3.7/site-packages/fsspec/core.py", line 283, in <listcomp>
    [fs.makedirs(parent, exist_ok=True) for parent in parents]
  File "/home/airflow/.local/lib/python3.7/site-packages/fsspec/asyn.py", line 114, in wrapper
    return sync(self.loop, func, *args, **kwargs)
  File "/home/airflow/.local/lib/python3.7/site-packages/fsspec/asyn.py", line 99, in sync
    raise return_result
  File "/home/airflow/.local/lib/python3.7/site-packages/fsspec/asyn.py", line 54, in _runner
    result[0] = await coro
  File "/home/airflow/.local/lib/python3.7/site-packages/s3fs/core.py", line 883, in _makedirs
    await self._mkdir(path, create_parents=True)
  File "/home/airflow/.local/lib/python3.7/site-packages/s3fs/core.py", line 868, in _mkdir
    await self._call_s3("create_bucket", **params)
  File "/home/airflow/.local/lib/python3.7/site-packages/s3fs/core.py", line 340, in _call_s3
    method, kwargs=additional_kwargs, retries=self.retries
  File "/home/airflow/.local/lib/python3.7/site-packages/s3fs/core.py", line 139, in _error_wrapper
    raise err
PermissionError: Anonymous access is forbidden for this operation
[2023-01-25T18:56:49.197+0000] {taskinstance.py:1323} INFO - Marking task as UP_FOR_RETRY. dag_id=twitter_dag, task_id=complete_twitter_etl, execution_date=20210302T000000, start_date=20230125T185635, end_date=20230125T185649
[2023-01-25T18:56:49.324+0000] {standard_task_runner.py:105} ERROR - Failed to execute job 223 for task complete_twitter_etl (Anonymous access is forbidden for this operation; 2221)
[2023-01-25T18:56:49.626+0000] {local_task_job.py:208} INFO - Task exited with return code 1
[2023-01-25T18:56:49.884+0000] {taskinstance.py:2578} INFO - 0 downstream tasks scheduled from follow-on schedule check
[2023-01-26T06:48:31.694+0000] {taskinstance.py:1083} INFO - Dependencies all met for <TaskInstance: twitter_dag.complete_twitter_etl scheduled__2021-03-02T00:00:00+00:00 [queued]>
[2023-01-26T06:48:31.718+0000] {taskinstance.py:1083} INFO - Dependencies all met for <TaskInstance: twitter_dag.complete_twitter_etl scheduled__2021-03-02T00:00:00+00:00 [queued]>
[2023-01-26T06:48:31.721+0000] {taskinstance.py:1279} INFO - 
--------------------------------------------------------------------------------
[2023-01-26T06:48:31.726+0000] {taskinstance.py:1280} INFO - Starting attempt 1 of 2
[2023-01-26T06:48:31.730+0000] {taskinstance.py:1281} INFO - 
--------------------------------------------------------------------------------
[2023-01-26T06:48:31.813+0000] {taskinstance.py:1300} INFO - Executing <Task(PythonOperator): complete_twitter_etl> on 2021-03-02 00:00:00+00:00
[2023-01-26T06:48:31.837+0000] {standard_task_runner.py:55} INFO - Started process 3261 to run task
[2023-01-26T06:48:31.867+0000] {standard_task_runner.py:82} INFO - Running: ['***', 'tasks', 'run', 'twitter_dag', 'complete_twitter_etl', 'scheduled__2021-03-02T00:00:00+00:00', '--job-id', '217', '--raw', '--subdir', 'DAGS_FOLDER/twitter_dag.py', '--cfg-path', '/tmp/tmpo1spvfn7']
[2023-01-26T06:48:31.874+0000] {standard_task_runner.py:83} INFO - Job 217: Subtask complete_twitter_etl
[2023-01-26T06:48:33.007+0000] {task_command.py:388} INFO - Running <TaskInstance: twitter_dag.complete_twitter_etl scheduled__2021-03-02T00:00:00+00:00 [running]> on host 864c120ca3c2
[2023-01-26T06:48:33.401+0000] {taskinstance.py:1509} INFO - Exporting the following env vars:
AIRFLOW_CTX_DAG_EMAIL=***@example.com
AIRFLOW_CTX_DAG_OWNER=***
AIRFLOW_CTX_DAG_ID=twitter_dag
AIRFLOW_CTX_TASK_ID=complete_twitter_etl
AIRFLOW_CTX_EXECUTION_DATE=2021-03-02T00:00:00+00:00
AIRFLOW_CTX_TRY_NUMBER=1
AIRFLOW_CTX_DAG_RUN_ID=scheduled__2021-03-02T00:00:00+00:00
[2023-01-26T06:48:34.051+0000] {taskinstance.py:1768} ERROR - Task failed with exception
Traceback (most recent call last):
  File "/home/airflow/.local/lib/python3.7/site-packages/airflow/operators/python.py", line 175, in execute
    return_value = self.execute_callable()
  File "/home/airflow/.local/lib/python3.7/site-packages/airflow/operators/python.py", line 192, in execute_callable
    return self.python_callable(*self.op_args, **self.op_kwargs)
  File "/opt/airflow/dags/twitter_etl.py", line 51, in run_twitter_etl
    aws_access_key_id=os.environ['aws_access_key_id'],
  File "/usr/local/lib/python3.7/os.py", line 681, in __getitem__
    raise KeyError(key) from None
KeyError: 'aws_access_key_id'
[2023-01-26T06:48:34.080+0000] {taskinstance.py:1323} INFO - Marking task as UP_FOR_RETRY. dag_id=twitter_dag, task_id=complete_twitter_etl, execution_date=20210302T000000, start_date=20230126T064831, end_date=20230126T064834
[2023-01-26T06:48:34.112+0000] {standard_task_runner.py:105} ERROR - Failed to execute job 217 for task complete_twitter_etl ('aws_access_key_id'; 3261)
[2023-01-26T06:48:34.194+0000] {local_task_job.py:208} INFO - Task exited with return code 1
[2023-01-26T06:48:34.235+0000] {taskinstance.py:2578} INFO - 0 downstream tasks scheduled from follow-on schedule check
[2023-01-26T07:13:37.179+0000] {taskinstance.py:1083} INFO - Dependencies all met for <TaskInstance: twitter_dag.complete_twitter_etl scheduled__2021-03-02T00:00:00+00:00 [queued]>
[2023-01-26T07:13:37.267+0000] {taskinstance.py:1083} INFO - Dependencies all met for <TaskInstance: twitter_dag.complete_twitter_etl scheduled__2021-03-02T00:00:00+00:00 [queued]>
[2023-01-26T07:13:37.269+0000] {taskinstance.py:1279} INFO - 
--------------------------------------------------------------------------------
[2023-01-26T07:13:37.272+0000] {taskinstance.py:1280} INFO - Starting attempt 1 of 2
[2023-01-26T07:13:37.274+0000] {taskinstance.py:1281} INFO - 
--------------------------------------------------------------------------------
[2023-01-26T07:13:37.356+0000] {taskinstance.py:1300} INFO - Executing <Task(PythonOperator): complete_twitter_etl> on 2021-03-02 00:00:00+00:00
[2023-01-26T07:13:37.382+0000] {standard_task_runner.py:55} INFO - Started process 1267 to run task
[2023-01-26T07:13:37.444+0000] {standard_task_runner.py:82} INFO - Running: ['***', 'tasks', 'run', 'twitter_dag', 'complete_twitter_etl', 'scheduled__2021-03-02T00:00:00+00:00', '--job-id', '153', '--raw', '--subdir', 'DAGS_FOLDER/twitter_dag.py', '--cfg-path', '/tmp/tmp53iql2ht']
[2023-01-26T07:13:37.456+0000] {standard_task_runner.py:83} INFO - Job 153: Subtask complete_twitter_etl
[2023-01-26T07:13:39.519+0000] {task_command.py:388} INFO - Running <TaskInstance: twitter_dag.complete_twitter_etl scheduled__2021-03-02T00:00:00+00:00 [running]> on host 2221c1ebf970
[2023-01-26T07:13:40.122+0000] {taskinstance.py:1509} INFO - Exporting the following env vars:
AIRFLOW_CTX_DAG_EMAIL=***@example.com
AIRFLOW_CTX_DAG_OWNER=***
AIRFLOW_CTX_DAG_ID=twitter_dag
AIRFLOW_CTX_TASK_ID=complete_twitter_etl
AIRFLOW_CTX_EXECUTION_DATE=2021-03-02T00:00:00+00:00
AIRFLOW_CTX_TRY_NUMBER=1
AIRFLOW_CTX_DAG_RUN_ID=scheduled__2021-03-02T00:00:00+00:00
[2023-01-26T07:13:42.544+0000] {python.py:177} INFO - Done. Returned value was: None
[2023-01-26T07:13:42.624+0000] {taskinstance.py:1323} INFO - Marking task as SUCCESS. dag_id=twitter_dag, task_id=complete_twitter_etl, execution_date=20210302T000000, start_date=20230126T071337, end_date=20230126T071342
[2023-01-26T07:13:42.928+0000] {local_task_job.py:208} INFO - Task exited with return code 0
[2023-01-26T07:13:44.057+0000] {taskinstance.py:2578} INFO - 0 downstream tasks scheduled from follow-on schedule check
[2023-01-26T09:11:09.946+0000] {taskinstance.py:1083} INFO - Dependencies all met for <TaskInstance: twitter_dag.complete_twitter_etl scheduled__2021-03-02T00:00:00+00:00 [queued]>
[2023-01-26T09:11:09.980+0000] {taskinstance.py:1083} INFO - Dependencies all met for <TaskInstance: twitter_dag.complete_twitter_etl scheduled__2021-03-02T00:00:00+00:00 [queued]>
[2023-01-26T09:11:09.989+0000] {taskinstance.py:1279} INFO - 
--------------------------------------------------------------------------------
[2023-01-26T09:11:09.990+0000] {taskinstance.py:1280} INFO - Starting attempt 1 of 2
[2023-01-26T09:11:09.992+0000] {taskinstance.py:1281} INFO - 
--------------------------------------------------------------------------------
[2023-01-26T09:11:10.066+0000] {taskinstance.py:1300} INFO - Executing <Task(PythonOperator): complete_twitter_etl> on 2021-03-02 00:00:00+00:00
[2023-01-26T09:11:10.099+0000] {standard_task_runner.py:55} INFO - Started process 587 to run task
[2023-01-26T09:11:10.144+0000] {standard_task_runner.py:82} INFO - Running: ['***', 'tasks', 'run', 'twitter_dag', 'complete_twitter_etl', 'scheduled__2021-03-02T00:00:00+00:00', '--job-id', '118', '--raw', '--subdir', 'DAGS_FOLDER/twitter_dag.py', '--cfg-path', '/tmp/tmpf8n84sfv']
[2023-01-26T09:11:10.156+0000] {standard_task_runner.py:83} INFO - Job 118: Subtask complete_twitter_etl
[2023-01-26T09:11:11.525+0000] {task_command.py:388} INFO - Running <TaskInstance: twitter_dag.complete_twitter_etl scheduled__2021-03-02T00:00:00+00:00 [running]> on host d0fc3b00c15c
[2023-01-26T09:11:12.168+0000] {taskinstance.py:1509} INFO - Exporting the following env vars:
AIRFLOW_CTX_DAG_EMAIL=***@example.com
AIRFLOW_CTX_DAG_OWNER=***
AIRFLOW_CTX_DAG_ID=twitter_dag
AIRFLOW_CTX_TASK_ID=complete_twitter_etl
AIRFLOW_CTX_EXECUTION_DATE=2021-03-02T00:00:00+00:00
AIRFLOW_CTX_TRY_NUMBER=1
AIRFLOW_CTX_DAG_RUN_ID=scheduled__2021-03-02T00:00:00+00:00
[2023-01-26T09:11:15.436+0000] {python.py:177} INFO - Done. Returned value was: None
[2023-01-26T09:11:15.458+0000] {taskinstance.py:1323} INFO - Marking task as SUCCESS. dag_id=twitter_dag, task_id=complete_twitter_etl, execution_date=20210302T000000, start_date=20230126T091109, end_date=20230126T091115
[2023-01-26T09:11:15.548+0000] {local_task_job.py:208} INFO - Task exited with return code 0
[2023-01-26T09:11:15.757+0000] {taskinstance.py:2578} INFO - 0 downstream tasks scheduled from follow-on schedule check
