[2023-01-25T18:58:29.028+0000] {taskinstance.py:1083} INFO - Dependencies all met for <TaskInstance: twitter_dag.complete_twitter_etl scheduled__2021-03-14T00:00:00+00:00 [queued]>
[2023-01-25T18:58:29.077+0000] {taskinstance.py:1083} INFO - Dependencies all met for <TaskInstance: twitter_dag.complete_twitter_etl scheduled__2021-03-14T00:00:00+00:00 [queued]>
[2023-01-25T18:58:29.083+0000] {taskinstance.py:1279} INFO - 
--------------------------------------------------------------------------------
[2023-01-25T18:58:29.086+0000] {taskinstance.py:1280} INFO - Starting attempt 1 of 2
[2023-01-25T18:58:29.088+0000] {taskinstance.py:1281} INFO - 
--------------------------------------------------------------------------------
[2023-01-25T18:58:29.219+0000] {taskinstance.py:1300} INFO - Executing <Task(PythonOperator): complete_twitter_etl> on 2021-03-14 00:00:00+00:00
[2023-01-25T18:58:29.243+0000] {standard_task_runner.py:55} INFO - Started process 2452 to run task
[2023-01-25T18:58:29.262+0000] {standard_task_runner.py:82} INFO - Running: ['***', 'tasks', 'run', 'twitter_dag', 'complete_twitter_etl', 'scheduled__2021-03-14T00:00:00+00:00', '--job-id', '250', '--raw', '--subdir', 'DAGS_FOLDER/twitter_dag.py', '--cfg-path', '/tmp/tmpvp5f4k2d']
[2023-01-25T18:58:29.273+0000] {standard_task_runner.py:83} INFO - Job 250: Subtask complete_twitter_etl
[2023-01-25T18:58:29.696+0000] {task_command.py:388} INFO - Running <TaskInstance: twitter_dag.complete_twitter_etl scheduled__2021-03-14T00:00:00+00:00 [running]> on host 512d0ff0785b
[2023-01-25T18:58:30.587+0000] {taskinstance.py:1509} INFO - Exporting the following env vars:
AIRFLOW_CTX_DAG_EMAIL=***@example.com
AIRFLOW_CTX_DAG_OWNER=***
AIRFLOW_CTX_DAG_ID=twitter_dag
AIRFLOW_CTX_TASK_ID=complete_twitter_etl
AIRFLOW_CTX_EXECUTION_DATE=2021-03-14T00:00:00+00:00
AIRFLOW_CTX_TRY_NUMBER=1
AIRFLOW_CTX_DAG_RUN_ID=scheduled__2021-03-14T00:00:00+00:00
[2023-01-25T18:58:36.084+0000] {taskinstance.py:1768} ERROR - Task failed with exception
Traceback (most recent call last):
  File "/home/airflow/.local/lib/python3.7/site-packages/s3fs/core.py", line 112, in _error_wrapper
    return await func(*args, **kwargs)
  File "/home/airflow/.local/lib/python3.7/site-packages/aiobotocore/client.py", line 358, in _make_api_call
    raise error_class(parsed_response, operation_name)
botocore.exceptions.ClientError: An error occurred (AccessDenied) when calling the CreateBucket operation: Anonymous access is forbidden for this operation

The above exception was the direct cause of the following exception:

Traceback (most recent call last):
  File "/home/airflow/.local/lib/python3.7/site-packages/airflow/operators/python.py", line 175, in execute
    return_value = self.execute_callable()
  File "/home/airflow/.local/lib/python3.7/site-packages/airflow/operators/python.py", line 192, in execute_callable
    return self.python_callable(*self.op_args, **self.op_kwargs)
  File "/opt/airflow/dags/twitter_etl.py", line 46, in run_twitter_etl
    df.to_csv("s3://jinchoi-airflow-bucket/data/elonmusk_tweets.csv")
  File "/home/airflow/.local/lib/python3.7/site-packages/pandas/core/generic.py", line 3482, in to_csv
    storage_options=storage_options,
  File "/home/airflow/.local/lib/python3.7/site-packages/pandas/io/formats/format.py", line 1105, in to_csv
    csv_formatter.save()
  File "/home/airflow/.local/lib/python3.7/site-packages/pandas/io/formats/csvs.py", line 243, in save
    storage_options=self.storage_options,
  File "/home/airflow/.local/lib/python3.7/site-packages/pandas/io/common.py", line 614, in get_handle
    storage_options=storage_options,
  File "/home/airflow/.local/lib/python3.7/site-packages/pandas/io/common.py", line 370, in _get_filepath_or_buffer
    filepath_or_buffer, mode=fsspec_mode, **(storage_options or {})
  File "/home/airflow/.local/lib/python3.7/site-packages/fsspec/core.py", line 428, in open
    **kwargs,
  File "/home/airflow/.local/lib/python3.7/site-packages/fsspec/core.py", line 283, in open_files
    [fs.makedirs(parent, exist_ok=True) for parent in parents]
  File "/home/airflow/.local/lib/python3.7/site-packages/fsspec/core.py", line 283, in <listcomp>
    [fs.makedirs(parent, exist_ok=True) for parent in parents]
  File "/home/airflow/.local/lib/python3.7/site-packages/fsspec/asyn.py", line 114, in wrapper
    return sync(self.loop, func, *args, **kwargs)
  File "/home/airflow/.local/lib/python3.7/site-packages/fsspec/asyn.py", line 99, in sync
    raise return_result
  File "/home/airflow/.local/lib/python3.7/site-packages/fsspec/asyn.py", line 54, in _runner
    result[0] = await coro
  File "/home/airflow/.local/lib/python3.7/site-packages/s3fs/core.py", line 883, in _makedirs
    await self._mkdir(path, create_parents=True)
  File "/home/airflow/.local/lib/python3.7/site-packages/s3fs/core.py", line 868, in _mkdir
    await self._call_s3("create_bucket", **params)
  File "/home/airflow/.local/lib/python3.7/site-packages/s3fs/core.py", line 340, in _call_s3
    method, kwargs=additional_kwargs, retries=self.retries
  File "/home/airflow/.local/lib/python3.7/site-packages/s3fs/core.py", line 139, in _error_wrapper
    raise err
PermissionError: Anonymous access is forbidden for this operation
[2023-01-25T18:58:36.131+0000] {taskinstance.py:1323} INFO - Marking task as UP_FOR_RETRY. dag_id=twitter_dag, task_id=complete_twitter_etl, execution_date=20210314T000000, start_date=20230125T185829, end_date=20230125T185836
[2023-01-25T18:58:36.215+0000] {standard_task_runner.py:105} ERROR - Failed to execute job 250 for task complete_twitter_etl (Anonymous access is forbidden for this operation; 2452)
[2023-01-25T18:58:36.316+0000] {local_task_job.py:208} INFO - Task exited with return code 1
[2023-01-25T18:58:36.359+0000] {taskinstance.py:2578} INFO - 0 downstream tasks scheduled from follow-on schedule check
[2023-01-26T06:53:59.231+0000] {taskinstance.py:1083} INFO - Dependencies all met for <TaskInstance: twitter_dag.complete_twitter_etl scheduled__2021-03-14T00:00:00+00:00 [queued]>
[2023-01-26T06:53:59.341+0000] {taskinstance.py:1083} INFO - Dependencies all met for <TaskInstance: twitter_dag.complete_twitter_etl scheduled__2021-03-14T00:00:00+00:00 [queued]>
[2023-01-26T06:53:59.342+0000] {taskinstance.py:1279} INFO - 
--------------------------------------------------------------------------------
[2023-01-26T06:53:59.347+0000] {taskinstance.py:1280} INFO - Starting attempt 1 of 2
[2023-01-26T06:53:59.350+0000] {taskinstance.py:1281} INFO - 
--------------------------------------------------------------------------------
[2023-01-26T06:53:59.524+0000] {taskinstance.py:1300} INFO - Executing <Task(PythonOperator): complete_twitter_etl> on 2021-03-14 00:00:00+00:00
[2023-01-26T06:53:59.571+0000] {standard_task_runner.py:55} INFO - Started process 344 to run task
[2023-01-26T06:53:59.584+0000] {standard_task_runner.py:82} INFO - Running: ['***', 'tasks', 'run', 'twitter_dag', 'complete_twitter_etl', 'scheduled__2021-03-14T00:00:00+00:00', '--job-id', '247', '--raw', '--subdir', 'DAGS_FOLDER/twitter_dag.py', '--cfg-path', '/tmp/tmp_4g985bq']
[2023-01-26T06:53:59.592+0000] {standard_task_runner.py:83} INFO - Job 247: Subtask complete_twitter_etl
[2023-01-26T06:54:00.804+0000] {task_command.py:388} INFO - Running <TaskInstance: twitter_dag.complete_twitter_etl scheduled__2021-03-14T00:00:00+00:00 [running]> on host 47843127de93
[2023-01-26T06:54:01.065+0000] {taskinstance.py:1509} INFO - Exporting the following env vars:
AIRFLOW_CTX_DAG_EMAIL=***@example.com
AIRFLOW_CTX_DAG_OWNER=***
AIRFLOW_CTX_DAG_ID=twitter_dag
AIRFLOW_CTX_TASK_ID=complete_twitter_etl
AIRFLOW_CTX_EXECUTION_DATE=2021-03-14T00:00:00+00:00
AIRFLOW_CTX_TRY_NUMBER=1
AIRFLOW_CTX_DAG_RUN_ID=scheduled__2021-03-14T00:00:00+00:00
[2023-01-26T06:54:01.675+0000] {taskinstance.py:1768} ERROR - Task failed with exception
Traceback (most recent call last):
  File "/home/airflow/.local/lib/python3.7/site-packages/airflow/operators/python.py", line 175, in execute
    return_value = self.execute_callable()
  File "/home/airflow/.local/lib/python3.7/site-packages/airflow/operators/python.py", line 192, in execute_callable
    return self.python_callable(*self.op_args, **self.op_kwargs)
  File "/opt/airflow/dags/twitter_etl.py", line 51, in run_twitter_etl
    aws_access_key_id=os.environ['aws_access_key_id'],
  File "/usr/local/lib/python3.7/os.py", line 681, in __getitem__
    raise KeyError(key) from None
KeyError: 'aws_access_key_id'
[2023-01-26T06:54:01.694+0000] {taskinstance.py:1323} INFO - Marking task as UP_FOR_RETRY. dag_id=twitter_dag, task_id=complete_twitter_etl, execution_date=20210314T000000, start_date=20230126T065359, end_date=20230126T065401
[2023-01-26T06:54:01.719+0000] {standard_task_runner.py:105} ERROR - Failed to execute job 247 for task complete_twitter_etl ('aws_access_key_id'; 344)
[2023-01-26T06:54:01.774+0000] {local_task_job.py:208} INFO - Task exited with return code 1
[2023-01-26T06:54:01.930+0000] {taskinstance.py:2578} INFO - 0 downstream tasks scheduled from follow-on schedule check
[2023-01-26T07:13:47.074+0000] {taskinstance.py:1083} INFO - Dependencies all met for <TaskInstance: twitter_dag.complete_twitter_etl scheduled__2021-03-14T00:00:00+00:00 [queued]>
[2023-01-26T07:13:47.224+0000] {taskinstance.py:1083} INFO - Dependencies all met for <TaskInstance: twitter_dag.complete_twitter_etl scheduled__2021-03-14T00:00:00+00:00 [queued]>
[2023-01-26T07:13:47.230+0000] {taskinstance.py:1279} INFO - 
--------------------------------------------------------------------------------
[2023-01-26T07:13:47.236+0000] {taskinstance.py:1280} INFO - Starting attempt 1 of 2
[2023-01-26T07:13:47.238+0000] {taskinstance.py:1281} INFO - 
--------------------------------------------------------------------------------
[2023-01-26T07:13:47.338+0000] {taskinstance.py:1300} INFO - Executing <Task(PythonOperator): complete_twitter_etl> on 2021-03-14 00:00:00+00:00
[2023-01-26T07:13:47.386+0000] {standard_task_runner.py:55} INFO - Started process 1303 to run task
[2023-01-26T07:13:47.444+0000] {standard_task_runner.py:82} INFO - Running: ['***', 'tasks', 'run', 'twitter_dag', 'complete_twitter_etl', 'scheduled__2021-03-14T00:00:00+00:00', '--job-id', '166', '--raw', '--subdir', 'DAGS_FOLDER/twitter_dag.py', '--cfg-path', '/tmp/tmpmbj_rfti']
[2023-01-26T07:13:47.449+0000] {standard_task_runner.py:83} INFO - Job 166: Subtask complete_twitter_etl
[2023-01-26T07:13:48.708+0000] {task_command.py:388} INFO - Running <TaskInstance: twitter_dag.complete_twitter_etl scheduled__2021-03-14T00:00:00+00:00 [running]> on host 2221c1ebf970
[2023-01-26T07:13:49.259+0000] {taskinstance.py:1509} INFO - Exporting the following env vars:
AIRFLOW_CTX_DAG_EMAIL=***@example.com
AIRFLOW_CTX_DAG_OWNER=***
AIRFLOW_CTX_DAG_ID=twitter_dag
AIRFLOW_CTX_TASK_ID=complete_twitter_etl
AIRFLOW_CTX_EXECUTION_DATE=2021-03-14T00:00:00+00:00
AIRFLOW_CTX_TRY_NUMBER=1
AIRFLOW_CTX_DAG_RUN_ID=scheduled__2021-03-14T00:00:00+00:00
[2023-01-26T07:13:50.847+0000] {python.py:177} INFO - Done. Returned value was: None
[2023-01-26T07:13:50.870+0000] {taskinstance.py:1323} INFO - Marking task as SUCCESS. dag_id=twitter_dag, task_id=complete_twitter_etl, execution_date=20210314T000000, start_date=20230126T071347, end_date=20230126T071350
[2023-01-26T07:13:50.992+0000] {local_task_job.py:208} INFO - Task exited with return code 0
[2023-01-26T07:13:51.040+0000] {taskinstance.py:2578} INFO - 0 downstream tasks scheduled from follow-on schedule check
[2023-01-26T09:11:38.180+0000] {taskinstance.py:1083} INFO - Dependencies all met for <TaskInstance: twitter_dag.complete_twitter_etl scheduled__2021-03-14T00:00:00+00:00 [queued]>
[2023-01-26T09:11:38.272+0000] {taskinstance.py:1083} INFO - Dependencies all met for <TaskInstance: twitter_dag.complete_twitter_etl scheduled__2021-03-14T00:00:00+00:00 [queued]>
[2023-01-26T09:11:38.276+0000] {taskinstance.py:1279} INFO - 
--------------------------------------------------------------------------------
[2023-01-26T09:11:38.279+0000] {taskinstance.py:1280} INFO - Starting attempt 1 of 2
[2023-01-26T09:11:38.281+0000] {taskinstance.py:1281} INFO - 
--------------------------------------------------------------------------------
[2023-01-26T09:11:38.420+0000] {taskinstance.py:1300} INFO - Executing <Task(PythonOperator): complete_twitter_etl> on 2021-03-14 00:00:00+00:00
[2023-01-26T09:11:38.437+0000] {standard_task_runner.py:55} INFO - Started process 644 to run task
[2023-01-26T09:11:38.467+0000] {standard_task_runner.py:82} INFO - Running: ['***', 'tasks', 'run', 'twitter_dag', 'complete_twitter_etl', 'scheduled__2021-03-14T00:00:00+00:00', '--job-id', '130', '--raw', '--subdir', 'DAGS_FOLDER/twitter_dag.py', '--cfg-path', '/tmp/tmpn7dtq5a7']
[2023-01-26T09:11:38.475+0000] {standard_task_runner.py:83} INFO - Job 130: Subtask complete_twitter_etl
[2023-01-26T09:11:40.495+0000] {task_command.py:388} INFO - Running <TaskInstance: twitter_dag.complete_twitter_etl scheduled__2021-03-14T00:00:00+00:00 [running]> on host d0fc3b00c15c
[2023-01-26T09:11:40.886+0000] {taskinstance.py:1509} INFO - Exporting the following env vars:
AIRFLOW_CTX_DAG_EMAIL=***@example.com
AIRFLOW_CTX_DAG_OWNER=***
AIRFLOW_CTX_DAG_ID=twitter_dag
AIRFLOW_CTX_TASK_ID=complete_twitter_etl
AIRFLOW_CTX_EXECUTION_DATE=2021-03-14T00:00:00+00:00
AIRFLOW_CTX_TRY_NUMBER=1
AIRFLOW_CTX_DAG_RUN_ID=scheduled__2021-03-14T00:00:00+00:00
[2023-01-26T09:11:44.871+0000] {python.py:177} INFO - Done. Returned value was: None
[2023-01-26T09:11:44.893+0000] {taskinstance.py:1323} INFO - Marking task as SUCCESS. dag_id=twitter_dag, task_id=complete_twitter_etl, execution_date=20210314T000000, start_date=20230126T091138, end_date=20230126T091144
[2023-01-26T09:11:45.065+0000] {local_task_job.py:208} INFO - Task exited with return code 0
[2023-01-26T09:11:45.371+0000] {taskinstance.py:2578} INFO - 0 downstream tasks scheduled from follow-on schedule check
