[2023-01-25T18:53:05.234+0000] {taskinstance.py:1083} INFO - Dependencies all met for <TaskInstance: twitter_dag.complete_twitter_etl scheduled__2021-01-21T00:00:00+00:00 [queued]>
[2023-01-25T18:53:05.265+0000] {taskinstance.py:1083} INFO - Dependencies all met for <TaskInstance: twitter_dag.complete_twitter_etl scheduled__2021-01-21T00:00:00+00:00 [queued]>
[2023-01-25T18:53:05.268+0000] {taskinstance.py:1279} INFO - 
--------------------------------------------------------------------------------
[2023-01-25T18:53:05.272+0000] {taskinstance.py:1280} INFO - Starting attempt 2 of 2
[2023-01-25T18:53:05.274+0000] {taskinstance.py:1281} INFO - 
--------------------------------------------------------------------------------
[2023-01-25T18:53:05.317+0000] {taskinstance.py:1300} INFO - Executing <Task(PythonOperator): complete_twitter_etl> on 2021-01-21 00:00:00+00:00
[2023-01-25T18:53:05.335+0000] {standard_task_runner.py:55} INFO - Started process 1755 to run task
[2023-01-25T18:53:05.362+0000] {standard_task_runner.py:82} INFO - Running: ['***', 'tasks', 'run', 'twitter_dag', 'complete_twitter_etl', 'scheduled__2021-01-21T00:00:00+00:00', '--job-id', '166', '--raw', '--subdir', 'DAGS_FOLDER/twitter_dag.py', '--cfg-path', '/tmp/tmpgwydqcj_']
[2023-01-25T18:53:05.365+0000] {standard_task_runner.py:83} INFO - Job 166: Subtask complete_twitter_etl
[2023-01-25T18:53:05.546+0000] {task_command.py:388} INFO - Running <TaskInstance: twitter_dag.complete_twitter_etl scheduled__2021-01-21T00:00:00+00:00 [running]> on host 512d0ff0785b
[2023-01-25T18:53:06.236+0000] {taskinstance.py:1509} INFO - Exporting the following env vars:
AIRFLOW_CTX_DAG_EMAIL=***@example.com
AIRFLOW_CTX_DAG_OWNER=***
AIRFLOW_CTX_DAG_ID=twitter_dag
AIRFLOW_CTX_TASK_ID=complete_twitter_etl
AIRFLOW_CTX_EXECUTION_DATE=2021-01-21T00:00:00+00:00
AIRFLOW_CTX_TRY_NUMBER=2
AIRFLOW_CTX_DAG_RUN_ID=scheduled__2021-01-21T00:00:00+00:00
[2023-01-25T18:53:11.272+0000] {taskinstance.py:1768} ERROR - Task failed with exception
Traceback (most recent call last):
  File "/home/airflow/.local/lib/python3.7/site-packages/s3fs/core.py", line 112, in _error_wrapper
    return await func(*args, **kwargs)
  File "/home/airflow/.local/lib/python3.7/site-packages/aiobotocore/client.py", line 358, in _make_api_call
    raise error_class(parsed_response, operation_name)
botocore.exceptions.ClientError: An error occurred (AccessDenied) when calling the CreateBucket operation: Anonymous access is forbidden for this operation

The above exception was the direct cause of the following exception:

Traceback (most recent call last):
  File "/home/airflow/.local/lib/python3.7/site-packages/airflow/operators/python.py", line 175, in execute
    return_value = self.execute_callable()
  File "/home/airflow/.local/lib/python3.7/site-packages/airflow/operators/python.py", line 192, in execute_callable
    return self.python_callable(*self.op_args, **self.op_kwargs)
  File "/opt/airflow/dags/twitter_etl.py", line 46, in run_twitter_etl
    df.to_csv("s3://jinchoi-airflow-bucket/data/elonmusk_tweets.csv")
  File "/home/airflow/.local/lib/python3.7/site-packages/pandas/core/generic.py", line 3482, in to_csv
    storage_options=storage_options,
  File "/home/airflow/.local/lib/python3.7/site-packages/pandas/io/formats/format.py", line 1105, in to_csv
    csv_formatter.save()
  File "/home/airflow/.local/lib/python3.7/site-packages/pandas/io/formats/csvs.py", line 243, in save
    storage_options=self.storage_options,
  File "/home/airflow/.local/lib/python3.7/site-packages/pandas/io/common.py", line 614, in get_handle
    storage_options=storage_options,
  File "/home/airflow/.local/lib/python3.7/site-packages/pandas/io/common.py", line 370, in _get_filepath_or_buffer
    filepath_or_buffer, mode=fsspec_mode, **(storage_options or {})
  File "/home/airflow/.local/lib/python3.7/site-packages/fsspec/core.py", line 428, in open
    **kwargs,
  File "/home/airflow/.local/lib/python3.7/site-packages/fsspec/core.py", line 283, in open_files
    [fs.makedirs(parent, exist_ok=True) for parent in parents]
  File "/home/airflow/.local/lib/python3.7/site-packages/fsspec/core.py", line 283, in <listcomp>
    [fs.makedirs(parent, exist_ok=True) for parent in parents]
  File "/home/airflow/.local/lib/python3.7/site-packages/fsspec/asyn.py", line 114, in wrapper
    return sync(self.loop, func, *args, **kwargs)
  File "/home/airflow/.local/lib/python3.7/site-packages/fsspec/asyn.py", line 99, in sync
    raise return_result
  File "/home/airflow/.local/lib/python3.7/site-packages/fsspec/asyn.py", line 54, in _runner
    result[0] = await coro
  File "/home/airflow/.local/lib/python3.7/site-packages/s3fs/core.py", line 883, in _makedirs
    await self._mkdir(path, create_parents=True)
  File "/home/airflow/.local/lib/python3.7/site-packages/s3fs/core.py", line 868, in _mkdir
    await self._call_s3("create_bucket", **params)
  File "/home/airflow/.local/lib/python3.7/site-packages/s3fs/core.py", line 340, in _call_s3
    method, kwargs=additional_kwargs, retries=self.retries
  File "/home/airflow/.local/lib/python3.7/site-packages/s3fs/core.py", line 139, in _error_wrapper
    raise err
PermissionError: Anonymous access is forbidden for this operation
[2023-01-25T18:53:11.349+0000] {taskinstance.py:1323} INFO - Marking task as FAILED. dag_id=twitter_dag, task_id=complete_twitter_etl, execution_date=20210121T000000, start_date=20230125T185305, end_date=20230125T185311
[2023-01-25T18:53:11.468+0000] {standard_task_runner.py:105} ERROR - Failed to execute job 166 for task complete_twitter_etl (Anonymous access is forbidden for this operation; 1755)
[2023-01-25T18:53:11.613+0000] {local_task_job.py:208} INFO - Task exited with return code 1
[2023-01-25T18:53:11.733+0000] {taskinstance.py:2578} INFO - 0 downstream tasks scheduled from follow-on schedule check
[2023-01-26T06:26:46.882+0000] {taskinstance.py:1083} INFO - Dependencies all met for <TaskInstance: twitter_dag.complete_twitter_etl scheduled__2021-01-21T00:00:00+00:00 [queued]>
[2023-01-26T06:26:46.926+0000] {taskinstance.py:1083} INFO - Dependencies all met for <TaskInstance: twitter_dag.complete_twitter_etl scheduled__2021-01-21T00:00:00+00:00 [queued]>
[2023-01-26T06:26:46.927+0000] {taskinstance.py:1279} INFO - 
--------------------------------------------------------------------------------
[2023-01-26T06:26:46.930+0000] {taskinstance.py:1280} INFO - Starting attempt 2 of 2
[2023-01-26T06:26:46.932+0000] {taskinstance.py:1281} INFO - 
--------------------------------------------------------------------------------
[2023-01-26T06:26:46.998+0000] {taskinstance.py:1300} INFO - Executing <Task(PythonOperator): complete_twitter_etl> on 2021-01-21 00:00:00+00:00
[2023-01-26T06:26:47.011+0000] {standard_task_runner.py:55} INFO - Started process 2776 to run task
[2023-01-26T06:26:47.058+0000] {standard_task_runner.py:82} INFO - Running: ['***', 'tasks', 'run', 'twitter_dag', 'complete_twitter_etl', 'scheduled__2021-01-21T00:00:00+00:00', '--job-id', '163', '--raw', '--subdir', 'DAGS_FOLDER/twitter_dag.py', '--cfg-path', '/tmp/tmpnpz49pq6']
[2023-01-26T06:26:47.061+0000] {standard_task_runner.py:83} INFO - Job 163: Subtask complete_twitter_etl
[2023-01-26T06:26:48.353+0000] {task_command.py:388} INFO - Running <TaskInstance: twitter_dag.complete_twitter_etl scheduled__2021-01-21T00:00:00+00:00 [running]> on host 864c120ca3c2
[2023-01-26T06:26:48.651+0000] {taskinstance.py:1509} INFO - Exporting the following env vars:
AIRFLOW_CTX_DAG_EMAIL=***@example.com
AIRFLOW_CTX_DAG_OWNER=***
AIRFLOW_CTX_DAG_ID=twitter_dag
AIRFLOW_CTX_TASK_ID=complete_twitter_etl
AIRFLOW_CTX_EXECUTION_DATE=2021-01-21T00:00:00+00:00
AIRFLOW_CTX_TRY_NUMBER=2
AIRFLOW_CTX_DAG_RUN_ID=scheduled__2021-01-21T00:00:00+00:00
[2023-01-26T06:26:49.302+0000] {taskinstance.py:1768} ERROR - Task failed with exception
Traceback (most recent call last):
  File "/home/airflow/.local/lib/python3.7/site-packages/airflow/operators/python.py", line 175, in execute
    return_value = self.execute_callable()
  File "/home/airflow/.local/lib/python3.7/site-packages/airflow/operators/python.py", line 192, in execute_callable
    return self.python_callable(*self.op_args, **self.op_kwargs)
  File "/opt/airflow/dags/twitter_etl.py", line 51, in run_twitter_etl
    aws_access_key_id=os.environ['aws_access_key_id'],
  File "/usr/local/lib/python3.7/os.py", line 681, in __getitem__
    raise KeyError(key) from None
KeyError: 'aws_access_key_id'
[2023-01-26T06:26:49.329+0000] {taskinstance.py:1323} INFO - Marking task as FAILED. dag_id=twitter_dag, task_id=complete_twitter_etl, execution_date=20210121T000000, start_date=20230126T062646, end_date=20230126T062649
[2023-01-26T06:26:49.365+0000] {standard_task_runner.py:105} ERROR - Failed to execute job 163 for task complete_twitter_etl ('aws_access_key_id'; 2776)
[2023-01-26T06:26:49.446+0000] {local_task_job.py:208} INFO - Task exited with return code 1
[2023-01-26T06:26:49.477+0000] {taskinstance.py:2578} INFO - 0 downstream tasks scheduled from follow-on schedule check
[2023-01-26T08:29:40.290+0000] {taskinstance.py:1083} INFO - Dependencies all met for <TaskInstance: twitter_dag.complete_twitter_etl scheduled__2021-01-21T00:00:00+00:00 [queued]>
[2023-01-26T08:29:40.308+0000] {taskinstance.py:1083} INFO - Dependencies all met for <TaskInstance: twitter_dag.complete_twitter_etl scheduled__2021-01-21T00:00:00+00:00 [queued]>
[2023-01-26T08:29:40.309+0000] {taskinstance.py:1279} INFO - 
--------------------------------------------------------------------------------
[2023-01-26T08:29:40.310+0000] {taskinstance.py:1280} INFO - Starting attempt 2 of 2
[2023-01-26T08:29:40.312+0000] {taskinstance.py:1281} INFO - 
--------------------------------------------------------------------------------
[2023-01-26T08:29:40.355+0000] {taskinstance.py:1300} INFO - Executing <Task(PythonOperator): complete_twitter_etl> on 2021-01-21 00:00:00+00:00
[2023-01-26T08:29:40.395+0000] {standard_task_runner.py:55} INFO - Started process 2372 to run task
[2023-01-26T08:29:40.402+0000] {standard_task_runner.py:82} INFO - Running: ['***', 'tasks', 'run', 'twitter_dag', 'complete_twitter_etl', 'scheduled__2021-01-21T00:00:00+00:00', '--job-id', '166', '--raw', '--subdir', 'DAGS_FOLDER/twitter_dag.py', '--cfg-path', '/tmp/tmp7fkbtx5t']
[2023-01-26T08:29:40.404+0000] {standard_task_runner.py:83} INFO - Job 166: Subtask complete_twitter_etl
[2023-01-26T08:29:40.923+0000] {task_command.py:388} INFO - Running <TaskInstance: twitter_dag.complete_twitter_etl scheduled__2021-01-21T00:00:00+00:00 [running]> on host 3143b9e5b257
[2023-01-26T08:29:41.276+0000] {taskinstance.py:1509} INFO - Exporting the following env vars:
AIRFLOW_CTX_DAG_EMAIL=***@example.com
AIRFLOW_CTX_DAG_OWNER=***
AIRFLOW_CTX_DAG_ID=twitter_dag
AIRFLOW_CTX_TASK_ID=complete_twitter_etl
AIRFLOW_CTX_EXECUTION_DATE=2021-01-21T00:00:00+00:00
AIRFLOW_CTX_TRY_NUMBER=2
AIRFLOW_CTX_DAG_RUN_ID=scheduled__2021-01-21T00:00:00+00:00
[2023-01-26T08:29:42.590+0000] {taskinstance.py:1768} ERROR - Task failed with exception
Traceback (most recent call last):
  File "/home/airflow/.local/lib/python3.7/site-packages/airflow/operators/python.py", line 175, in execute
    return_value = self.execute_callable()
  File "/home/airflow/.local/lib/python3.7/site-packages/airflow/operators/python.py", line 192, in execute_callable
    return self.python_callable(*self.op_args, **self.op_kwargs)
  File "/opt/airflow/dags/twitter_etl.py", line 64, in run_twitter_etl
    s3.Object(BUCKET_NAME, KEY).put(Body=csv_buffer.getvalue())
  File "/home/airflow/.local/lib/python3.7/site-packages/boto3/resources/factory.py", line 580, in do_action
    response = action(self, *args, **kwargs)
  File "/home/airflow/.local/lib/python3.7/site-packages/boto3/resources/action.py", line 88, in __call__
    response = getattr(parent.meta.client, operation_name)(*args, **params)
  File "/home/airflow/.local/lib/python3.7/site-packages/botocore/client.py", line 508, in _api_call
    return self._make_api_call(operation_name, kwargs)
  File "/home/airflow/.local/lib/python3.7/site-packages/botocore/client.py", line 915, in _make_api_call
    raise error_class(parsed_response, operation_name)
botocore.exceptions.ClientError: An error occurred (InvalidAccessKeyId) when calling the PutObject operation: The AWS Access Key Id you provided does not exist in our records.
[2023-01-26T08:29:42.628+0000] {taskinstance.py:1323} INFO - Marking task as FAILED. dag_id=twitter_dag, task_id=complete_twitter_etl, execution_date=20210121T000000, start_date=20230126T082940, end_date=20230126T082942
[2023-01-26T08:29:42.665+0000] {standard_task_runner.py:105} ERROR - Failed to execute job 166 for task complete_twitter_etl (An error occurred (InvalidAccessKeyId) when calling the PutObject operation: The AWS Access Key Id you provided does not exist in our records.; 2372)
[2023-01-26T08:29:42.771+0000] {local_task_job.py:208} INFO - Task exited with return code 1
[2023-01-26T08:29:42.877+0000] {taskinstance.py:2578} INFO - 0 downstream tasks scheduled from follow-on schedule check
