[2023-01-25T18:51:45.295+0000] {taskinstance.py:1083} INFO - Dependencies all met for <TaskInstance: twitter_dag.complete_twitter_etl scheduled__2021-01-21T00:00:00+00:00 [queued]>
[2023-01-25T18:51:45.554+0000] {taskinstance.py:1083} INFO - Dependencies all met for <TaskInstance: twitter_dag.complete_twitter_etl scheduled__2021-01-21T00:00:00+00:00 [queued]>
[2023-01-25T18:51:45.577+0000] {taskinstance.py:1279} INFO - 
--------------------------------------------------------------------------------
[2023-01-25T18:51:45.598+0000] {taskinstance.py:1280} INFO - Starting attempt 1 of 2
[2023-01-25T18:51:45.603+0000] {taskinstance.py:1281} INFO - 
--------------------------------------------------------------------------------
[2023-01-25T18:51:46.368+0000] {taskinstance.py:1300} INFO - Executing <Task(PythonOperator): complete_twitter_etl> on 2021-01-21 00:00:00+00:00
[2023-01-25T18:51:46.457+0000] {standard_task_runner.py:55} INFO - Started process 1582 to run task
[2023-01-25T18:51:46.564+0000] {standard_task_runner.py:82} INFO - Running: ['***', 'tasks', 'run', 'twitter_dag', 'complete_twitter_etl', 'scheduled__2021-01-21T00:00:00+00:00', '--job-id', '145', '--raw', '--subdir', 'DAGS_FOLDER/twitter_dag.py', '--cfg-path', '/tmp/tmpr2mpvb_1']
[2023-01-25T18:51:46.572+0000] {standard_task_runner.py:83} INFO - Job 145: Subtask complete_twitter_etl
[2023-01-25T18:51:47.352+0000] {task_command.py:388} INFO - Running <TaskInstance: twitter_dag.complete_twitter_etl scheduled__2021-01-21T00:00:00+00:00 [running]> on host 512d0ff0785b
[2023-01-25T18:51:53.068+0000] {taskinstance.py:1509} INFO - Exporting the following env vars:
AIRFLOW_CTX_DAG_EMAIL=***@example.com
AIRFLOW_CTX_DAG_OWNER=***
AIRFLOW_CTX_DAG_ID=twitter_dag
AIRFLOW_CTX_TASK_ID=complete_twitter_etl
AIRFLOW_CTX_EXECUTION_DATE=2021-01-21T00:00:00+00:00
AIRFLOW_CTX_TRY_NUMBER=1
AIRFLOW_CTX_DAG_RUN_ID=scheduled__2021-01-21T00:00:00+00:00
[2023-01-25T18:52:01.191+0000] {taskinstance.py:1768} ERROR - Task failed with exception
Traceback (most recent call last):
  File "/home/airflow/.local/lib/python3.7/site-packages/s3fs/core.py", line 112, in _error_wrapper
    return await func(*args, **kwargs)
  File "/home/airflow/.local/lib/python3.7/site-packages/aiobotocore/client.py", line 358, in _make_api_call
    raise error_class(parsed_response, operation_name)
botocore.exceptions.ClientError: An error occurred (AccessDenied) when calling the CreateBucket operation: Anonymous access is forbidden for this operation

The above exception was the direct cause of the following exception:

Traceback (most recent call last):
  File "/home/airflow/.local/lib/python3.7/site-packages/airflow/operators/python.py", line 175, in execute
    return_value = self.execute_callable()
  File "/home/airflow/.local/lib/python3.7/site-packages/airflow/operators/python.py", line 192, in execute_callable
    return self.python_callable(*self.op_args, **self.op_kwargs)
  File "/opt/airflow/dags/twitter_etl.py", line 46, in run_twitter_etl
    df.to_csv("s3://jinchoi-airflow-bucket/data/elonmusk_tweets.csv")
  File "/home/airflow/.local/lib/python3.7/site-packages/pandas/core/generic.py", line 3482, in to_csv
    storage_options=storage_options,
  File "/home/airflow/.local/lib/python3.7/site-packages/pandas/io/formats/format.py", line 1105, in to_csv
    csv_formatter.save()
  File "/home/airflow/.local/lib/python3.7/site-packages/pandas/io/formats/csvs.py", line 243, in save
    storage_options=self.storage_options,
  File "/home/airflow/.local/lib/python3.7/site-packages/pandas/io/common.py", line 614, in get_handle
    storage_options=storage_options,
  File "/home/airflow/.local/lib/python3.7/site-packages/pandas/io/common.py", line 370, in _get_filepath_or_buffer
    filepath_or_buffer, mode=fsspec_mode, **(storage_options or {})
  File "/home/airflow/.local/lib/python3.7/site-packages/fsspec/core.py", line 428, in open
    **kwargs,
  File "/home/airflow/.local/lib/python3.7/site-packages/fsspec/core.py", line 283, in open_files
    [fs.makedirs(parent, exist_ok=True) for parent in parents]
  File "/home/airflow/.local/lib/python3.7/site-packages/fsspec/core.py", line 283, in <listcomp>
    [fs.makedirs(parent, exist_ok=True) for parent in parents]
  File "/home/airflow/.local/lib/python3.7/site-packages/fsspec/asyn.py", line 114, in wrapper
    return sync(self.loop, func, *args, **kwargs)
  File "/home/airflow/.local/lib/python3.7/site-packages/fsspec/asyn.py", line 99, in sync
    raise return_result
  File "/home/airflow/.local/lib/python3.7/site-packages/fsspec/asyn.py", line 54, in _runner
    result[0] = await coro
  File "/home/airflow/.local/lib/python3.7/site-packages/s3fs/core.py", line 883, in _makedirs
    await self._mkdir(path, create_parents=True)
  File "/home/airflow/.local/lib/python3.7/site-packages/s3fs/core.py", line 868, in _mkdir
    await self._call_s3("create_bucket", **params)
  File "/home/airflow/.local/lib/python3.7/site-packages/s3fs/core.py", line 340, in _call_s3
    method, kwargs=additional_kwargs, retries=self.retries
  File "/home/airflow/.local/lib/python3.7/site-packages/s3fs/core.py", line 139, in _error_wrapper
    raise err
PermissionError: Anonymous access is forbidden for this operation
[2023-01-25T18:52:01.306+0000] {taskinstance.py:1323} INFO - Marking task as UP_FOR_RETRY. dag_id=twitter_dag, task_id=complete_twitter_etl, execution_date=20210121T000000, start_date=20230125T185145, end_date=20230125T185201
[2023-01-25T18:52:01.457+0000] {standard_task_runner.py:105} ERROR - Failed to execute job 145 for task complete_twitter_etl (Anonymous access is forbidden for this operation; 1582)
[2023-01-25T18:52:02.109+0000] {local_task_job.py:208} INFO - Task exited with return code 1
[2023-01-25T18:52:02.620+0000] {taskinstance.py:2578} INFO - 0 downstream tasks scheduled from follow-on schedule check
[2023-01-26T06:21:36.333+0000] {taskinstance.py:1083} INFO - Dependencies all met for <TaskInstance: twitter_dag.complete_twitter_etl scheduled__2021-01-21T00:00:00+00:00 [queued]>
[2023-01-26T06:21:36.375+0000] {taskinstance.py:1083} INFO - Dependencies all met for <TaskInstance: twitter_dag.complete_twitter_etl scheduled__2021-01-21T00:00:00+00:00 [queued]>
[2023-01-26T06:21:36.378+0000] {taskinstance.py:1279} INFO - 
--------------------------------------------------------------------------------
[2023-01-26T06:21:36.379+0000] {taskinstance.py:1280} INFO - Starting attempt 1 of 2
[2023-01-26T06:21:36.381+0000] {taskinstance.py:1281} INFO - 
--------------------------------------------------------------------------------
[2023-01-26T06:21:36.470+0000] {taskinstance.py:1300} INFO - Executing <Task(PythonOperator): complete_twitter_etl> on 2021-01-21 00:00:00+00:00
[2023-01-26T06:21:36.496+0000] {standard_task_runner.py:55} INFO - Started process 2419 to run task
[2023-01-26T06:21:36.532+0000] {standard_task_runner.py:82} INFO - Running: ['***', 'tasks', 'run', 'twitter_dag', 'complete_twitter_etl', 'scheduled__2021-01-21T00:00:00+00:00', '--job-id', '142', '--raw', '--subdir', 'DAGS_FOLDER/twitter_dag.py', '--cfg-path', '/tmp/tmp95l_7bbp']
[2023-01-26T06:21:36.543+0000] {standard_task_runner.py:83} INFO - Job 142: Subtask complete_twitter_etl
[2023-01-26T06:21:37.372+0000] {task_command.py:388} INFO - Running <TaskInstance: twitter_dag.complete_twitter_etl scheduled__2021-01-21T00:00:00+00:00 [running]> on host 864c120ca3c2
[2023-01-26T06:21:37.519+0000] {taskinstance.py:1509} INFO - Exporting the following env vars:
AIRFLOW_CTX_DAG_EMAIL=***@example.com
AIRFLOW_CTX_DAG_OWNER=***
AIRFLOW_CTX_DAG_ID=twitter_dag
AIRFLOW_CTX_TASK_ID=complete_twitter_etl
AIRFLOW_CTX_EXECUTION_DATE=2021-01-21T00:00:00+00:00
AIRFLOW_CTX_TRY_NUMBER=1
AIRFLOW_CTX_DAG_RUN_ID=scheduled__2021-01-21T00:00:00+00:00
[2023-01-26T06:21:38.113+0000] {taskinstance.py:1768} ERROR - Task failed with exception
Traceback (most recent call last):
  File "/home/airflow/.local/lib/python3.7/site-packages/airflow/operators/python.py", line 175, in execute
    return_value = self.execute_callable()
  File "/home/airflow/.local/lib/python3.7/site-packages/airflow/operators/python.py", line 192, in execute_callable
    return self.python_callable(*self.op_args, **self.op_kwargs)
  File "/opt/airflow/dags/twitter_etl.py", line 51, in run_twitter_etl
    aws_access_key_id=os.environ['AWS_ACCESS_KEY_ID'],
  File "/usr/local/lib/python3.7/os.py", line 681, in __getitem__
    raise KeyError(key) from None
KeyError: 'AWS_ACCESS_KEY_ID'
[2023-01-26T06:21:38.129+0000] {taskinstance.py:1323} INFO - Marking task as UP_FOR_RETRY. dag_id=twitter_dag, task_id=complete_twitter_etl, execution_date=20210121T000000, start_date=20230126T062136, end_date=20230126T062138
[2023-01-26T06:21:38.152+0000] {standard_task_runner.py:105} ERROR - Failed to execute job 142 for task complete_twitter_etl ('AWS_ACCESS_KEY_ID'; 2419)
[2023-01-26T06:21:38.224+0000] {local_task_job.py:208} INFO - Task exited with return code 1
[2023-01-26T06:21:38.262+0000] {taskinstance.py:2578} INFO - 0 downstream tasks scheduled from follow-on schedule check
[2023-01-26T07:12:25.619+0000] {taskinstance.py:1083} INFO - Dependencies all met for <TaskInstance: twitter_dag.complete_twitter_etl scheduled__2021-01-21T00:00:00+00:00 [queued]>
[2023-01-26T07:12:25.968+0000] {taskinstance.py:1083} INFO - Dependencies all met for <TaskInstance: twitter_dag.complete_twitter_etl scheduled__2021-01-21T00:00:00+00:00 [queued]>
[2023-01-26T07:12:25.981+0000] {taskinstance.py:1279} INFO - 
--------------------------------------------------------------------------------
[2023-01-26T07:12:25.991+0000] {taskinstance.py:1280} INFO - Starting attempt 1 of 2
[2023-01-26T07:12:25.999+0000] {taskinstance.py:1281} INFO - 
--------------------------------------------------------------------------------
[2023-01-26T07:12:27.081+0000] {taskinstance.py:1300} INFO - Executing <Task(PythonOperator): complete_twitter_etl> on 2021-01-21 00:00:00+00:00
[2023-01-26T07:12:27.292+0000] {standard_task_runner.py:55} INFO - Started process 1096 to run task
[2023-01-26T07:12:27.465+0000] {standard_task_runner.py:82} INFO - Running: ['***', 'tasks', 'run', 'twitter_dag', 'complete_twitter_etl', 'scheduled__2021-01-21T00:00:00+00:00', '--job-id', '114', '--raw', '--subdir', 'DAGS_FOLDER/twitter_dag.py', '--cfg-path', '/tmp/tmpwsflrqs7']
[2023-01-26T07:12:27.489+0000] {standard_task_runner.py:83} INFO - Job 114: Subtask complete_twitter_etl
[2023-01-26T07:12:31.151+0000] {task_command.py:388} INFO - Running <TaskInstance: twitter_dag.complete_twitter_etl scheduled__2021-01-21T00:00:00+00:00 [running]> on host 2221c1ebf970
[2023-01-26T07:12:31.755+0000] {taskinstance.py:1509} INFO - Exporting the following env vars:
AIRFLOW_CTX_DAG_EMAIL=***@example.com
AIRFLOW_CTX_DAG_OWNER=***
AIRFLOW_CTX_DAG_ID=twitter_dag
AIRFLOW_CTX_TASK_ID=complete_twitter_etl
AIRFLOW_CTX_EXECUTION_DATE=2021-01-21T00:00:00+00:00
AIRFLOW_CTX_TRY_NUMBER=1
AIRFLOW_CTX_DAG_RUN_ID=scheduled__2021-01-21T00:00:00+00:00
[2023-01-26T07:12:33.585+0000] {python.py:177} INFO - Done. Returned value was: None
[2023-01-26T07:12:33.718+0000] {taskinstance.py:1323} INFO - Marking task as SUCCESS. dag_id=twitter_dag, task_id=complete_twitter_etl, execution_date=20210121T000000, start_date=20230126T071225, end_date=20230126T071233
[2023-01-26T07:12:34.464+0000] {local_task_job.py:208} INFO - Task exited with return code 0
[2023-01-26T07:12:35.598+0000] {taskinstance.py:2578} INFO - 0 downstream tasks scheduled from follow-on schedule check
[2023-01-26T08:24:33.258+0000] {taskinstance.py:1083} INFO - Dependencies all met for <TaskInstance: twitter_dag.complete_twitter_etl scheduled__2021-01-21T00:00:00+00:00 [queued]>
[2023-01-26T08:24:33.285+0000] {taskinstance.py:1083} INFO - Dependencies all met for <TaskInstance: twitter_dag.complete_twitter_etl scheduled__2021-01-21T00:00:00+00:00 [queued]>
[2023-01-26T08:24:33.287+0000] {taskinstance.py:1279} INFO - 
--------------------------------------------------------------------------------
[2023-01-26T08:24:33.288+0000] {taskinstance.py:1280} INFO - Starting attempt 1 of 2
[2023-01-26T08:24:33.291+0000] {taskinstance.py:1281} INFO - 
--------------------------------------------------------------------------------
[2023-01-26T08:24:33.345+0000] {taskinstance.py:1300} INFO - Executing <Task(PythonOperator): complete_twitter_etl> on 2021-01-21 00:00:00+00:00
[2023-01-26T08:24:33.382+0000] {standard_task_runner.py:55} INFO - Started process 2024 to run task
[2023-01-26T08:24:33.401+0000] {standard_task_runner.py:82} INFO - Running: ['***', 'tasks', 'run', 'twitter_dag', 'complete_twitter_etl', 'scheduled__2021-01-21T00:00:00+00:00', '--job-id', '146', '--raw', '--subdir', 'DAGS_FOLDER/twitter_dag.py', '--cfg-path', '/tmp/tmpco51v7xj']
[2023-01-26T08:24:33.409+0000] {standard_task_runner.py:83} INFO - Job 146: Subtask complete_twitter_etl
[2023-01-26T08:24:34.794+0000] {task_command.py:388} INFO - Running <TaskInstance: twitter_dag.complete_twitter_etl scheduled__2021-01-21T00:00:00+00:00 [running]> on host 3143b9e5b257
[2023-01-26T08:24:35.308+0000] {taskinstance.py:1509} INFO - Exporting the following env vars:
AIRFLOW_CTX_DAG_EMAIL=***@example.com
AIRFLOW_CTX_DAG_OWNER=***
AIRFLOW_CTX_DAG_ID=twitter_dag
AIRFLOW_CTX_TASK_ID=complete_twitter_etl
AIRFLOW_CTX_EXECUTION_DATE=2021-01-21T00:00:00+00:00
AIRFLOW_CTX_TRY_NUMBER=1
AIRFLOW_CTX_DAG_RUN_ID=scheduled__2021-01-21T00:00:00+00:00
[2023-01-26T08:24:36.822+0000] {taskinstance.py:1768} ERROR - Task failed with exception
Traceback (most recent call last):
  File "/home/airflow/.local/lib/python3.7/site-packages/airflow/operators/python.py", line 175, in execute
    return_value = self.execute_callable()
  File "/home/airflow/.local/lib/python3.7/site-packages/airflow/operators/python.py", line 192, in execute_callable
    return self.python_callable(*self.op_args, **self.op_kwargs)
  File "/opt/airflow/dags/twitter_etl.py", line 64, in run_twitter_etl
    s3.Object(BUCKET_NAME, KEY).put(Body=csv_buffer.getvalue())
  File "/home/airflow/.local/lib/python3.7/site-packages/boto3/resources/factory.py", line 580, in do_action
    response = action(self, *args, **kwargs)
  File "/home/airflow/.local/lib/python3.7/site-packages/boto3/resources/action.py", line 88, in __call__
    response = getattr(parent.meta.client, operation_name)(*args, **params)
  File "/home/airflow/.local/lib/python3.7/site-packages/botocore/client.py", line 508, in _api_call
    return self._make_api_call(operation_name, kwargs)
  File "/home/airflow/.local/lib/python3.7/site-packages/botocore/client.py", line 915, in _make_api_call
    raise error_class(parsed_response, operation_name)
botocore.exceptions.ClientError: An error occurred (InvalidAccessKeyId) when calling the PutObject operation: The AWS Access Key Id you provided does not exist in our records.
[2023-01-26T08:24:36.840+0000] {taskinstance.py:1323} INFO - Marking task as UP_FOR_RETRY. dag_id=twitter_dag, task_id=complete_twitter_etl, execution_date=20210121T000000, start_date=20230126T082433, end_date=20230126T082436
[2023-01-26T08:24:37.057+0000] {standard_task_runner.py:105} ERROR - Failed to execute job 146 for task complete_twitter_etl (An error occurred (InvalidAccessKeyId) when calling the PutObject operation: The AWS Access Key Id you provided does not exist in our records.; 2024)
[2023-01-26T08:24:37.205+0000] {local_task_job.py:208} INFO - Task exited with return code 1
[2023-01-26T08:24:37.264+0000] {taskinstance.py:2578} INFO - 0 downstream tasks scheduled from follow-on schedule check
[2023-01-26T09:10:06.010+0000] {taskinstance.py:1083} INFO - Dependencies all met for <TaskInstance: twitter_dag.complete_twitter_etl scheduled__2021-01-21T00:00:00+00:00 [queued]>
[2023-01-26T09:10:06.047+0000] {taskinstance.py:1083} INFO - Dependencies all met for <TaskInstance: twitter_dag.complete_twitter_etl scheduled__2021-01-21T00:00:00+00:00 [queued]>
[2023-01-26T09:10:06.053+0000] {taskinstance.py:1279} INFO - 
--------------------------------------------------------------------------------
[2023-01-26T09:10:06.054+0000] {taskinstance.py:1280} INFO - Starting attempt 1 of 2
[2023-01-26T09:10:06.057+0000] {taskinstance.py:1281} INFO - 
--------------------------------------------------------------------------------
[2023-01-26T09:10:06.118+0000] {taskinstance.py:1300} INFO - Executing <Task(PythonOperator): complete_twitter_etl> on 2021-01-21 00:00:00+00:00
[2023-01-26T09:10:06.138+0000] {standard_task_runner.py:55} INFO - Started process 430 to run task
[2023-01-26T09:10:06.149+0000] {standard_task_runner.py:82} INFO - Running: ['***', 'tasks', 'run', 'twitter_dag', 'complete_twitter_etl', 'scheduled__2021-01-21T00:00:00+00:00', '--job-id', '79', '--raw', '--subdir', 'DAGS_FOLDER/twitter_dag.py', '--cfg-path', '/tmp/tmptyjznort']
[2023-01-26T09:10:06.172+0000] {standard_task_runner.py:83} INFO - Job 79: Subtask complete_twitter_etl
[2023-01-26T09:10:07.656+0000] {task_command.py:388} INFO - Running <TaskInstance: twitter_dag.complete_twitter_etl scheduled__2021-01-21T00:00:00+00:00 [running]> on host d0fc3b00c15c
[2023-01-26T09:10:08.336+0000] {taskinstance.py:1509} INFO - Exporting the following env vars:
AIRFLOW_CTX_DAG_EMAIL=***@example.com
AIRFLOW_CTX_DAG_OWNER=***
AIRFLOW_CTX_DAG_ID=twitter_dag
AIRFLOW_CTX_TASK_ID=complete_twitter_etl
AIRFLOW_CTX_EXECUTION_DATE=2021-01-21T00:00:00+00:00
AIRFLOW_CTX_TRY_NUMBER=1
AIRFLOW_CTX_DAG_RUN_ID=scheduled__2021-01-21T00:00:00+00:00
[2023-01-26T09:10:10.908+0000] {python.py:177} INFO - Done. Returned value was: None
[2023-01-26T09:10:10.945+0000] {taskinstance.py:1323} INFO - Marking task as SUCCESS. dag_id=twitter_dag, task_id=complete_twitter_etl, execution_date=20210121T000000, start_date=20230126T091006, end_date=20230126T091010
[2023-01-26T09:10:11.042+0000] {local_task_job.py:208} INFO - Task exited with return code 0
[2023-01-26T09:10:11.183+0000] {taskinstance.py:2578} INFO - 0 downstream tasks scheduled from follow-on schedule check
