[2023-01-25T18:58:51.549+0000] {taskinstance.py:1083} INFO - Dependencies all met for <TaskInstance: twitter_dag.complete_twitter_etl scheduled__2021-03-18T00:00:00+00:00 [queued]>
[2023-01-25T18:58:51.770+0000] {taskinstance.py:1083} INFO - Dependencies all met for <TaskInstance: twitter_dag.complete_twitter_etl scheduled__2021-03-18T00:00:00+00:00 [queued]>
[2023-01-25T18:58:51.772+0000] {taskinstance.py:1279} INFO - 
--------------------------------------------------------------------------------
[2023-01-25T18:58:51.774+0000] {taskinstance.py:1280} INFO - Starting attempt 1 of 2
[2023-01-25T18:58:51.801+0000] {taskinstance.py:1281} INFO - 
--------------------------------------------------------------------------------
[2023-01-25T18:58:51.944+0000] {taskinstance.py:1300} INFO - Executing <Task(PythonOperator): complete_twitter_etl> on 2021-03-18 00:00:00+00:00
[2023-01-25T18:58:52.050+0000] {standard_task_runner.py:55} INFO - Started process 2503 to run task
[2023-01-25T18:58:52.083+0000] {standard_task_runner.py:82} INFO - Running: ['***', 'tasks', 'run', 'twitter_dag', 'complete_twitter_etl', 'scheduled__2021-03-18T00:00:00+00:00', '--job-id', '255', '--raw', '--subdir', 'DAGS_FOLDER/twitter_dag.py', '--cfg-path', '/tmp/tmp_6s5jg9c']
[2023-01-25T18:58:52.087+0000] {standard_task_runner.py:83} INFO - Job 255: Subtask complete_twitter_etl
[2023-01-25T18:58:53.092+0000] {task_command.py:388} INFO - Running <TaskInstance: twitter_dag.complete_twitter_etl scheduled__2021-03-18T00:00:00+00:00 [running]> on host 512d0ff0785b
[2023-01-25T18:58:57.540+0000] {taskinstance.py:1509} INFO - Exporting the following env vars:
AIRFLOW_CTX_DAG_EMAIL=***@example.com
AIRFLOW_CTX_DAG_OWNER=***
AIRFLOW_CTX_DAG_ID=twitter_dag
AIRFLOW_CTX_TASK_ID=complete_twitter_etl
AIRFLOW_CTX_EXECUTION_DATE=2021-03-18T00:00:00+00:00
AIRFLOW_CTX_TRY_NUMBER=1
AIRFLOW_CTX_DAG_RUN_ID=scheduled__2021-03-18T00:00:00+00:00
[2023-01-25T18:59:03.614+0000] {taskinstance.py:1768} ERROR - Task failed with exception
Traceback (most recent call last):
  File "/home/airflow/.local/lib/python3.7/site-packages/s3fs/core.py", line 112, in _error_wrapper
    return await func(*args, **kwargs)
  File "/home/airflow/.local/lib/python3.7/site-packages/aiobotocore/client.py", line 358, in _make_api_call
    raise error_class(parsed_response, operation_name)
botocore.exceptions.ClientError: An error occurred (AccessDenied) when calling the CreateBucket operation: Anonymous access is forbidden for this operation

The above exception was the direct cause of the following exception:

Traceback (most recent call last):
  File "/home/airflow/.local/lib/python3.7/site-packages/airflow/operators/python.py", line 175, in execute
    return_value = self.execute_callable()
  File "/home/airflow/.local/lib/python3.7/site-packages/airflow/operators/python.py", line 192, in execute_callable
    return self.python_callable(*self.op_args, **self.op_kwargs)
  File "/opt/airflow/dags/twitter_etl.py", line 46, in run_twitter_etl
    df.to_csv("s3://jinchoi-airflow-bucket/data/elonmusk_tweets.csv")
  File "/home/airflow/.local/lib/python3.7/site-packages/pandas/core/generic.py", line 3482, in to_csv
    storage_options=storage_options,
  File "/home/airflow/.local/lib/python3.7/site-packages/pandas/io/formats/format.py", line 1105, in to_csv
    csv_formatter.save()
  File "/home/airflow/.local/lib/python3.7/site-packages/pandas/io/formats/csvs.py", line 243, in save
    storage_options=self.storage_options,
  File "/home/airflow/.local/lib/python3.7/site-packages/pandas/io/common.py", line 614, in get_handle
    storage_options=storage_options,
  File "/home/airflow/.local/lib/python3.7/site-packages/pandas/io/common.py", line 370, in _get_filepath_or_buffer
    filepath_or_buffer, mode=fsspec_mode, **(storage_options or {})
  File "/home/airflow/.local/lib/python3.7/site-packages/fsspec/core.py", line 428, in open
    **kwargs,
  File "/home/airflow/.local/lib/python3.7/site-packages/fsspec/core.py", line 283, in open_files
    [fs.makedirs(parent, exist_ok=True) for parent in parents]
  File "/home/airflow/.local/lib/python3.7/site-packages/fsspec/core.py", line 283, in <listcomp>
    [fs.makedirs(parent, exist_ok=True) for parent in parents]
  File "/home/airflow/.local/lib/python3.7/site-packages/fsspec/asyn.py", line 114, in wrapper
    return sync(self.loop, func, *args, **kwargs)
  File "/home/airflow/.local/lib/python3.7/site-packages/fsspec/asyn.py", line 99, in sync
    raise return_result
  File "/home/airflow/.local/lib/python3.7/site-packages/fsspec/asyn.py", line 54, in _runner
    result[0] = await coro
  File "/home/airflow/.local/lib/python3.7/site-packages/s3fs/core.py", line 883, in _makedirs
    await self._mkdir(path, create_parents=True)
  File "/home/airflow/.local/lib/python3.7/site-packages/s3fs/core.py", line 868, in _mkdir
    await self._call_s3("create_bucket", **params)
  File "/home/airflow/.local/lib/python3.7/site-packages/s3fs/core.py", line 340, in _call_s3
    method, kwargs=additional_kwargs, retries=self.retries
  File "/home/airflow/.local/lib/python3.7/site-packages/s3fs/core.py", line 139, in _error_wrapper
    raise err
PermissionError: Anonymous access is forbidden for this operation
[2023-01-25T18:59:03.706+0000] {taskinstance.py:1323} INFO - Marking task as UP_FOR_RETRY. dag_id=twitter_dag, task_id=complete_twitter_etl, execution_date=20210318T000000, start_date=20230125T185851, end_date=20230125T185903
[2023-01-25T18:59:03.747+0000] {standard_task_runner.py:105} ERROR - Failed to execute job 255 for task complete_twitter_etl (Anonymous access is forbidden for this operation; 2503)
[2023-01-25T18:59:03.908+0000] {local_task_job.py:208} INFO - Task exited with return code 1
[2023-01-25T18:59:03.991+0000] {taskinstance.py:2578} INFO - 0 downstream tasks scheduled from follow-on schedule check
[2023-01-26T06:54:00.560+0000] {taskinstance.py:1083} INFO - Dependencies all met for <TaskInstance: twitter_dag.complete_twitter_etl scheduled__2021-03-18T00:00:00+00:00 [queued]>
[2023-01-26T06:54:00.601+0000] {taskinstance.py:1083} INFO - Dependencies all met for <TaskInstance: twitter_dag.complete_twitter_etl scheduled__2021-03-18T00:00:00+00:00 [queued]>
[2023-01-26T06:54:00.604+0000] {taskinstance.py:1279} INFO - 
--------------------------------------------------------------------------------
[2023-01-26T06:54:00.605+0000] {taskinstance.py:1280} INFO - Starting attempt 1 of 2
[2023-01-26T06:54:00.606+0000] {taskinstance.py:1281} INFO - 
--------------------------------------------------------------------------------
[2023-01-26T06:54:00.671+0000] {taskinstance.py:1300} INFO - Executing <Task(PythonOperator): complete_twitter_etl> on 2021-03-18 00:00:00+00:00
[2023-01-26T06:54:00.688+0000] {standard_task_runner.py:55} INFO - Started process 348 to run task
[2023-01-26T06:54:00.712+0000] {standard_task_runner.py:82} INFO - Running: ['***', 'tasks', 'run', 'twitter_dag', 'complete_twitter_etl', 'scheduled__2021-03-18T00:00:00+00:00', '--job-id', '250', '--raw', '--subdir', 'DAGS_FOLDER/twitter_dag.py', '--cfg-path', '/tmp/tmprlsab219']
[2023-01-26T06:54:00.714+0000] {standard_task_runner.py:83} INFO - Job 250: Subtask complete_twitter_etl
[2023-01-26T06:54:01.333+0000] {task_command.py:388} INFO - Running <TaskInstance: twitter_dag.complete_twitter_etl scheduled__2021-03-18T00:00:00+00:00 [running]> on host 47843127de93
[2023-01-26T06:54:01.504+0000] {taskinstance.py:1509} INFO - Exporting the following env vars:
AIRFLOW_CTX_DAG_EMAIL=***@example.com
AIRFLOW_CTX_DAG_OWNER=***
AIRFLOW_CTX_DAG_ID=twitter_dag
AIRFLOW_CTX_TASK_ID=complete_twitter_etl
AIRFLOW_CTX_EXECUTION_DATE=2021-03-18T00:00:00+00:00
AIRFLOW_CTX_TRY_NUMBER=1
AIRFLOW_CTX_DAG_RUN_ID=scheduled__2021-03-18T00:00:00+00:00
[2023-01-26T06:54:02.066+0000] {taskinstance.py:1768} ERROR - Task failed with exception
Traceback (most recent call last):
  File "/home/airflow/.local/lib/python3.7/site-packages/airflow/operators/python.py", line 175, in execute
    return_value = self.execute_callable()
  File "/home/airflow/.local/lib/python3.7/site-packages/airflow/operators/python.py", line 192, in execute_callable
    return self.python_callable(*self.op_args, **self.op_kwargs)
  File "/opt/airflow/dags/twitter_etl.py", line 51, in run_twitter_etl
    aws_access_key_id=os.environ['aws_access_key_id'],
  File "/usr/local/lib/python3.7/os.py", line 681, in __getitem__
    raise KeyError(key) from None
KeyError: 'aws_access_key_id'
[2023-01-26T06:54:02.092+0000] {taskinstance.py:1323} INFO - Marking task as UP_FOR_RETRY. dag_id=twitter_dag, task_id=complete_twitter_etl, execution_date=20210318T000000, start_date=20230126T065400, end_date=20230126T065402
[2023-01-26T06:54:02.117+0000] {standard_task_runner.py:105} ERROR - Failed to execute job 250 for task complete_twitter_etl ('aws_access_key_id'; 348)
[2023-01-26T06:54:02.182+0000] {local_task_job.py:208} INFO - Task exited with return code 1
[2023-01-26T06:54:02.222+0000] {taskinstance.py:2578} INFO - 0 downstream tasks scheduled from follow-on schedule check
[2023-01-26T07:13:57.088+0000] {taskinstance.py:1083} INFO - Dependencies all met for <TaskInstance: twitter_dag.complete_twitter_etl scheduled__2021-03-18T00:00:00+00:00 [queued]>
[2023-01-26T07:13:57.130+0000] {taskinstance.py:1083} INFO - Dependencies all met for <TaskInstance: twitter_dag.complete_twitter_etl scheduled__2021-03-18T00:00:00+00:00 [queued]>
[2023-01-26T07:13:57.131+0000] {taskinstance.py:1279} INFO - 
--------------------------------------------------------------------------------
[2023-01-26T07:13:57.138+0000] {taskinstance.py:1280} INFO - Starting attempt 1 of 2
[2023-01-26T07:13:57.140+0000] {taskinstance.py:1281} INFO - 
--------------------------------------------------------------------------------
[2023-01-26T07:13:57.195+0000] {taskinstance.py:1300} INFO - Executing <Task(PythonOperator): complete_twitter_etl> on 2021-03-18 00:00:00+00:00
[2023-01-26T07:13:57.232+0000] {standard_task_runner.py:55} INFO - Started process 1327 to run task
[2023-01-26T07:13:57.263+0000] {standard_task_runner.py:82} INFO - Running: ['***', 'tasks', 'run', 'twitter_dag', 'complete_twitter_etl', 'scheduled__2021-03-18T00:00:00+00:00', '--job-id', '169', '--raw', '--subdir', 'DAGS_FOLDER/twitter_dag.py', '--cfg-path', '/tmp/tmpan287so9']
[2023-01-26T07:13:57.270+0000] {standard_task_runner.py:83} INFO - Job 169: Subtask complete_twitter_etl
[2023-01-26T07:13:59.383+0000] {task_command.py:388} INFO - Running <TaskInstance: twitter_dag.complete_twitter_etl scheduled__2021-03-18T00:00:00+00:00 [running]> on host 2221c1ebf970
[2023-01-26T07:13:59.777+0000] {taskinstance.py:1509} INFO - Exporting the following env vars:
AIRFLOW_CTX_DAG_EMAIL=***@example.com
AIRFLOW_CTX_DAG_OWNER=***
AIRFLOW_CTX_DAG_ID=twitter_dag
AIRFLOW_CTX_TASK_ID=complete_twitter_etl
AIRFLOW_CTX_EXECUTION_DATE=2021-03-18T00:00:00+00:00
AIRFLOW_CTX_TRY_NUMBER=1
AIRFLOW_CTX_DAG_RUN_ID=scheduled__2021-03-18T00:00:00+00:00
[2023-01-26T07:14:02.757+0000] {python.py:177} INFO - Done. Returned value was: None
[2023-01-26T07:14:02.820+0000] {taskinstance.py:1323} INFO - Marking task as SUCCESS. dag_id=twitter_dag, task_id=complete_twitter_etl, execution_date=20210318T000000, start_date=20230126T071357, end_date=20230126T071402
[2023-01-26T07:14:03.495+0000] {local_task_job.py:208} INFO - Task exited with return code 0
[2023-01-26T07:14:05.045+0000] {taskinstance.py:2578} INFO - 0 downstream tasks scheduled from follow-on schedule check
[2023-01-26T09:11:38.822+0000] {taskinstance.py:1083} INFO - Dependencies all met for <TaskInstance: twitter_dag.complete_twitter_etl scheduled__2021-03-18T00:00:00+00:00 [queued]>
[2023-01-26T09:11:38.955+0000] {taskinstance.py:1083} INFO - Dependencies all met for <TaskInstance: twitter_dag.complete_twitter_etl scheduled__2021-03-18T00:00:00+00:00 [queued]>
[2023-01-26T09:11:38.965+0000] {taskinstance.py:1279} INFO - 
--------------------------------------------------------------------------------
[2023-01-26T09:11:38.970+0000] {taskinstance.py:1280} INFO - Starting attempt 1 of 2
[2023-01-26T09:11:38.973+0000] {taskinstance.py:1281} INFO - 
--------------------------------------------------------------------------------
[2023-01-26T09:11:39.150+0000] {taskinstance.py:1300} INFO - Executing <Task(PythonOperator): complete_twitter_etl> on 2021-03-18 00:00:00+00:00
[2023-01-26T09:11:39.255+0000] {standard_task_runner.py:82} INFO - Running: ['***', 'tasks', 'run', 'twitter_dag', 'complete_twitter_etl', 'scheduled__2021-03-18T00:00:00+00:00', '--job-id', '132', '--raw', '--subdir', 'DAGS_FOLDER/twitter_dag.py', '--cfg-path', '/tmp/tmpdi515i9c']
[2023-01-26T09:11:39.286+0000] {standard_task_runner.py:83} INFO - Job 132: Subtask complete_twitter_etl
[2023-01-26T09:11:39.228+0000] {standard_task_runner.py:55} INFO - Started process 647 to run task
[2023-01-26T09:11:40.781+0000] {task_command.py:388} INFO - Running <TaskInstance: twitter_dag.complete_twitter_etl scheduled__2021-03-18T00:00:00+00:00 [running]> on host d0fc3b00c15c
[2023-01-26T09:11:41.058+0000] {taskinstance.py:1509} INFO - Exporting the following env vars:
AIRFLOW_CTX_DAG_EMAIL=***@example.com
AIRFLOW_CTX_DAG_OWNER=***
AIRFLOW_CTX_DAG_ID=twitter_dag
AIRFLOW_CTX_TASK_ID=complete_twitter_etl
AIRFLOW_CTX_EXECUTION_DATE=2021-03-18T00:00:00+00:00
AIRFLOW_CTX_TRY_NUMBER=1
AIRFLOW_CTX_DAG_RUN_ID=scheduled__2021-03-18T00:00:00+00:00
[2023-01-26T09:11:43.047+0000] {python.py:177} INFO - Done. Returned value was: None
[2023-01-26T09:11:43.092+0000] {taskinstance.py:1323} INFO - Marking task as SUCCESS. dag_id=twitter_dag, task_id=complete_twitter_etl, execution_date=20210318T000000, start_date=20230126T091138, end_date=20230126T091143
[2023-01-26T09:11:43.369+0000] {local_task_job.py:208} INFO - Task exited with return code 0
[2023-01-26T09:11:43.460+0000] {taskinstance.py:2578} INFO - 0 downstream tasks scheduled from follow-on schedule check
