[2023-01-25T18:56:56.264+0000] {taskinstance.py:1083} INFO - Dependencies all met for <TaskInstance: twitter_dag.complete_twitter_etl scheduled__2021-02-21T00:00:00+00:00 [queued]>
[2023-01-25T18:56:56.368+0000] {taskinstance.py:1083} INFO - Dependencies all met for <TaskInstance: twitter_dag.complete_twitter_etl scheduled__2021-02-21T00:00:00+00:00 [queued]>
[2023-01-25T18:56:56.372+0000] {taskinstance.py:1279} INFO - 
--------------------------------------------------------------------------------
[2023-01-25T18:56:56.376+0000] {taskinstance.py:1280} INFO - Starting attempt 2 of 2
[2023-01-25T18:56:56.385+0000] {taskinstance.py:1281} INFO - 
--------------------------------------------------------------------------------
[2023-01-25T18:56:56.494+0000] {taskinstance.py:1300} INFO - Executing <Task(PythonOperator): complete_twitter_etl> on 2021-02-21 00:00:00+00:00
[2023-01-25T18:56:56.546+0000] {standard_task_runner.py:55} INFO - Started process 2278 to run task
[2023-01-25T18:56:56.574+0000] {standard_task_runner.py:82} INFO - Running: ['***', 'tasks', 'run', 'twitter_dag', 'complete_twitter_etl', 'scheduled__2021-02-21T00:00:00+00:00', '--job-id', '229', '--raw', '--subdir', 'DAGS_FOLDER/twitter_dag.py', '--cfg-path', '/tmp/tmp2i0rpt4_']
[2023-01-25T18:56:56.604+0000] {standard_task_runner.py:83} INFO - Job 229: Subtask complete_twitter_etl
[2023-01-25T18:56:57.034+0000] {task_command.py:388} INFO - Running <TaskInstance: twitter_dag.complete_twitter_etl scheduled__2021-02-21T00:00:00+00:00 [running]> on host 512d0ff0785b
[2023-01-25T18:56:58.069+0000] {taskinstance.py:1509} INFO - Exporting the following env vars:
AIRFLOW_CTX_DAG_EMAIL=***@example.com
AIRFLOW_CTX_DAG_OWNER=***
AIRFLOW_CTX_DAG_ID=twitter_dag
AIRFLOW_CTX_TASK_ID=complete_twitter_etl
AIRFLOW_CTX_EXECUTION_DATE=2021-02-21T00:00:00+00:00
AIRFLOW_CTX_TRY_NUMBER=2
AIRFLOW_CTX_DAG_RUN_ID=scheduled__2021-02-21T00:00:00+00:00
[2023-01-25T18:57:03.594+0000] {taskinstance.py:1768} ERROR - Task failed with exception
Traceback (most recent call last):
  File "/home/airflow/.local/lib/python3.7/site-packages/s3fs/core.py", line 112, in _error_wrapper
    return await func(*args, **kwargs)
  File "/home/airflow/.local/lib/python3.7/site-packages/aiobotocore/client.py", line 358, in _make_api_call
    raise error_class(parsed_response, operation_name)
botocore.exceptions.ClientError: An error occurred (AccessDenied) when calling the CreateBucket operation: Anonymous access is forbidden for this operation

The above exception was the direct cause of the following exception:

Traceback (most recent call last):
  File "/home/airflow/.local/lib/python3.7/site-packages/airflow/operators/python.py", line 175, in execute
    return_value = self.execute_callable()
  File "/home/airflow/.local/lib/python3.7/site-packages/airflow/operators/python.py", line 192, in execute_callable
    return self.python_callable(*self.op_args, **self.op_kwargs)
  File "/opt/airflow/dags/twitter_etl.py", line 46, in run_twitter_etl
    df.to_csv("s3://jinchoi-airflow-bucket/data/elonmusk_tweets.csv")
  File "/home/airflow/.local/lib/python3.7/site-packages/pandas/core/generic.py", line 3482, in to_csv
    storage_options=storage_options,
  File "/home/airflow/.local/lib/python3.7/site-packages/pandas/io/formats/format.py", line 1105, in to_csv
    csv_formatter.save()
  File "/home/airflow/.local/lib/python3.7/site-packages/pandas/io/formats/csvs.py", line 243, in save
    storage_options=self.storage_options,
  File "/home/airflow/.local/lib/python3.7/site-packages/pandas/io/common.py", line 614, in get_handle
    storage_options=storage_options,
  File "/home/airflow/.local/lib/python3.7/site-packages/pandas/io/common.py", line 370, in _get_filepath_or_buffer
    filepath_or_buffer, mode=fsspec_mode, **(storage_options or {})
  File "/home/airflow/.local/lib/python3.7/site-packages/fsspec/core.py", line 428, in open
    **kwargs,
  File "/home/airflow/.local/lib/python3.7/site-packages/fsspec/core.py", line 283, in open_files
    [fs.makedirs(parent, exist_ok=True) for parent in parents]
  File "/home/airflow/.local/lib/python3.7/site-packages/fsspec/core.py", line 283, in <listcomp>
    [fs.makedirs(parent, exist_ok=True) for parent in parents]
  File "/home/airflow/.local/lib/python3.7/site-packages/fsspec/asyn.py", line 114, in wrapper
    return sync(self.loop, func, *args, **kwargs)
  File "/home/airflow/.local/lib/python3.7/site-packages/fsspec/asyn.py", line 99, in sync
    raise return_result
  File "/home/airflow/.local/lib/python3.7/site-packages/fsspec/asyn.py", line 54, in _runner
    result[0] = await coro
  File "/home/airflow/.local/lib/python3.7/site-packages/s3fs/core.py", line 883, in _makedirs
    await self._mkdir(path, create_parents=True)
  File "/home/airflow/.local/lib/python3.7/site-packages/s3fs/core.py", line 868, in _mkdir
    await self._call_s3("create_bucket", **params)
  File "/home/airflow/.local/lib/python3.7/site-packages/s3fs/core.py", line 340, in _call_s3
    method, kwargs=additional_kwargs, retries=self.retries
  File "/home/airflow/.local/lib/python3.7/site-packages/s3fs/core.py", line 139, in _error_wrapper
    raise err
PermissionError: Anonymous access is forbidden for this operation
[2023-01-25T18:57:03.651+0000] {taskinstance.py:1323} INFO - Marking task as FAILED. dag_id=twitter_dag, task_id=complete_twitter_etl, execution_date=20210221T000000, start_date=20230125T185656, end_date=20230125T185703
[2023-01-25T18:57:04.143+0000] {standard_task_runner.py:105} ERROR - Failed to execute job 229 for task complete_twitter_etl (Anonymous access is forbidden for this operation; 2278)
[2023-01-25T18:57:04.246+0000] {local_task_job.py:208} INFO - Task exited with return code 1
[2023-01-25T18:57:04.309+0000] {taskinstance.py:2578} INFO - 0 downstream tasks scheduled from follow-on schedule check
[2023-01-26T06:53:33.458+0000] {taskinstance.py:1083} INFO - Dependencies all met for <TaskInstance: twitter_dag.complete_twitter_etl scheduled__2021-02-21T00:00:00+00:00 [queued]>
[2023-01-26T06:53:33.491+0000] {taskinstance.py:1083} INFO - Dependencies all met for <TaskInstance: twitter_dag.complete_twitter_etl scheduled__2021-02-21T00:00:00+00:00 [queued]>
[2023-01-26T06:53:33.494+0000] {taskinstance.py:1279} INFO - 
--------------------------------------------------------------------------------
[2023-01-26T06:53:33.496+0000] {taskinstance.py:1280} INFO - Starting attempt 2 of 2
[2023-01-26T06:53:33.498+0000] {taskinstance.py:1281} INFO - 
--------------------------------------------------------------------------------
[2023-01-26T06:53:33.558+0000] {taskinstance.py:1300} INFO - Executing <Task(PythonOperator): complete_twitter_etl> on 2021-02-21 00:00:00+00:00
[2023-01-26T06:53:33.578+0000] {standard_task_runner.py:55} INFO - Started process 261 to run task
[2023-01-26T06:53:33.599+0000] {standard_task_runner.py:82} INFO - Running: ['***', 'tasks', 'run', 'twitter_dag', 'complete_twitter_etl', 'scheduled__2021-02-21T00:00:00+00:00', '--job-id', '224', '--raw', '--subdir', 'DAGS_FOLDER/twitter_dag.py', '--cfg-path', '/tmp/tmpmi7_rpj5']
[2023-01-26T06:53:33.608+0000] {standard_task_runner.py:83} INFO - Job 224: Subtask complete_twitter_etl
[2023-01-26T06:53:36.123+0000] {task_command.py:388} INFO - Running <TaskInstance: twitter_dag.complete_twitter_etl scheduled__2021-02-21T00:00:00+00:00 [running]> on host 47843127de93
[2023-01-26T06:53:36.993+0000] {taskinstance.py:1509} INFO - Exporting the following env vars:
AIRFLOW_CTX_DAG_EMAIL=***@example.com
AIRFLOW_CTX_DAG_OWNER=***
AIRFLOW_CTX_DAG_ID=twitter_dag
AIRFLOW_CTX_TASK_ID=complete_twitter_etl
AIRFLOW_CTX_EXECUTION_DATE=2021-02-21T00:00:00+00:00
AIRFLOW_CTX_TRY_NUMBER=2
AIRFLOW_CTX_DAG_RUN_ID=scheduled__2021-02-21T00:00:00+00:00
[2023-01-26T06:53:37.545+0000] {taskinstance.py:1768} ERROR - Task failed with exception
Traceback (most recent call last):
  File "/home/airflow/.local/lib/python3.7/site-packages/airflow/operators/python.py", line 175, in execute
    return_value = self.execute_callable()
  File "/home/airflow/.local/lib/python3.7/site-packages/airflow/operators/python.py", line 192, in execute_callable
    return self.python_callable(*self.op_args, **self.op_kwargs)
  File "/opt/airflow/dags/twitter_etl.py", line 51, in run_twitter_etl
    aws_access_key_id=os.environ['aws_access_key_id'],
  File "/usr/local/lib/python3.7/os.py", line 681, in __getitem__
    raise KeyError(key) from None
KeyError: 'aws_access_key_id'
[2023-01-26T06:53:37.581+0000] {taskinstance.py:1323} INFO - Marking task as FAILED. dag_id=twitter_dag, task_id=complete_twitter_etl, execution_date=20210221T000000, start_date=20230126T065333, end_date=20230126T065337
[2023-01-26T06:53:37.649+0000] {standard_task_runner.py:105} ERROR - Failed to execute job 224 for task complete_twitter_etl ('aws_access_key_id'; 261)
[2023-01-26T06:53:37.856+0000] {local_task_job.py:208} INFO - Task exited with return code 1
[2023-01-26T06:53:37.952+0000] {taskinstance.py:2578} INFO - 0 downstream tasks scheduled from follow-on schedule check
