[2023-01-26T07:47:44.838+0000] {taskinstance.py:1083} INFO - Dependencies all met for <TaskInstance: twitter_dag.complete_twitter_etl scheduled__2022-05-07T00:00:00+00:00 [queued]>
[2023-01-26T07:47:44.890+0000] {taskinstance.py:1083} INFO - Dependencies all met for <TaskInstance: twitter_dag.complete_twitter_etl scheduled__2022-05-07T00:00:00+00:00 [queued]>
[2023-01-26T07:47:44.892+0000] {taskinstance.py:1279} INFO - 
--------------------------------------------------------------------------------
[2023-01-26T07:47:44.893+0000] {taskinstance.py:1280} INFO - Starting attempt 1 of 2
[2023-01-26T07:47:44.895+0000] {taskinstance.py:1281} INFO - 
--------------------------------------------------------------------------------
[2023-01-26T07:47:44.984+0000] {taskinstance.py:1300} INFO - Executing <Task(PythonOperator): complete_twitter_etl> on 2022-05-07 00:00:00+00:00
[2023-01-26T07:47:45.048+0000] {standard_task_runner.py:55} INFO - Started process 2985 to run task
[2023-01-26T07:47:45.067+0000] {standard_task_runner.py:82} INFO - Running: ['***', 'tasks', 'run', 'twitter_dag', 'complete_twitter_etl', 'scheduled__2022-05-07T00:00:00+00:00', '--job-id', '585', '--raw', '--subdir', 'DAGS_FOLDER/twitter_dag.py', '--cfg-path', '/tmp/tmpedqix8ya']
[2023-01-26T07:47:45.075+0000] {standard_task_runner.py:83} INFO - Job 585: Subtask complete_twitter_etl
[2023-01-26T07:47:46.037+0000] {task_command.py:388} INFO - Running <TaskInstance: twitter_dag.complete_twitter_etl scheduled__2022-05-07T00:00:00+00:00 [running]> on host 2221c1ebf970
[2023-01-26T07:47:46.303+0000] {taskinstance.py:1509} INFO - Exporting the following env vars:
AIRFLOW_CTX_DAG_EMAIL=***@example.com
AIRFLOW_CTX_DAG_OWNER=***
AIRFLOW_CTX_DAG_ID=twitter_dag
AIRFLOW_CTX_TASK_ID=complete_twitter_etl
AIRFLOW_CTX_EXECUTION_DATE=2022-05-07T00:00:00+00:00
AIRFLOW_CTX_TRY_NUMBER=1
AIRFLOW_CTX_DAG_RUN_ID=scheduled__2022-05-07T00:00:00+00:00
[2023-01-26T07:47:46.311+0000] {taskinstance.py:1768} ERROR - Task failed with exception
Traceback (most recent call last):
  File "/home/airflow/.local/lib/python3.7/site-packages/airflow/operators/python.py", line 175, in execute
    return_value = self.execute_callable()
  File "/home/airflow/.local/lib/python3.7/site-packages/airflow/operators/python.py", line 192, in execute_callable
    return self.python_callable(*self.op_args, **self.op_kwargs)
  File "/opt/airflow/dags/twitter_etl.py", line 12, in run_twitter_etl
    access_key = os.environ['tweepy_access_key']
  File "/usr/local/lib/python3.7/os.py", line 681, in __getitem__
    raise KeyError(key) from None
KeyError: 'tweepy_access_key'
[2023-01-26T07:47:46.333+0000] {taskinstance.py:1323} INFO - Marking task as UP_FOR_RETRY. dag_id=twitter_dag, task_id=complete_twitter_etl, execution_date=20220507T000000, start_date=20230126T074744, end_date=20230126T074746
[2023-01-26T07:47:46.370+0000] {standard_task_runner.py:105} ERROR - Failed to execute job 585 for task complete_twitter_etl ('tweepy_access_key'; 2985)
[2023-01-26T07:47:46.447+0000] {local_task_job.py:208} INFO - Task exited with return code 1
[2023-01-26T07:47:46.509+0000] {taskinstance.py:2578} INFO - 0 downstream tasks scheduled from follow-on schedule check
