[2023-01-26T07:47:43.648+0000] {taskinstance.py:1083} INFO - Dependencies all met for <TaskInstance: twitter_dag.complete_twitter_etl scheduled__2022-05-06T00:00:00+00:00 [queued]>
[2023-01-26T07:47:43.763+0000] {taskinstance.py:1083} INFO - Dependencies all met for <TaskInstance: twitter_dag.complete_twitter_etl scheduled__2022-05-06T00:00:00+00:00 [queued]>
[2023-01-26T07:47:43.766+0000] {taskinstance.py:1279} INFO - 
--------------------------------------------------------------------------------
[2023-01-26T07:47:43.772+0000] {taskinstance.py:1280} INFO - Starting attempt 1 of 2
[2023-01-26T07:47:43.775+0000] {taskinstance.py:1281} INFO - 
--------------------------------------------------------------------------------
[2023-01-26T07:47:43.952+0000] {taskinstance.py:1300} INFO - Executing <Task(PythonOperator): complete_twitter_etl> on 2022-05-06 00:00:00+00:00
[2023-01-26T07:47:44.032+0000] {standard_task_runner.py:55} INFO - Started process 2981 to run task
[2023-01-26T07:47:44.068+0000] {standard_task_runner.py:82} INFO - Running: ['***', 'tasks', 'run', 'twitter_dag', 'complete_twitter_etl', 'scheduled__2022-05-06T00:00:00+00:00', '--job-id', '582', '--raw', '--subdir', 'DAGS_FOLDER/twitter_dag.py', '--cfg-path', '/tmp/tmpopqgjyss']
[2023-01-26T07:47:44.071+0000] {standard_task_runner.py:83} INFO - Job 582: Subtask complete_twitter_etl
[2023-01-26T07:47:45.076+0000] {task_command.py:388} INFO - Running <TaskInstance: twitter_dag.complete_twitter_etl scheduled__2022-05-06T00:00:00+00:00 [running]> on host 2221c1ebf970
[2023-01-26T07:47:45.355+0000] {taskinstance.py:1509} INFO - Exporting the following env vars:
AIRFLOW_CTX_DAG_EMAIL=***@example.com
AIRFLOW_CTX_DAG_OWNER=***
AIRFLOW_CTX_DAG_ID=twitter_dag
AIRFLOW_CTX_TASK_ID=complete_twitter_etl
AIRFLOW_CTX_EXECUTION_DATE=2022-05-06T00:00:00+00:00
AIRFLOW_CTX_TRY_NUMBER=1
AIRFLOW_CTX_DAG_RUN_ID=scheduled__2022-05-06T00:00:00+00:00
[2023-01-26T07:47:45.359+0000] {taskinstance.py:1768} ERROR - Task failed with exception
Traceback (most recent call last):
  File "/home/airflow/.local/lib/python3.7/site-packages/airflow/operators/python.py", line 175, in execute
    return_value = self.execute_callable()
  File "/home/airflow/.local/lib/python3.7/site-packages/airflow/operators/python.py", line 192, in execute_callable
    return self.python_callable(*self.op_args, **self.op_kwargs)
  File "/opt/airflow/dags/twitter_etl.py", line 12, in run_twitter_etl
    access_key = os.environ['tweepy_access_key']
  File "/usr/local/lib/python3.7/os.py", line 681, in __getitem__
    raise KeyError(key) from None
KeyError: 'tweepy_access_key'
[2023-01-26T07:47:45.378+0000] {taskinstance.py:1323} INFO - Marking task as UP_FOR_RETRY. dag_id=twitter_dag, task_id=complete_twitter_etl, execution_date=20220506T000000, start_date=20230126T074743, end_date=20230126T074745
[2023-01-26T07:47:45.410+0000] {standard_task_runner.py:105} ERROR - Failed to execute job 582 for task complete_twitter_etl ('tweepy_access_key'; 2981)
[2023-01-26T07:47:45.488+0000] {local_task_job.py:208} INFO - Task exited with return code 1
[2023-01-26T07:47:45.617+0000] {taskinstance.py:2578} INFO - 0 downstream tasks scheduled from follow-on schedule check
